File: data/results_table.csv
num,Code,Thickness (mm),xCell,yCell,zCell,Angle (°),Height (mm),Radius (mm),RD,SA (cm^2),SA/VR (1/cm),Porosity,Elastic Modulus (GPa),Yield Strain (-),Yield Stress (MPa),Ultimate Strain (-),Ultimate Stress (MPa),Energy Absorption (MJ/m^3),Plateau Stress (MPa)
1,D,0.2,3,3,3,0,8,2.5,15.0874345,4.127542368,172.5325662,84.9125655,3.073900612,0.023444101,65.9170362,0.123627186,90.52632236,41.71456262,85.84563089
11,D,0.3,4,4,3,0,8,2.5,18.82063393,3.632619186,121.5420069,81.17936607,2.765692486,0.021989379,55.28447459,0.160056919,76.6456619,35.32700229,73.60985422
21,D,0.4,3,4,4,0,8,2.5,25.34004988,3.685146134,91.33863483,74.65995012,6.11547347,0.022793581,127.1625929,0.190579295,170.2765372,74.04505232,153.5308048
31,D,0.2,3,4,3,30,8,2.5,13.69280405,3.839574336,176.6036747,86.30719595,2.185387043,0.025155321,50.60333928,0.14046441,68.20717552,30.61710911,61.27766161
41,D,0.3,4,3,4,30,8,2.5,19.14204655,3.688252437,120.6180329,80.85795345,4.164310448,0.023621089,90.03692651,0.103672594,113.7197489,48.15516861,88.95312949
51,D,0.4,3,3,3,60,8,2.5,30.89428969,4.317735742,88.09307844,69.10571031,6.06572665,0.025505211,142.576187,0.184899569,215.1369486,93.18269372,185.8343438
61,D,0.2,3,3,4,60,8,2.5,13.67023464,3.728640251,176.7271485,86.32976536,2.188701879,0.025055638,50.46191773,0.136673689,67.90255999,29.72377592,60.18950053
71,D,0.3,4,4,4,60,8,2.5,17.39441237,3.255810281,118.2075555,82.60558763,2.661584309,0.028474609,70.4644051,0.137029976,92.18000942,39.66395548,72.50373148
81,D,0.4,3,4,3,0,10,2.5,28.0791284,5.033126079,90.20340711,71.9208716,4.264702632,0.026062734,102.6204071,0.18986907,156.7857733,68.76959843,145.463813
91,D,0.2,3,4,4,0,10,2.5,12.665998,4.435546471,175.8959234,87.334002,2.620347999,0.023178214,55.49429097,0.153854227,72.24690052,30.40443072,63.02003472
101,D,0.3,4,3,3,30,10,2.5,20.97717718,4.866989287,118.8032123,79.02282282,4.305642912,0.023043852,90.60731114,0.147546494,119.4663457,52.11825055,99.31142063
111,D,0.4,3,3,4,30,10,2.5,28.00246039,4.993698358,89.73846718,71.99753961,6.405268054,0.023763717,139.4024422,0.116199386,190.4262903,79.49297567,148.3000298
121,D,0.2,3,3,3,60,10,2.5,15.33928035,5.222465588,172.6055907,84.66071965,2.871534125,0.023658429,62.19291864,0.135053897,87.50762313,37.95730469,77.02672705
131,D,0.3,4,4,3,60,10,2.5,18.95013851,4.513027737,119.3988829,81.04986149,4.313074624,0.022475637,88.31294821,0.083172309,113.3754693,47.59138558,93.11149275
141,D,0.4,3,4,4,60,10,2.5,25.26087287,4.570963902,90.89173355,74.73912713,5.107943071,0.024780863,116.3633504,0.137747598,156.8598065,66.01065786,124.7088999
295,D,0.2,3,4,3,0,8,5,13.98594702,15.15666941,171.2213698,86.01405298,2.507222303,0.024204893,55.67260292,0.127690196,76.44635547,36.12181068,75.31722133
305,D,0.3,4,3,4,0,8,5,19.21419029,13.83279943,115.4776136,80.78580971,4.40080647,0.025216938,102.1732505,0.136782676,136.30259,61.9837584,122.1777241
315,D,0.4,3,3,3,30,8,5,31.01973367,16.5941477,84.6751433,68.98026633,6.531778635,0.025910382,156.1773241,0.180078745,231.7720283,98.21119619,192.0746698
325,D,0.2,3,3,4,30,8,5,14.06159514,15.39287368,172.8242114,85.93840486,2.865165624,0.025213509,66.51054814,0.164681867,88.98567998,37.93255554,69.58635626
335,D,0.3,4,4,4,30,8,5,17.31972412,12.48904262,114.141697,82.68027588,3.02470033,0.026497381,74.09723673,0.180161774,102.204374,45.07352922,87.00420853
345,D,0.4,3,4,3,60,8,5,28.15757484,15.4439721,87.03279601,71.84242516,6.633369693,0.024968962,152.3616194,0.188802421,218.5155256,87.09469244,159.1330348
355,D,0.2,3,4,4,60,8,5,12.69824203,13.85743375,173.1744311,87.30175797,2.242915544,0.026495006,54.94023076,0.10786365,72.4728277,31.55007707,59.0615473
365,D,0.3,4,3,3,0,10,5,21.29584774,19.19343754,114.7635954,78.70415226,3.639019877,0.02659068,89.48597158,0.198830652,129.4889859,56.56883239,113.3114089
375,D,0.4,3,3,4,0,10,5,28.19174518,19.12956123,86.18563431,71.80825482,7.794389688,0.024068007,172.006648,0.179718971,234.9175818,98.62542832,198.9693474
385,D,0.2,3,3,3,30,10,5,15.50242378,20.61520029,169.1255395,84.49757622,2.377937379,0.033126318,74.01643577,0.192963707,99.82204688,43.54297895,85.85346539
395,D,0.3,4,4,3,30,10,5,19.11690427,17.26631915,114.8550445,80.88309573,3.050982014,0.025928118,73.00425806,0.15191288,102.2466715,47.37221308,96.40505241
405,D,0.4,3,4,4,30,10,5,25.56168657,17.47576351,86.92407557,74.43831343,5.53891761,0.025352686,129.348604,0.159425354,178.8404517,76.21817822,145.0292301
415,D,0.2,3,4,3,60,10,5,13.99606592,19.00565527,173.1859184,86.00393408,3.037617859,0.024090626,67.10288035,0.150299406,88.61636438,37.99091664,71.5347452
425,D,0.3,4,3,4,60,10,5,19.12512976,17.28503447,115.5613977,80.87487024,3.02669872,0.026089341,72.91117732,0.164538455,102.6253429,47.38770149,95.11125381
435,D,0.4,3,3,3,0,15,5,31.02766497,30.62406836,83.29731212,68.97233503,7.391730633,0.023259341,157.1433218,0.198974911,221.2987925,99.09302321,207.2163314
445,D,0.2,3,3,4,0,15,5,14.10629996,28.51570351,172.3530437,85.89370004,4.321535809,0.022450345,88.37689611,0.10957942,110.3646091,45.68592144,83.88912773
455,D,0.3,4,4,4,0,15,5,17.43589773,23.26207683,113.5983825,82.56410227,3.872642631,0.023074588,81.61434981,0.161570803,106.5302458,45.88230446,86.247745
465,D,0.4,3,4,3,30,15,5,28.09490627,28.74519367,85.8278119,71.90509373,6.149080782,0.023209668,130.4199622,0.181211837,186.1488336,81.735381,163.2581365
475,D,0.2,3,4,4,30,15,5,12.74337038,25.91990026,173.9203692,87.25662962,2.562422948,0.024058475,56.5231421,0.098270973,72.97019805,31.7339792,64.6202917
485,D,0.3,4,3,3,60,15,5,21.13804369,28.27270685,113.8515404,78.86195631,4.396789287,0.023564845,94.81607901,0.181302436,134.8456647,58.4513661,115.9309808
495,D,0.4,3,3,4,60,15,5,28.12753666,28.45027857,85.84160823,71.87246334,6.157857279,0.023187018,130.4666303,0.157320054,183.8510904,82.49963062,164.0985951
505,D,0.2,3,3,3,0,20,5,15.44099112,40.85512196,168.0481547,84.55900888,3.657914144,0.022475201,74.89652749,0.097926867,96.6194733,43.67987227,88.2397056
515,D,0.3,4,4,3,0,20,5,19.0617174,34.49083843,114.5661219,80.9382826,3.245697862,0.022557815,66.72445707,0.198319745,92.68483353,41.77977874,84.27036967
525,D,0.4,3,4,4,0,20,5,25.65628895,34.9241425,85.64126845,74.34371105,6.703852876,0.023546685,144.4458082,0.115737069,188.3972783,75.36975353,151.1047926
535,D,0.2,3,4,3,30,20,5,13.86233496,37.74776411,172.4575635,86.13766504,2.616670843,0.02332482,55.80003517,0.123175097,76.30015998,34.15705961,70.15524094
545,D,0.3,4,3,4,30,20,5,18.99081389,34.3580548,114.8372888,81.00918611,3.985625495,0.023718341,86.56117383,0.13341167,121.5638397,50.08351986,94.00339822
555,D,0.4,3,3,3,60,20,5,30.67958401,40.44032958,83.78958136,69.32041599,7.289026151,0.023115205,153.9092835,0.16220243,220.2654305,94.34696187,185.2617594
565,D,0.2,3,3,4,60,20,5,13.8596486,37.51451406,173.1457583,86.1403514,2.609714574,0.023299577,55.58581591,0.123173904,75.86800956,33.18248492,69.36149395
575,D,0.3,4,4,4,60,20,5,17.24440136,30.93168038,113.8202247,82.75559864,3.475897564,0.02325393,73.8764831,0.115745318,97.91663908,42.64905538,87.16269182
585,D,0.4,3,4,3,0,8,7.5,27.88937976,33.80274895,85.44946596,72.11062024,5.411972903,0.024450814,121.5031985,0.170856297,174.1754242,80.95444382,160.0154872
595,D,0.2,3,4,4,0,8,7.5,12.78273507,30.97542485,171.4432908,87.21726493,2.115636139,0.035298774,70.44809,0.105563432,85.64566574,38.71555425,82.62262677
605,D,0.3,4,3,3,30,8,7.5,21.04237799,33.94665194,113.6022801,78.95762201,4.053013095,0.025020273,93.30146801,0.190014184,135.8675807,59.1038863,117.5832084
615,D,0.4,3,3,4,30,8,7.5,28.11153573,33.89666983,85.6672436,71.88846427,5.65833903,0.029975808,158.2966061,0.165259033,215.1396916,85.99832307,154.2284156
625,D,0.2,3,3,3,60,8,7.5,15.45725154,36.67546318,168.7332483,84.54274846,2.844542692,0.026116682,68.6009303,0.191502288,100.1992882,44.17097892,86.77457047
635,D,0.3,4,4,3,60,8,7.5,19.12492035,31.30476394,114.8975453,80.87507965,3.857750409,0.025198283,89.49318587,0.166030839,125.2473395,52.44651353,95.06146874
645,D,0.4,3,4,4,60,8,7.5,25.5896219,31.67875794,86.05240817,74.4103781,5.2879632,0.027710072,135.9539151,0.124368459,182.4437853,74.37321682,134.5197949
655,D,0.2,3,4,3,0,10,7.5,14.13581912,42.94632538,171.5465533,85.86418088,2.313347117,0.027032039,57.90779533,0.182338166,81.26180095,35.75185055,70.88967027
665,D,0.3,4,3,4,0,10,7.5,19.09812678,38.9060305,113.7976056,80.90187322,4.478775532,0.025118695,103.5434454,0.107572532,134.7034226,60.00094249,122.1608182
675,D,0.4,3,3,3,30,10,7.5,30.96775795,45.71082064,83.29211558,69.03224205,5.518737776,0.032412523,167.8387395,0.192943907,235.1101587,98.55433398,190.82388
685,D,0.2,3,3,4,30,10,7.5,14.05107151,42.39247856,171.3416609,85.94892849,2.367492085,0.031951225,70.90928864,0.153609061,88.89711274,37.89932518,71.8564682
695,D,0.3,4,4,4,30,10,7.5,17.30520736,34.6708542,112.2141766,82.69479264,3.191344105,0.025790159,75.92258369,0.174728179,103.6591095,44.26084841,82.55750391
705,D,0.4,3,4,3,60,10,7.5,28.1793588,42.16451099,84.93681303,71.8206412,5.51257463,0.031389591,162.0123163,0.173859763,217.1989687,86.42127608,158.5990261
715,D,0.2,3,4,4,60,10,7.5,12.7476245,38.44677773,173.1194881,87.2523755,2.443035895,0.025488604,57.3835033,0.112620044,74.66923068,32.23064939,60.93034228
725,D,0.3,4,3,3,0,15,7.5,21.09172161,62.84318364,113.2871962,78.90827839,4.198573521,0.022942213,87.92742083,0.152599684,127.4399123,55.21758958,109.5128955
735,D,0.4,3,3,4,0,15,7.5,28.1882963,63.52109265,84.54374008,71.8117037,7.422381661,0.030702162,213.0384,0.157623959,262.8237056,90.40838421,177.69541
745,D,0.2,3,3,3,30,15,7.5,15.47066306,68.92868183,167.3211136,84.52933694,2.995336962,0.025223291,69.56158238,0.192054701,100.9596951,44.10186038,87.6258322
755,D,0.3,4,4,3,30,15,7.5,19.11854136,57.86808268,114.0681871,80.88145864,3.137451357,0.026785887,77.76451351,0.131365283,108.1927468,48.03992819,97.02213134
765,D,0.4,3,4,4,30,15,7.5,25.52947415,58.27951092,84.96507608,74.47052585,5.419702177,0.026944631,135.1924718,0.151912038,181.6496922,74.51518424,137.874802
775,D,0.2,3,4,3,60,15,7.5,14.02137665,62.74366124,171.7567005,85.97862335,2.809979384,0.02569271,66.57602618,0.150475327,89.2464376,39.03515135,75.68081513
785,D,0.3,4,3,4,60,15,7.5,19.14636555,57.82424181,114.1319366,80.85363445,3.126250069,0.025125139,72.2949663,0.167833742,108.0578725,47.76568466,95.38007818
795,D,0.4,3,3,3,0,20,7.5,30.91540808,91.14289269,82.90241147,69.08459192,8.015249205,0.022272859,162.4920156,0.177238989,233.5695225,102.5851161,215.1947713
805,D,0.2,3,3,4,0,20,7.5,14.02804205,84.74176841,169.9393446,85.97195795,4.230285803,0.021585419,82.85192083,0.086632186,118.4975376,42.93559345,72.0232156
815,D,0.3,4,4,4,0,20,7.5,17.33629078,69.14927629,111.7444623,82.66370922,4.05848149,0.022266929,82.2529545,0.109382915,103.9341344,47.50842702,96.96981263
825,D,0.4,3,4,3,30,20,7.5,28.14371741,83.25526578,83.75278892,71.85628259,5.899636696,0.024313793,131.6432733,0.15372436,196.7458445,82.25485816,164.1591068
835,D,0.2,3,4,4,30,20,7.5,12.76340857,78.10285511,171.166779,87.23659143,2.614249417,0.023621374,56.52366342,0.120982134,75.77568371,32.75052224,64.34992643
845,D,0.3,4,3,3,60,20,7.5,21.04535349,84.63824101,113.4122383,78.95464651,4.129928337,0.024181099,91.60635097,0.187918389,135.4856075,60.1466117,119.9914759
855,D,0.4,3,3,4,60,20,7.5,28.17048817,83.81787808,84.07558363,71.82951183,6.223317904,0.022655536,128.5459656,0.185428643,193.8786844,77.93227129,160.5017181
865,D,0.2,3,3,3,0,8,10,15.264578,64.8874639,168.7938649,84.735422,2.491929245,0.033845467,79.35665052,0.108372971,99.70945734,48.21578588,102.2236238
875,D,0.3,4,4,3,0,8,10,19.00933553,54.91798341,114.3741202,80.99066447,2.901770999,0.024564059,65.47573168,0.176139325,96.81757678,45.29101213,89.52059511
885,D,0.4,3,4,4,0,8,10,25.55261628,54.78115643,85.16661822,74.44738372,4.40264968,0.037703991,157.1921636,0.135310382,195.7307058,86.78077769,172.0174148
895,D,0.2,3,4,3,30,8,10,14.05445742,60.32562992,170.6111427,85.94554258,2.053144947,0.030656914,58.8367988,0.165777415,83.68488376,37.20565953,75.29948472
905,D,0.3,4,3,4,30,8,10,19.14202374,54.82077395,113.6182985,80.85797626,3.12113972,0.031473477,91.99083895,0.168646961,128.5556006,52.5577553,99.79394218
915,D,0.4,3,3,3,60,8,10,30.9543339,65.04176677,82.9837202,69.0456661,5.024209734,0.036992093,175.8076119,0.189001799,244.8017609,101.0824671,197.643347
925,D,0.2,3,3,4,60,8,10,14.091377,60.75840132,171.0981024,85.908623,1.991284312,0.031717302,59.17559689,0.155625746,83.56869699,37.5379935,76.23693585
935,D,0.3,4,4,4,60,8,10,17.39053076,49.43317951,112.5594207,82.60946924,2.570158579,0.033292561,80.42684535,0.15581122,107.1914116,46.23243891,90.37613584
945,D,0.4,3,4,3,0,10,10,28.35148606,74.72857308,83.96106458,71.64851394,5.699748889,0.023849631,124.5374078,0.188277102,187.8244934,83.44709195,176.234161
955,D,0.2,3,4,4,0,10,10,12.77055116,68.02735561,170.729799,87.22944884,3.040235619,0.024422703,68.17029942,0.089722019,87.02144943,39.82643284,84.42865833
965,D,0.3,4,3,3,30,10,10,21.0985274,74.57598986,112.9829456,78.9014726,3.618372115,0.029304177,98.79667373,0.199482155,138.1769609,60.07530982,119.663349
975,D,0.4,3,3,4,30,10,10,28.12560664,74.3866514,84.14533404,71.87439336,4.814176549,0.037601077,171.3898691,0.164470077,218.5845684,88.8044693,163.7467361
985,D,0.2,3,3,3,60,10,10,15.45455214,80.2996049,167.9698539,84.54544786,2.644182339,0.029800541,73.50969908,0.162640262,101.8832124,44.73947867,88.53384351
995,D,0.3,4,4,3,60,10,10,19.13919261,68.61976188,113.8888538,80.86080739,3.088976028,0.033058479,95.93889828,0.159129965,127.9872797,53.19832413,102.825025
1005,D,0.4,3,4,4,60,10,10,25.56504574,68.07018592,85.43190074,74.43495426,4.797733237,0.03172242,142.6002431,0.133698118,186.5284801,76.3441573,140.3336661
1015,D,0.2,3,4,3,0,15,10,14.01884595,111.8875917,170.1217372,85.98115405,2.639609308,0.023964501,57.97770125,0.181639242,79.9991154,36.15190196,71.84062717
1025,D,0.3,4,3,4,0,15,10,19.14024979,102.1974525,113.3597016,80.85975021,4.293759948,0.027969162,111.5053475,0.111372709,139.2399457,59.32459566,110.8604865
1035,D,0.4,3,3,3,30,15,10,30.92743843,120.0254596,82.13443841,69.07256157,7.008811147,0.025065877,161.664375,0.168056663,236.2362772,99.57767198,193.5153461
1045,D,0.2,3,3,4,30,15,10,14.0044327,112.6016938,169.9981967,85.9955673,2.951015335,0.023607491,63.76403753,0.11147155,106.2038896,34.90541559,63.5598031
1055,D,0.3,4,4,4,30,15,10,17.40127574,92.2042588,111.6549802,82.59872426,3.357011384,0.02500903,77.2415768,0.151666021,104.9928112,45.17489555,85.39734992
1065,D,0.4,3,4,3,60,15,10,28.10382738,110.8364868,83.66831211,71.89617262,6.406458328,0.026585602,157.5066367,0.16460859,215.5512339,65.66861599,162.4046473
1075,D,0.2,3,4,4,60,15,10,12.75726536,102.7855177,170.250241,87.24273464,2.340252218,0.02781984,60.4249386,0.116390626,77.41003774,32.50754917,63.05572174
1085,D,0.3,4,3,3,0,20,10,20.9587547,148.4171033,112.7825233,79.0412453,4.875452339,0.022096347,97.97878117,0.172403264,140.2416096,56.38917454,116.8931291
1095,D,0.4,3,3,4,0,20,10,28.05235152,147.0510406,83.51996596,71.94764848,9.155089876,0.022683105,189.3556853,0.17008419,281.9111312,72.6419826,204.369456
1105,D,0.2,3,3,3,30,20,10,15.4381538,159.6783865,166.9173841,84.5618462,2.686265883,0.033662833,85.05478851,0.185528839,118.1986111,44.08138018,86.67639644
1115,D,0.3,4,4,3,30,20,10,19.15059124,135.8441919,112.953281,80.84940876,3.263495503,0.027423955,82.97096333,0.144974649,108.4220513,49.53690788,101.2330937
1125,D,0.4,3,4,4,30,20,10,25.46806715,134.334676,84.60317617,74.53193285,6.416997266,0.023876939,140.3842562,0.15374763,186.1128715,69.43884054,124.6449136
1135,D,0.2,3,4,3,60,20,10,14.00575481,149.2738894,170.4795335,85.99424519,2.903072499,0.025649881,68.65731778,0.140056562,91.78040595,28.62167381,74.86773233
1145,D,0.3,4,3,4,60,20,10,19.17070331,136.9025757,112.479935,80.82929669,3.267794073,0.027461398,83.20260461,0.148768663,108.3433293,49.42862454,100.7654219
3,G,0.4,3,3,3,0,8,2.5,25.89409839,3.582782123,86.57029645,74.10590161,3.425187492,0.029543392,94.34128238,0.194671333,130.2387252,59.63100242,117.8464306
13,G,0.2,3,3,4,0,8,2.5,11.76682844,3.210675274,171.3541818,88.23317156,2.292816904,0.022542645,47.10052449,0.089804992,57.4875229,25.30222527,45.50412911
23,G,0.3,4,4,4,0,8,2.5,14.15777121,2.574165486,113.1083694,85.84222879,1.151179443,0.030380763,32.67135065,0.105573326,43.26689785,19.39741107,37.28189723
33,G,0.4,3,4,3,30,8,2.5,23.4993156,3.274581052,88.37149509,76.5006844,3.415915236,0.025263762,79.46704033,0.123432435,111.7525288,50.6541359,99.09726504
43,G,0.2,3,4,4,30,8,2.5,10.83181131,2.908842464,170.4036217,89.16818869,1.411699415,0.025862556,33.68675685,0.062402677,42.08264015,18.35882202,35.96561458
53,G,0.3,4,3,3,60,8,2.5,17.05774937,3.186810074,117.5096369,82.94225063,1.903870821,0.024228392,42.31998604,0.193121016,63.64391461,29.28525171,58.89643016
63,G,0.4,3,3,4,60,8,2.5,23.08274843,3.222099834,87.29320783,76.91725157,3.006682949,0.028710381,80.30964665,0.114483222,111.6671291,38.11390176,63.59462559
73,G,0.2,3,3,3,0,10,2.5,13.02661448,4.269101798,166.5950383,86.97338552,1.291550714,0.035441482,43.19136937,0.100337589,53.02211454,24.77045999,49.33772686
83,G,0.3,4,4,3,0,10,2.5,15.69397504,3.62344426,115.9636949,84.30602496,1.253334337,0.026067457,30.16457035,0.117446876,42.81170793,20.0387642,39.98706946
93,G,0.4,3,4,4,0,10,2.5,20.81136911,3.823017667,91.16830766,79.18863089,2.882432258,0.022837588,60.06293539,0.090765941,75.2503768,35.77653061,69.49655015
103,G,0.2,3,4,3,30,10,2.5,11.73063947,3.989801542,169.9850633,88.26936053,1.387879036,0.028064078,36.17378803,0.077485281,44.6444984,16.48640587,36.54847125
113,G,0.3,4,3,4,30,10,2.5,16.13879714,3.696421498,115.8259329,83.86120286,2.303599493,0.025463308,54.05006542,0.088905394,68.96124897,29.67529511,59.56776321
123,G,0.4,3,3,3,60,10,2.5,25.41241827,4.419198577,87.41725737,74.58758173,3.762411314,0.027034015,94.18826188,0.161295724,129.0753635,54.46885449,102.9921492
133,G,0.2,3,3,4,60,10,2.5,11.49261798,3.849174515,169.3651881,88.50738202,1.544998782,0.023565757,33.31906761,0.058157331,41.78895758,11.32313277,18.37633892
143,G,0.3,4,4,4,60,10,2.5,14.84214309,3.368492615,113.5514987,85.15785691,2.049319816,0.024172926,45.43941652,0.07862103,57.6554459,25.65524116,50.21545812
297,G,0.4,3,4,3,0,8,5,23.33482546,12.60742814,85.48009676,76.66517454,3.523076821,0.023686745,76.40406989,0.16702497,105.7341431,49.98551471,100.5419308
307,G,0.2,3,4,4,0,8,5,10.61257769,11.25022709,168.4384664,89.38742231,1.512690508,0.027216408,38.14462046,0.199367806,49.53159026,22.69514376,46.77910239
317,G,0.3,4,3,3,30,8,5,17.52738289,12.48344489,112.6359867,82.47261711,2.284236362,0.027036099,57.18836751,0.142538518,82.18081598,38.66306327,77.75846215
327,G,0.4,3,3,4,30,8,5,23.47503035,12.6553594,84.57804515,76.52496965,4.223169088,0.027703917,108.5519864,0.130003005,148.0532853,61.76251272,114.9368634
337,G,0.2,3,3,3,60,8,5,12.83934355,13.50783421,165.5448857,87.16065645,1.58927897,0.034449937,51.57200252,0.108428836,64.72209519,29.36268484,57.55518176
347,G,0.3,4,4,3,60,8,5,16.01063465,11.41240855,112.7076023,83.98936535,1.984426613,0.03595763,67.38642561,0.072857454,78.52099023,34.30595822,64.17141561
357,G,0.4,3,4,4,60,8,5,21.50299918,11.6555088,85.54677488,78.49700082,3.843051933,0.026708102,94.95451939,0.144054174,128.6693982,54.68272517,103.8738567
367,G,0.2,3,4,3,0,10,5,11.7821118,15.65417897,167.9693047,88.2178882,1.431743947,0.026076157,34.47089267,0.149140692,45.75169633,21.50765537,44.14187798
377,G,0.3,4,3,4,0,10,5,16.01636997,14.18689661,113.1486432,83.98363003,3.113533559,0.023381422,66.57177492,0.163881111,84.83923685,35.90170769,68.01820722
387,G,0.4,3,3,3,30,10,5,25.82974466,16.61535395,82.71999258,74.17025534,4.225678201,0.028767752,113.1119074,0.16529963,153.2462712,66.54755617,124.7596098
397,G,0.2,3,3,4,30,10,5,11.7159197,15.65752449,166.8029949,88.2840803,2.106844948,0.025521882,49.55695931,0.078697622,62.64665505,27.47935649,56.38126037
407,G,0.3,4,4,4,30,10,5,14.50050183,12.73512816,110.4519848,85.49949817,1.999132775,0.027607088,51.19196838,0.086374545,65.9710146,29.17499289,59.76913735
417,G,0.4,3,4,3,60,10,5,23.4891083,15.59209092,84.31823987,76.5108917,4.669677193,0.026373251,113.8152142,0.149896085,149.6580391,61.89094861,110.858156
427,G,0.2,3,4,4,60,10,5,10.69838031,14.13081275,167.6548158,89.30161969,1.801697954,0.025312008,42.00119732,0.091372716,52.42862221,22.14810434,43.60120253
437,G,0.3,4,3,3,0,15,5,17.65985262,23.23604893,111.2064209,82.34014738,2.573436468,0.023665032,55.75358225,0.155120786,78.91036744,35.80751421,71.51614168
447,G,0.4,3,3,4,0,15,5,23.41305801,23.31356231,83.88825664,76.58694199,5.440291698,0.023634096,117.6957906,0.147609075,147.9127412,62.56224111,116.2117948
457,G,0.2,3,3,3,30,15,5,12.88638032,24.81111523,163.3659551,87.11361968,2.164372869,0.024901655,49.56772025,0.102386713,63.92163703,29.32106035,58.04808796
467,G,0.3,4,4,3,30,15,5,15.9850471,21.12512888,111.5557982,84.0149529,2.00683494,0.024863921,45.88411547,0.12507809,63.18361831,28.71896974,56.94964185
477,G,0.4,3,4,4,30,15,5,21.32845907,21.2802696,84.38950036,78.67154093,4.233460464,0.024711981,96.15027203,0.108742269,122.5840222,43.74134031,89.33288635
487,G,0.2,3,4,3,60,15,5,11.71840013,22.46006895,166.6429029,88.28159987,2.182832096,0.025414749,51.11046657,0.069561791,62.48223856,26.99869361,51.90314074
497,G,0.3,4,3,4,60,15,5,16.04833914,21.27128132,111.9770901,83.95166086,2.083135636,0.024329729,46.51585429,0.082145802,62.51614625,29.2296684,58.77832864
507,G,0.4,3,3,3,0,20,5,25.72179694,33.41262126,81.97204215,74.27820306,5.184458659,0.022485609,106.2067948,0.144610631,139.9597618,62.27180358,124.8428958
517,G,0.2,3,3,4,0,20,5,11.69880644,30.55979369,166.2008594,88.30119356,2.648032815,0.022311366,53.78516466,0.072958672,64.39210208,28.49687623,56.51019075
527,G,0.3,4,4,4,0,20,5,14.59880905,25.21234609,109.7960036,85.40119095,2.314865707,0.023444169,49.64037059,0.09448514,64.31713081,28.67700585,57.55607328
537,G,0.4,3,4,3,30,20,5,23.48853716,30.98631013,83.93528089,76.51146284,4.211272965,0.023759762,91.63629653,0.10711844,120.5797076,52.21395385,105.4137942
547,G,0.2,3,4,4,30,20,5,10.67516424,27.99835804,166.406437,89.32483576,2.012457671,0.023095404,42.4536072,0.064250302,50.80930797,21.14696538,42.00643268
557,G,0.3,4,3,3,60,20,5,17.58738327,30.90673855,111.1217435,82.41261673,2.793399601,0.023666854,60.52418185,0.096999872,78.71798166,36.65769751,73.01876546
567,G,0.4,3,3,4,60,20,5,23.59411559,30.56465008,83.31249358,76.40588441,4.193030193,0.024217742,93.1596632,0.080650628,119.7575541,54.02345403,113.3234832
577,G,0.2,3,3,3,0,8,7.5,12.78345218,29.86866245,163.5072611,87.21654782,1.603491019,0.032557437,48.99857551,0.173186392,62.49006197,30.09592282,63.05417237
587,G,0.3,4,4,3,0,8,7.5,15.90163847,25.22975436,112.928598,84.09836153,1.576956383,0.028669548,42.05671355,0.166395009,59.04162578,28.13850501,58.26218232
597,G,0.4,3,4,4,0,8,7.5,21.32751993,25.46088371,84.20655126,78.67248007,2.899096734,0.036372207,99.64835225,0.159413099,123.1190362,54.69039369,113.6363455
607,G,0.2,3,4,3,30,8,7.5,11.69886379,27.61592392,166.4944452,88.30113621,1.459795342,0.031136173,42.53284954,0.11222177,55.26487392,25.14697111,50.23883129
617,G,0.3,4,3,4,30,8,7.5,15.95768931,25.34580845,111.9650848,84.04231069,1.557104333,0.05209405,78.00166291,0.116640627,85.50621392,37.37552884,73.57504231
627,G,0.4,3,3,3,60,8,7.5,25.83045788,30.03332961,82.56562783,74.16954212,3.840836946,0.032791938,118.2668145,0.160840183,157.6645593,70.15930012,141.8632398
637,G,0.2,3,3,4,60,8,7.5,11.69025391,27.34247704,166.6548364,88.30974609,1.360557369,0.032975514,42.1439639,0.108550213,54.04222753,24.85953134,49.00480004
647,G,0.3,4,4,4,60,8,7.5,14.49198615,22.74223617,110.114665,85.50801385,1.984130892,0.030815819,57.17435733,0.091880567,70.16812764,31.95082715,64.0387952
657,G,0.4,3,4,3,0,10,7.5,23.59408702,35.36680634,83.44399435,76.40591298,3.989134266,0.023057471,84.00108099,0.195340657,115.0412854,52.02299906,103.886815
667,G,0.2,3,4,4,0,10,7.5,10.64226228,31.30385806,166.0127947,89.35773772,1.908463392,0.024270274,42.50200318,0.080915874,52.3442247,24.22288371,47.96470465
677,G,0.3,4,3,3,30,10,7.5,17.54032703,34.26584198,110.8421192,82.45967297,2.431615851,0.02748708,61.97478816,0.161288857,85.71470268,39.50458841,80.93790651
687,G,0.4,3,3,4,30,10,7.5,23.47827716,34.70886445,83.2489156,76.52172284,5.052696335,0.025305342,117.7548152,0.147275758,155.3050604,64.23267136,116.6920242
697,G,0.2,3,3,3,60,10,7.5,12.90883245,37.13422986,163.2388263,87.09116755,1.920261839,0.027845229,49.62960659,0.101635289,65.68664201,30.15054828,60.02547143
707,G,0.3,4,4,3,60,10,7.5,15.94225328,31.3580156,110.4764332,84.05774672,2.319278397,0.031196414,67.7146132,0.091581011,83.8818018,37.03990583,72.45457627
717,G,0.4,3,4,4,60,10,7.5,21.15877922,31.59554627,83.67343312,78.84122078,4.099592186,0.026134534,98.94174531,0.106731081,127.9748033,53.57444003,100.1910053
727,G,0.2,3,4,3,0,15,7.5,11.71304337,51.25760936,165.181576,88.28695663,1.618900892,0.024148866,35.85681849,0.155156994,48.70485024,22.31812681,44.00260565
737,G,0.3,4,3,4,0,15,7.5,15.97810095,47.86554615,111.0272187,84.02189905,3.179231263,0.023010456,66.79709961,0.119813347,84.81025885,37.72840794,74.47871605
747,G,0.4,3,3,3,30,15,7.5,25.82513541,55.63858576,80.63031702,74.17486459,5.078165886,0.024780558,115.6834515,0.158022817,158.8412593,69.94786819,133.3904142
757,G,0.2,3,3,4,30,15,7.5,11.75062604,51.7828737,165.9115161,88.24937396,2.403294216,0.024391135,53.81248513,0.066969816,65.01625758,29.00616996,57.93892474
767,G,0.3,4,4,4,30,15,7.5,14.50446732,41.77806945,109.4485179,85.49553268,2.097999644,0.028883187,56.40091683,0.092475287,68.75874293,30.44872708,57.77706632
777,G,0.4,3,4,3,60,15,7.5,23.4511293,52.28013818,82.6689686,76.5488707,5.075508966,0.025256347,118.0377988,0.139112155,152.4905279,58.77084231,111.5055103
787,G,0.2,3,4,4,60,15,7.5,10.57173282,46.22919921,165.9951836,89.42826718,1.886377063,0.025171909,43.71095837,0.069575334,53.66322556,23.59906028,47.57984501
797,G,0.3,4,3,3,0,20,7.5,17.52984559,68.57200787,110.3655083,82.47015441,2.800025549,0.0227274,58.03724886,0.199917603,78.51945021,36.90410091,75.73630703
807,G,0.4,3,3,4,0,20,7.5,23.43595997,68.3257542,82.45221852,76.56404003,6.121768749,0.022099828,123.046499,0.152296591,155.2380947,65.7143677,119.8088239
817,G,0.2,3,3,3,30,20,7.5,12.87906632,74.4865549,162.3379989,87.12093368,2.318513264,0.023849299,50.65788842,0.115960932,65.93313921,30.37057349,60.27830166
827,G,0.3,4,4,3,30,20,7.5,15.90562575,62.80775383,110.734654,84.09437425,2.292331792,0.023726888,49.80523542,0.115951633,68.23119583,30.62244698,59.57149313
837,G,0.4,3,4,4,30,20,7.5,21.32971507,62.19921737,82.6781879,78.67028493,4.788883014,0.023046231,100.787938,0.144873643,130.4199599,54.51445359,101.6839349
847,G,0.2,3,4,3,60,20,7.5,11.70336152,68.64829364,164.7069587,88.29663848,2.475549716,0.023315549,52.76770157,0.066780674,64.3434343,27.83232621,55.52453777
857,G,0.3,4,3,4,60,20,7.5,15.89950816,62.43733333,110.5381758,84.10049184,2.263751532,0.023555098,48.79538573,0.115936208,67.70143468,31.15477691,62.01115402
867,G,0.4,3,3,3,0,8,10,25.6875712,53.54171899,81.99590512,74.3124288,3.82313729,0.031315356,112.0766323,0.171907529,148.7483569,68.67296907,140.9403516
877,G,0.2,3,3,4,0,8,10,11.70636406,48.57208066,166.3876094,88.29363594,2.655459826,0.022951123,55.63486522,0.080964699,69.38846197,31.94336212,65.607138
887,G,0.3,4,4,4,0,8,10,14.49809815,40.24395385,109.3164634,85.50190185,1.843059371,0.031247833,53.90549353,0.132609546,69.78445127,31.62889772,64.74708646
897,G,0.4,3,4,3,30,8,10,23.41114623,49.19686542,83.13931315,76.58885377,3.482327952,0.030514968,99.2984695,0.16708079,133.7557004,59.38858668,117.4578977
907,G,0.2,3,4,4,30,8,10,10.61708113,44.65687402,166.6784261,89.38291887,1.643940495,0.029296106,44.87317341,0.074013144,55.95747734,24.68974148,48.27902922
917,G,0.3,4,3,3,60,8,10,17.55954699,49.1661156,110.1576222,82.44045301,2.194192036,0.032107901,66.06251632,0.15827778,87.08692616,40.66402099,82.05227877
927,G,0.4,3,3,4,60,8,10,23.31865947,48.69213365,83.11073513,76.68134053,3.183248111,0.03415044,102.3428286,0.155796081,133.6207361,58.88065482,119.0331968
937,G,0.2,3,3,3,0,10,10,12.965173,65.95533031,162.2216908,87.034827,1.636419329,0.034092587,52.516929,0.167660451,65.33199043,29.80586949,60.0325411
947,G,0.3,4,4,3,0,10,10,16.04266002,55.78670474,110.9001622,83.95733998,1.89540085,0.026323259,46.10232625,0.187167299,63.35020485,29.21722445,59.94941311
957,G,0.4,3,4,4,0,10,10,21.29239207,55.68233621,82.90279085,78.70760793,4.350093824,0.024147601,96.34414024,0.132773471,123.818347,54.70291036,107.6303833
967,G,0.2,3,4,3,30,10,10,11.67504176,61.07200549,165.9833687,88.32495824,1.641936671,0.027565328,41.97665037,0.106709242,56.08176756,25.51981825,49.44770351
977,G,0.3,4,3,4,30,10,10,15.97519232,55.82216096,110.7396776,84.02480768,2.494774595,0.029895219,69.59228347,0.100504947,88.00646438,38.90438312,76.56746673
987,G,0.4,3,3,3,60,10,10,25.84109179,66.03181787,81.10369496,74.15890821,3.801388587,0.034892305,125.0364336,0.198807907,160.6053018,70.39743449,141.8791451
997,G,0.2,3,3,4,60,10,10,11.66053876,60.70127989,165.4562338,88.33946124,1.494592504,0.030000648,41.84955838,0.192189598,54.94055255,25.34015751,51.37017392
1007,G,0.3,4,4,4,60,10,10,14.5221049,49.99713714,108.0345484,85.4778951,2.182946335,0.027530819,55.73240752,0.087705231,71.35639674,32.14084246,63.97628295
1017,G,0.4,3,4,3,0,15,10,23.4639983,90.60433668,82.11661629,76.5360017,3.741108472,0.024356273,83.6372409,0.185433547,115.0673447,51.66756912,102.6051555
1027,G,0.2,3,4,4,0,15,10,10.63356255,83.18803844,166.51457,89.36643745,1.968250066,0.023638318,42.58962177,0.095871687,53.54667681,22.92220094,42.9531637
1037,G,0.3,4,3,3,30,15,10,17.55874718,91.85924363,109.890057,82.44125282,2.728120573,0.025635396,64.48021054,0.174429401,86.68408807,39.87244454,79.37242925
1047,G,0.4,3,3,4,30,15,10,23.43876111,91.2664025,81.86813153,76.56123889,5.425793043,0.024277968,120.8756436,0.126378187,154.2873971,64.40065365,119.356581
1057,G,0.2,3,3,3,60,15,10,12.88323099,99.34321745,162.1237804,87.11676901,2.15106531,0.026274658,52.21637528,0.126506352,66.91316836,30.70337274,59.98055152
1067,G,0.3,4,4,3,60,15,10,15.94181691,83.19972019,109.6724858,84.05818309,2.89956373,0.025984399,69.5442946,0.096132215,86.59975694,37.84550347,73.3666626
1077,G,0.4,3,4,4,60,15,10,21.35569432,84.44976645,82.50116174,78.64430568,4.456406949,0.025105103,102.9657425,0.1075188,131.2049533,54.56063996,99.20165244
1087,G,0.2,3,4,3,0,20,10,11.65688425,120.4821211,164.4966483,88.34311575,1.730387244,0.022656481,35.74371083,0.199935102,48.12213527,22.34513479,46.45482809
1097,G,0.3,4,3,4,0,20,10,15.9897625,110.3225634,109.5830073,84.0102375,3.453159622,0.022698719,71.4759797,0.109604526,89.00550803,38.03034545,70.6147885
1107,G,0.4,3,3,3,30,20,10,25.81656814,129.5236689,80.27930553,74.18343186,5.295356472,0.02381469,115.5165617,0.185334456,159.1134333,70.0397571,135.665674
1117,G,0.2,3,3,4,30,20,10,11.71340023,121.2430172,165.3097286,88.28659977,2.510571855,0.023292134,53.45543228,0.079402912,66.05665213,28.79954417,56.92851237
1127,G,0.3,4,4,4,30,20,10,14.51983288,98.94190274,108.3692446,85.48016712,2.554859861,0.023933504,56.03702796,0.09460178,72.57123468,32.09302204,60.89703671
1137,G,0.4,3,4,3,60,20,10,23.46449061,121.6499714,81.85153934,76.53550939,5.749783217,0.022749187,119.3033255,0.14364022,153.8420647,60.07014546,116.1225524
1147,G,0.2,3,4,4,60,20,10,10.63846023,110.4612914,164.2362597,89.36153977,2.086577457,0.023666703,45.20925324,0.071879691,55.97024691,24.89118742,50.2210395
5,S,0.3,4,3,3,0,8,2.5,23.69453307,5.24020953,138.0728221,76.30546693,5.217364089,0.02311727,110.1764845,0.184093118,166.2117982,78.7182901,164.4950544
15,S,0.4,3,3,4,0,8,2.5,31.77236481,5.227327462,103.9656631,68.22763519,10.0700766,0.022936207,210.82921,0.160075366,309.3412933,129.4247885,248.4929282
25,S,0.2,3,3,3,30,8,2.5,17.53019771,5.634806509,205.6156493,82.46980229,4.049334275,0.02436733,90.57279613,0.17599526,129.9222197,64.59448101,136.2583154
35,S,0.3,4,4,3,30,8,2.5,21.38574556,4.695250595,138.1599883,78.61425444,4.016348281,0.024872571,91.86421113,0.198718548,135.6440367,63.11994237,131.2495721
45,S,0.4,3,4,4,30,8,2.5,28.8143008,4.825647852,104.4980117,71.1856992,7.703383175,0.02433883,172.0845699,0.150715858,242.538949,105.4867384,209.374182
55,S,0.2,3,4,3,60,8,2.5,15.67343293,5.075901622,208.422248,84.32656707,3.952360378,0.024536151,89.07098885,0.137910202,114.6486199,54.64395829,112.7034483
65,S,0.3,4,3,4,60,8,2.5,21.06104553,4.653401584,138.9476086,78.93895447,3.750351811,0.025618993,88.57953435,0.115205362,127.1433748,53.14761244,104.5094339
75,S,0.4,3,3,3,0,10,2.5,34.65934316,7.081630264,102.0280392,65.34065684,8.113428853,0.02642572,198.1763442,0.169586039,304.2708634,137.332291,282.4073918
85,S,0.2,3,3,4,0,10,2.5,15.81316646,6.401670451,208.2094839,84.18683354,3.968339106,0.02440562,88.91309667,0.113916564,124.3455596,52.47664332,103.9265927
95,S,0.3,4,4,4,0,10,2.5,19.08848573,5.213184972,139.0550476,80.91151427,4.348260541,0.023236193,92.34050084,0.128607559,128.5584961,57.9230585,115.0863371
105,S,0.4,3,4,3,30,10,2.5,31.79917125,6.46754214,102.6068242,68.20082875,7.720978889,0.024362757,172.6623779,0.137773049,248.7328353,114.9673919,238.8099737
115,S,0.2,3,4,4,30,10,2.5,14.32756015,5.782229573,208.7218498,85.67243985,3.642043348,0.023220206,77.28490884,0.107209992,100.6105763,44.52719064,90.8421053
125,S,0.3,4,3,3,60,10,2.5,23.43224242,6.325846155,138.7490667,76.56775758,4.552160991,0.026057611,109.5141204,0.17817378,158.4413071,76.87338659,160.9248496
135,S,0.4,3,3,4,60,10,2.5,31.9179731,6.568220686,103.272859,68.0820269,7.310103268,0.024367586,163.5093653,0.131356192,236.9206649,110.4240168,230.616531
289,S,0.2,3,3,3,0,8,5,17.53391006,21.98368655,201.3420502,82.46608994,4.644591155,0.022942094,97.26746472,0.186629921,143.2002055,64.7351422,130.5655596
299,S,0.3,4,4,3,0,8,5,21.77695818,18.79581654,135.4756603,78.22304182,4.59263057,0.023310513,97.87131528,0.189111397,146.668944,66.06901714,133.4241999
309,S,0.4,3,4,4,0,8,5,28.64628631,18.20588253,101.3313304,71.35371369,7.390267055,0.026207884,178.9027298,0.18748495,259.6848754,110.8953912,223.7826474
319,S,0.2,3,4,3,30,8,5,15.8494884,20.04178976,204.7874936,84.1505116,3.430934133,0.025816567,81.7130714,0.188770354,120.7447418,55.82374735,114.3296422
329,S,0.3,4,3,4,30,8,5,21.62476575,18.44703171,135.6272768,78.37523425,4.809722062,0.026520713,117.9378133,0.198959395,176.0867197,80.64003299,168.3814277
339,S,0.4,3,3,3,60,8,5,34.77591331,21.58657111,98.14430907,65.22408669,8.859535604,0.025910723,211.8379059,0.198868886,322.4046684,149.7250625,315.4413576
349,S,0.2,3,3,4,60,8,5,15.88918115,20.18892838,207.1824418,84.11081885,3.34747474,0.026046675,80.49563701,0.186234295,114.2900528,54.71444233,113.3559898
359,S,0.3,4,4,4,60,8,5,19.61246568,16.77501463,133.9722591,80.38753432,4.099482277,0.025754236,97.38007051,0.195112735,133.6393095,64.66577929,134.1391361
369,S,0.4,3,4,3,0,10,5,31.21323845,24.79844947,100.5722064,68.78676155,7.700677101,0.02381364,167.9797988,0.153887796,253.8575795,119.2248272,247.6643023
379,S,0.2,3,4,4,0,10,5,14.28978032,23.00245565,207.7528888,85.71021968,3.6302462,0.024157267,80.43633254,0.135022271,106.3231919,48.38517042,97.70728255
389,S,0.3,4,3,3,30,10,5,23.72417348,25.08385091,133.7647092,76.27582652,5.266629157,0.024618873,119.1252184,0.190644455,184.0347255,87.82467676,184.2708474
399,S,0.4,3,3,4,30,10,5,31.62922475,24.98456194,98.82711655,68.37077525,8.678662022,0.026330839,211.1591308,0.188550794,305.5140608,132.657607,266.0977387
409,S,0.2,3,3,3,60,10,5,17.38203367,27.09401144,202.0326595,82.61796633,4.150839784,0.025252218,96.51623037,0.187019038,139.410865,66.07921162,138.5227773
419,S,0.3,4,4,3,60,10,5,21.51644055,22.79244749,135.4926615,78.48355945,5.236502771,0.025150398,121.2271222,0.149083984,166.5458576,78.73622276,160.3601841
429,S,0.4,3,4,4,60,10,5,28.7624077,22.76165531,100.5704925,71.2375923,7.462536252,0.026934955,186.0780078,0.167062545,257.1522738,117.4301491,237.6964467
439,S,0.2,3,4,3,0,15,5,15.72412199,37.3488146,206.9960993,84.27587801,3.249228344,0.024712666,73.7986381,0.197619661,110.1736831,50.36430804,101.531507
449,S,0.3,4,3,4,0,15,5,21.68668225,34.00480973,132.8605059,78.31331775,5.659770963,0.024077192,124.9518489,0.144819291,177.5296572,79.03473453,157.6826685
459,S,0.4,3,3,3,30,15,5,34.84512333,40.06821483,96.66514167,65.15487667,9.834198425,0.023581954,212.2412194,0.181435172,331.753863,148.8822861,307.8869963
469,S,0.2,3,3,4,30,15,5,15.80217403,37.17485545,206.1036994,84.19782597,4.480174891,0.023227555,95.10315799,0.13222429,129.9684316,60.96630859,124.1548681
479,S,0.3,4,4,4,30,15,5,19.52873859,30.6402095,132.970591,80.47126141,4.772249981,0.02355699,102.8753463,0.156117185,143.3666107,64.99576424,130.4281694
489,S,0.4,3,4,3,60,15,5,31.62887044,36.99746309,98.82085929,68.37112956,10.09192048,0.023102976,212.9695523,0.185108153,302.6732177,135.4295915,276.9651076
499,S,0.2,3,4,4,60,15,5,14.41118665,34.27100186,205.458384,85.58881335,3.895873158,0.023498328,83.75476013,0.159918276,109.3196964,50.18924557,100.63446
509,S,0.3,4,3,3,0,20,5,23.72567281,50.07218881,133.9938753,76.27432719,5.903047678,0.0218063,116.9175356,0.17796967,180.2873365,81.03203466,166.3840676
519,S,0.4,3,3,4,0,20,5,31.5990649,49.39026568,98.53407503,68.4009351,11.06924817,0.021796957,219.1374336,0.147948456,312.0575314,108.2319403,228.8577461
529,S,0.2,3,3,3,30,20,5,17.28763903,53.62260967,200.8813727,82.71236097,4.251887547,0.02371107,92.3130261,0.182732511,150.8860747,66.39635169,136.5389469
539,S,0.3,4,4,3,30,20,5,21.36985009,45.31023727,134.0625076,78.63014991,4.528675623,0.023956891,99.43563851,0.142407489,150.7365624,68.94730029,141.9745865
549,S,0.4,3,4,4,30,20,5,28.46065754,44.66846344,99.97902576,71.53934246,8.358904763,0.022867328,174.4280071,0.134836292,253.82387,102.4093866,212.5051797
559,S,0.2,3,4,3,60,20,5,15.63892698,49.72142198,203.9206879,84.36107302,4.381921664,0.022999348,92.0174998,0.105858839,126.9041826,59.026431,119.8513262
569,S,0.3,4,3,4,60,20,5,21.37162622,44.82160191,133.7455353,78.62837378,3.969740386,0.022482626,81.31070622,0.137433243,165.5750793,66.17647007,138.1012497
579,S,0.4,3,3,3,0,8,7.5,35.55046654,48.33041106,95.77064903,64.44953346,11.11628991,0.02289928,232.3224499,0.160155267,343.0380079,151.0604988,304.2390968
589,S,0.2,3,3,4,0,8,7.5,15.94859908,45.09536284,203.6947241,84.05140092,4.767514082,0.023535939,102.6728932,0.157764435,140.9958648,63.19969376,123.926563
599,S,0.3,4,4,4,0,8,7.5,19.80152134,37.08560922,131.7050552,80.19847866,5.14778623,0.023076667,108.4981761,0.153819442,147.6327193,65.82749282,129.3360976
609,S,0.4,3,4,3,30,8,7.5,31.81337696,44.27948151,98.60409012,68.18662304,8.070158699,0.025626884,190.6727048,0.198921859,291.8197429,128.9413918,264.5747629
619,S,0.2,3,4,4,30,8,7.5,14.44313559,41.12753256,204.4832954,85.55686441,3.566241278,0.02629127,86.62852956,0.142021582,117.9106877,52.94970775,104.7745409
629,S,0.3,4,3,3,60,8,7.5,23.87723266,44.85728491,132.8224536,76.12276734,5.342287317,0.024850751,122.0752789,0.175765514,192.5883518,86.93258821,181.148626
639,S,0.4,3,3,4,60,8,7.5,31.87086098,44.56989645,98.73474913,68.12913902,7.827782882,0.025985148,187.7505287,0.179994926,279.5864397,128.0331405,262.4692223
649,S,0.2,3,3,3,0,10,7.5,17.37862256,60.65841627,201.8186519,82.62137744,3.940411252,0.026057305,94.79567429,0.184767139,145.9019884,68.14287602,142.8394374
659,S,0.3,4,4,3,0,10,7.5,21.55281575,50.70156326,134.0989213,78.44718425,4.52698662,0.024163571,100.3341898,0.157650375,147.1000589,69.5858965,144.0735709
669,S,0.4,3,4,4,0,10,7.5,28.96126033,50.875533,98.83719104,71.03873967,9.005164762,0.023879043,197.0243859,0.134970975,277.9046054,114.1090473,225.4141346
679,S,0.2,3,4,3,30,10,7.5,15.89685846,55.72139472,203.0265183,84.10314154,3.672676064,0.025079668,84.76414551,0.1933617,125.6047225,57.87374479,118.068103
689,S,0.3,4,3,4,30,10,7.5,21.68586061,51.18191261,133.6821125,78.31413939,5.275263764,0.025440916,123.6570146,0.185863256,180.0313999,81.73287949,168.5466243
699,S,0.4,3,3,3,60,10,7.5,35.03129433,59.93155227,95.9921396,64.96870567,9.709579964,0.025082048,224.116994,0.199656308,336.306465,153.1534948,318.8931169
709,S,0.2,3,3,4,60,10,7.5,15.91665027,56.29971713,204.7381711,84.08334973,3.644420881,0.02542276,85.36239488,0.174538565,120.8783346,54.95271374,113.0141934
719,S,0.3,4,4,4,60,10,7.5,19.72838277,45.80639105,131.3580408,80.27161723,4.662589843,0.025173853,108.0501729,0.130160344,143.8342409,67.36347772,138.0717414
729,S,0.4,3,4,3,0,15,7.5,31.88904953,82.71156001,96.86174998,68.11095047,7.870085558,0.024641982,178.1943387,0.197700977,278.0404999,123.2694543,252.4387179
739,S,0.2,3,4,4,0,15,7.5,14.62848084,77.43935447,202.3686744,85.37151916,3.988738625,0.023809858,86.99382206,0.152332735,116.3307777,49.82868842,99.47821793
749,S,0.3,4,3,3,30,15,7.5,23.92515258,83.05515329,131.6742081,76.07484742,5.583146733,0.023610939,120.6570445,0.198917818,188.7599435,88.96809822,186.0570307
759,S,0.4,3,3,4,30,15,7.5,31.78547228,82.075936,97.51326931,68.21452772,10.32942688,0.022845581,215.322906,0.163670635,320.9223296,136.9162829,270.9168655
769,S,0.2,3,3,3,60,15,7.5,17.50718533,91.24893011,199.1121801,82.49281467,4.522588907,0.023867798,98.89906234,0.199007193,144.9163365,67.74014215,140.6683103
779,S,0.3,4,4,3,60,15,7.5,21.68299212,76.44898131,132.4139732,78.31700788,5.777457957,0.023383771,123.5438363,0.178811741,172.7464085,81.31742059,165.7670696
789,S,0.4,3,4,4,60,15,7.5,28.88721669,74.94842322,98.70418447,71.11278331,8.905496788,0.023083187,187.7562581,0.157401244,264.8707384,114.9225128,228.9561355
799,S,0.2,3,4,3,0,20,7.5,15.96144831,112.1302504,203.1756301,84.03855169,3.460328459,0.024089904,76.43832281,0.197491884,116.1126181,53.09023137,108.1261239
809,S,0.3,4,3,4,0,20,7.5,21.68465348,102.0544457,132.1993068,78.31534652,6.026700037,0.023151831,127.4757393,0.148438287,187.3167715,82.7238366,163.3838982
819,S,0.4,3,3,3,30,20,7.5,33.67205603,112.671978,95.24358693,66.32794397,11.6175481,0.022668749,240.1201813,0.158889008,385.0238324,150.6390088,309.5029663
829,S,0.2,3,3,4,30,20,7.5,15.25987215,107.4528268,203.8688775,84.74012785,4.558960158,0.02447145,102.4464471,0.14619472,136.848569,60.69175969,119.4855105
839,S,0.3,4,4,4,30,20,7.5,18.90613363,88.1190248,131.1396149,81.09386637,4.889382846,0.025371951,114.2744165,0.152520728,150.6223635,66.94990095,133.0397729
849,S,0.4,3,4,3,60,20,7.5,30.53972719,105.6734658,96.9411626,69.46027281,10.07286818,0.02384316,220.0232698,0.182719421,315.6305162,134.4625198,261.3735116
859,S,0.2,3,4,4,60,20,7.5,13.84550082,97.74964345,203.2656339,86.15449918,3.754786966,0.026046855,90.29081706,0.110999787,114.4046907,50.72589357,101.0177985
869,S,0.3,4,3,3,0,8,10,24.11118383,79.73969167,130.6298527,75.88881617,5.087344871,0.027135489,127.8729028,0.162140012,190.4301387,83.48899542,165.1004388
879,S,0.4,3,3,4,0,8,10,31.7921343,78.51938558,97.81210771,68.2078657,10.80755988,0.023452241,231.8463745,0.151538163,337.7433392,131.5430659,249.0628236
889,S,0.2,3,3,3,30,8,10,17.44601124,86.24399087,200.9177778,82.55398876,4.079179396,0.026894373,101.5486117,0.193963826,152.2788098,68.17330294,138.3289333
899,S,0.3,4,4,3,30,8,10,21.66456913,72.21699892,132.4977064,78.33543087,4.214443643,0.027808236,108.7673556,0.19907707,161.9719018,72.32549873,148.4028267
909,S,0.4,3,4,4,30,8,10,28.7994836,72.73804206,99.51499134,71.2005164,8.14383144,0.0259769,195.2638333,0.157226011,276.0067206,114.0621692,214.336498
919,S,0.2,3,4,3,60,8,10,15.85258435,79.59099696,202.4656818,84.14741565,4.116069952,0.026503779,100.8592678,0.15468882,136.4973137,63.52632426,128.1769534
929,S,0.3,4,3,4,60,8,10,21.66406093,72.51568869,132.8351767,78.33593907,4.001792455,0.028418541,105.7215179,0.191601843,154.120482,71.77657441,149.552104
939,S,0.4,3,3,3,0,10,10,34.70391495,105.1862072,96.25394979,65.29608505,9.21197604,0.025374464,215.3250014,0.186031389,338.3237971,151.7094805,311.5420238
949,S,0.2,3,3,4,0,10,10,15.83493471,99.69228508,203.9518512,84.16506529,4.441002955,0.026005844,106.610026,0.15189476,143.9808767,63.57768128,124.1255526
959,S,0.3,4,4,4,0,10,10,19.72943412,81.09933024,130.2042272,80.27056588,4.403432384,0.026766763,109.0587655,0.151801753,150.6612097,66.40493072,129.5430112
969,S,0.4,3,4,3,30,10,10,31.63680016,97.52070099,97.07605495,68.36319984,6.08407852,0.036291854,208.6343343,0.196227145,292.7944378,130.6289576,271.3405537
979,S,0.2,3,4,4,30,10,10,14.3209207,90.2722117,204.2477033,85.6790793,3.051899206,0.032181773,92.11172978,0.160304737,125.6746582,53.13671244,106.3481617
989,S,0.3,4,3,3,60,10,10,23.74227891,98.00362526,131.4990773,76.25772109,4.420398199,0.030855849,127.5543416,0.199549174,187.5310302,88.7799196,185.6985038
999,S,0.4,3,3,4,60,10,10,31.60512907,97.53383984,97.56319022,68.39487093,7.143778036,0.02865303,190.4033303,0.19314642,284.146806,129.1579843,268.1861733
1009,S,0.2,3,3,3,0,15,10,17.44645971,160.8562612,200.217412,82.55354029,4.301999306,0.024246618,95.70493357,0.199333763,147.801017,67.08466902,137.5847663
1019,S,0.3,4,4,3,0,15,10,21.72489323,135.5091949,131.4301252,78.27510677,3.862536245,0.024540833,87.06478536,0.17967631,166.5878968,70.00747738,147.2277912
1029,S,0.4,3,4,4,0,15,10,29.24494053,133.601846,97.22829362,70.75505947,8.668517099,0.023707488,188.1717269,0.138757372,266.049753,115.2042027,223.1848922
1039,S,0.2,3,4,3,30,15,10,15.4108492,144.3308949,201.0106012,84.5891508,3.600702306,0.025535367,84.74385072,0.19210844,125.8500228,58.09590108,119.3553647
1049,S,0.3,4,3,4,30,15,10,20.99648221,131.3129439,131.9955502,79.00351779,4.73085091,0.029867674,131.8378099,0.159392993,186.191679,81.23064872,167.770248
1059,S,0.4,3,3,3,60,15,10,33.97280421,151.4866663,94.54815975,66.02719579,9.42825725,0.024886086,215.7759059,0.178234227,341.7758515,152.7024332,317.0576174
1069,S,0.2,3,3,4,60,15,10,15.36980422,144.2951987,203.758808,84.63019578,3.544079879,0.025157413,82.07172302,0.197176886,122.1218787,56.45026942,116.8550859
1079,S,0.3,4,4,4,60,15,10,19.06865562,117.0321794,130.1482059,80.93134438,4.297302166,0.027499447,109.5788305,0.19616731,151.1124318,69.19947433,139.5509618
1089,S,0.4,3,4,3,0,20,10,32.03632162,194.0586452,96.32367132,67.96367838,8.905998902,0.022570224,183.1983921,0.182391715,292.900471,129.7102109,264.8630873
1099,S,0.2,3,4,4,0,20,10,14.45618451,181.5271669,203.2851745,85.54381549,4.146215349,0.022069586,83.21282599,0.168487692,115.7266681,52.50214406,103.4366097
1110,S,0.4,4,3,3,30,20,10,28.61072551,173.269203,96.24457126,71.38927449,7.770034196,0.02315035,164.3389424,0.189057374,286.6887778,132.8201679,282.2981964
1120,S,0.2,4,3,4,30,20,10,12.92596576,161.0824844,205.6720083,87.07403424,3.533354847,0.02381248,77.07123156,0.1941154,116.0476896,54.65284495,113.6634446
1130,S,0.3,3,3,3,60,20,10,23.53388037,189.6226859,128.5040603,76.46611963,7.343560455,0.023584398,158.5063282,0.195324612,253.6833941,119.3689563,251.6471601
1140,S,0.4,4,4,3,60,20,10,25.93808428,159.9674618,97.90504599,74.06191572,8.040071712,0.024717911,182.6536298,0.143669462,271.3306275,118.3420449,245.0975732
1150,S,0.2,4,4,4,60,20,10,11.76449343,144.3706344,200.6365565,88.23550657,3.093990785,0.022961104,64.85346344,0.178976369,94.74511171,42.12900307,84.47645834
1152,S,0.4,4,4,4,60,20,10,23.52827407,143.810817,97.0304232,76.47172593,6.695068682,0.022949286,140.2569074,0.149996281,230.995779,99.11599275,201.2234143