File: data/results_table2.csv
num,Code,Thickness (mm),xCell,yCell,zCell,Angle (°),Height (mm),Radius (mm),RD,SA (cm^2),SA/VR (1/cm),Porosity,Elastic Modulus (GPa),Yield Strain (-),Yield Stress (MPa),Ultimate Strain (-),Ultimate Stress (MPa),Energy Absorption (MJ/m^3),Plateau Stress (MPa)
1,G,0.2,3,3,3,0,8,2.5,12.88201546,3.431527612,167.4756168,87.11798454,1.377231442,0.032289326,41.71541149,0.101792127,52.32626056,25.04909125,50.85215536
5,G,0.3,4,3,3,0,8,2.5,17.35968515,3.199481113,115.1614126,82.64031485,1.825144643,0.028522238,48.40692124,0.199420035,67.85103477,32.13521238,66.12621691
9,G,0.4,3,4,3,0,8,2.5,22.7914,3.360374401,91.77144277,77.2086,2.427093332,0.023411606,51.96796594,0.199778423,76.89954751,35.69828322,72.17960273
13,G,0.2,3,3,4,0,8,2.5,11.76682844,3.210675274,171.3541818,88.23317156,2.292816904,0.022542645,47.10052449,0.089804992,57.4875229,25.30222527,45.50412911
17,G,0.3,4,3,4,0,8,2.5,15.91342939,2.88040829,115.1537468,84.08657061,2.475007309,0.025443463,58.02274349,0.120828763,75.19170057,32.83166094,64.49779259
21,G,0.4,3,4,4,0,8,2.5,20.81174601,3.066594126,91.66881149,79.18825399,2.56196262,0.025034581,59.01373519,0.101569846,75.80781094,35.61863178,66.88904651
25,G,0.2,3,3,3,30,8,2.5,12.76265702,3.456387536,168.0207918,87.23734298,1.704078554,0.025702909,40.39161866,0.077528544,51.28574499,22.82766752,43.10016327
29,G,0.3,4,3,3,30,8,2.5,17.44775057,3.207273514,115.7972829,82.55224943,2.152471384,0.025504485,50.5927313,0.188261747,73.64994423,28.08457536,54.83584546
33,G,0.4,3,4,3,30,8,2.5,23.4993156,3.274581052,88.37149509,76.5006844,3.415915236,0.025263762,79.46704033,0.123432435,111.7525288,50.6541359,99.09726504
37,G,0.2,3,3,4,30,8,2.5,11.62711422,3.08745878,171.1998137,88.37288578,1.906259836,0.02482705,43.51428938,0.059601441,53.98812407,22.98441108,46.70494568
41,G,0.3,4,3,4,30,8,2.5,15.91484451,2.923055271,116.0875764,84.08515549,1.955793592,0.027949513,50.7518906,0.099391609,68.93518589,32.72077238,64.26284488
45,G,0.4,3,4,4,30,8,2.5,21.69038955,3.032626924,88.4013312,78.30961045,3.397110466,0.025924983,81.27581069,0.136249557,105.2239456,46.77129125,82.89062315
49,G,0.2,3,3,3,60,8,2.5,12.67383395,3.34255803,168.6831434,87.32616605,1.873599886,0.023192577,39.70641074,0.096330315,51.81084854,22.30791453,42.30152878
53,G,0.3,4,3,3,60,8,2.5,17.05774937,3.186810074,117.5096369,82.94225063,1.903870821,0.024228392,42.31998604,0.193121016,63.64391461,29.28525171,58.89643016
57,G,0.4,3,4,3,60,8,2.5,23.35933389,3.285261153,88.32429853,76.64066611,4.255277164,0.025286263,99.08950442,0.122235373,133.0318629,52.41497612,86.3172865
61,G,0.2,3,3,4,60,8,2.5,11.5140671,3.08751106,169.2745399,88.4859329,1.293112917,0.028868973,34.74461638,0.082698829,46.35963394,13.36435468,19.41042447
65,G,0.3,4,3,4,60,8,2.5,16.10782697,2.924078994,115.6192499,83.89217303,1.289101174,0.034284923,41.61853211,0.103210837,53.10426156,22.18161953,42.03936864
69,G,0.4,3,4,4,60,8,2.5,21.08871695,2.962855572,88.46599492,78.91128305,3.655636543,0.026425372,89.29028328,0.107070133,115.3499872,45.28993296,80.63035698
73,G,0.2,3,3,3,0,10,2.5,13.02661448,4.269101798,166.5950383,86.97338552,1.291550714,0.035441482,43.19136937,0.100337589,53.02211454,24.77045999,49.33772686
77,G,0.3,4,3,3,0,10,2.5,17.60905071,4.014790025,115.3094862,82.39094929,2.425390418,0.023369402,51.82914338,0.12974757,69.31913778,31.87910151,62.71240212
81,G,0.4,3,4,3,0,10,2.5,23.07468789,4.227321739,90.55288551,76.92531211,2.330700838,0.023322072,49.69537015,0.192830157,74.07275891,36.73453852,76.97087048
85,G,0.2,3,3,4,0,10,2.5,11.78039705,3.954518578,169.2060668,88.21960295,2.207557623,0.023539607,47.54992442,0.071838647,58.28417758,24.33950529,45.30616385
89,G,0.3,4,3,4,0,10,2.5,15.89606697,3.602181719,115.288046,84.10393303,2.610789197,0.02462127,59.05936625,0.136378407,75.88967988,32.85721977,61.42968124
93,G,0.4,3,4,4,0,10,2.5,20.81136911,3.823017667,91.16830766,79.18863089,2.882432258,0.022837588,60.06293539,0.090765941,75.2503768,35.77653061,69.49655015
97,G,0.2,3,3,3,30,10,2.5,12.76330799,4.225801088,167.3614281,87.23669201,1.742328219,0.025666296,41.23445453,0.068528318,50.66708898,23.24941519,49.75841138
101,G,0.3,4,3,3,30,10,2.5,17.53874084,3.992888941,115.2275149,82.46125916,1.785683893,0.031336075,52.38495585,0.194652247,71.99892788,31.45444968,65.23778121
105,G,0.4,3,4,3,30,10,2.5,23.54596835,4.079440081,87.99855515,76.45403165,3.40401859,0.027581741,87.08072195,0.106696153,113.3134691,49.14858824,97.35301841
109,G,0.2,3,3,4,30,10,2.5,11.68059056,3.923472873,169.6508426,88.31940944,1.920040558,0.024973175,44.10942719,0.060847729,53.82895046,22.28440533,44.12469853
113,G,0.3,4,3,4,30,10,2.5,16.13879714,3.696421498,115.8259329,83.86120286,2.303599493,0.025463308,54.05006542,0.088905394,68.96124897,29.67529511,59.56776321
117,G,0.4,3,4,4,30,10,2.5,21.16119873,3.709768742,88.73266627,78.83880127,3.648732078,0.024572,82.35918068,0.098944682,102.8784572,41.10024468,85.69961762
121,G,0.2,3,3,3,60,10,2.5,12.65886269,4.218562119,167.7831911,87.34113731,1.595595689,0.027063902,39.99185321,0.105422688,51.61276268,22.72964646,45.95037745
125,G,0.3,4,3,3,60,10,2.5,17.17787393,3.991816632,116.7110616,82.82212607,1.648477804,0.028155963,43.11752473,0.173951006,61.62338383,29.47046123,57.4453576
129,G,0.4,3,4,3,60,10,2.5,23.41546357,4.052281737,87.7997309,76.58453643,4.427092408,0.024182659,98.20468201,0.095094752,126.7174959,54.4664703,102.9078286
133,G,0.2,3,3,4,60,10,2.5,11.49261798,3.849174515,169.3651881,88.50738202,1.544998782,0.023565757,33.31906761,0.058157331,41.78895758,11.32313277,18.37633892
137,G,0.3,4,3,4,60,10,2.5,15.85354606,3.626978486,114.972262,84.14645394,1.793119388,0.023209708,38.03153841,0.080816865,49.58388881,21.69601317,45.60205097
141,G,0.4,3,4,4,60,10,2.5,21.13929641,3.696140188,87.00657432,78.86070359,4.142360581,0.023935271,90.86380008,0.095067585,115.1448825,44.2307831,85.28551691
289,G,0.2,3,3,3,0,8,5,12.74406427,13.27673852,165.1379134,87.25593573,1.636660867,0.029547623,45.08611607,0.199761882,58.41901478,28.16498108,58.58309274
293,G,0.3,4,3,3,0,8,5,17.47025955,12.45212388,112.8856302,82.52974045,1.765843499,0.036057135,60.13957068,0.159214467,76.70928411,36.11071954,75.31792138
297,G,0.4,3,4,3,0,8,5,23.33482546,12.60742814,85.48009676,76.66517454,3.523076821,0.023686745,76.40406989,0.16702497,105.7341431,49.98551471,100.5419308
301,G,0.2,3,3,4,0,8,5,11.67923861,12.11510726,167.3813564,88.32076139,2.515644695,0.022773134,52.2578243,0.098657951,64.69872568,28.69046961,55.71813647
305,G,0.3,4,3,4,0,8,5,16.00794308,11.4068746,112.6978888,83.99205692,2.734954357,0.026033589,65.73076861,0.111933678,84.17017489,37.03924512,71.76646567
309,G,0.4,3,4,4,0,8,5,21.29972466,11.48489458,85.99157889,78.70027534,3.557425478,0.025817725,84.72978079,0.158729672,115.6985014,50.83922026,104.0791716
313,G,0.2,3,3,3,30,8,5,12.82349254,13.22747546,165.0961852,87.17650746,1.760268961,0.029223486,47.92065797,0.141448915,62.87093401,28.82378189,55.8949384
317,G,0.3,4,3,3,30,8,5,17.52738289,12.48344489,112.6359867,82.47261711,2.284236362,0.027036099,57.18836751,0.142538518,82.18081598,38.66306327,77.75846215
321,G,0.4,3,4,3,30,8,5,23.44737975,12.58776571,84.69875126,76.55262025,3.561414122,0.027894271,92.22022391,0.156664923,125.6994905,56.4219694,110.8747148
325,G,0.2,3,3,4,30,8,5,11.71096693,12.48439011,167.2164557,88.28903307,1.818476595,0.028639214,48.44278705,0.071367517,61.09081894,26.74413977,52.93342909
329,G,0.3,4,3,4,30,8,5,15.87469774,11.22841649,113.1229376,84.12530226,2.419190052,0.028071315,63.07146509,0.084106416,81.25642348,35.61898866,68.91491173
333,G,0.4,3,4,4,30,8,5,21.30233966,11.43150104,85.36926613,78.69766034,3.538016145,0.028347709,93.2186182,0.12498422,123.4536249,52.27782992,100.7900767
337,G,0.2,3,3,3,60,8,5,12.83934355,13.50783421,165.5448857,87.16065645,1.58927897,0.034449937,51.57200252,0.108428836,64.72209519,29.36268484,57.55518176
341,G,0.3,4,3,3,60,8,5,17.40536574,12.43655219,112.1765115,82.59463426,2.047637725,0.031995136,61.41917282,0.199113995,79.16733183,37.86476856,77.32637177
345,G,0.4,3,4,3,60,8,5,23.51503278,12.5397432,84.58568775,76.48496722,4.20062719,0.029159274,114.0859832,0.122471318,149.033268,61.59242662,110.9278154
349,G,0.2,3,3,4,60,8,5,11.84373982,12.29236072,167.0734093,88.15626018,1.540868619,0.028066274,40.16470302,0.090457387,53.77056653,24.62497895,49.07253609
353,G,0.3,4,3,4,60,8,5,16.18171408,11.52234139,112.8393237,83.81828592,1.809741097,0.028956326,48.78397018,0.114669561,64.60183231,31.15844585,64.41124356
357,G,0.4,3,4,4,60,8,5,21.50299918,11.6555088,85.54677488,78.49700082,3.843051933,0.026708102,94.95451939,0.144054174,128.6693982,54.68272517,103.8738567
361,G,0.2,3,3,3,0,10,5,12.96151802,16.69056865,162.8428759,87.03848198,1.510164414,0.034869056,49.63767902,0.132088494,61.13762685,27.4115116,53.44265191
365,G,0.3,4,3,3,0,10,5,17.72422239,15.68833466,113.035648,82.27577761,2.74303806,0.023033839,57.69662037,0.176487458,79.52850431,35.03220276,66.91565783
369,G,0.4,3,4,3,0,10,5,23.58711713,15.7932105,85.19884785,76.41288287,3.316430034,0.025408692,77.63328777,0.199694777,108.7303246,49.19761438,97.3712717
373,G,0.2,3,3,4,0,10,5,11.68509336,15.363109,165.8821737,88.31490664,2.538550504,0.023082584,53.51920445,0.090746653,65.54524332,27.93248135,50.70735173
377,G,0.3,4,3,4,0,10,5,16.01636997,14.18689661,113.1486432,83.98363003,3.113533559,0.023381422,66.57177492,0.163881111,84.83923685,35.90170769,68.01820722
381,G,0.4,3,4,4,0,10,5,21.31245411,14.39182692,85.46721128,78.68754589,4.302918347,0.022772874,89.38397997,0.160236263,115.1408225,51.26820473,101.2535746
385,G,0.2,3,3,3,30,10,5,12.88669143,16.61633742,163.8665312,87.11330857,1.834656955,0.028832148,49.22778771,0.105539203,63.7135173,29.1501483,56.30386841
389,G,0.3,4,3,3,30,10,5,17.64470337,15.42140658,111.4137915,82.35529663,2.32252781,0.027780441,59.87579099,0.147340822,81.89345379,38.83516181,77.475774
393,G,0.4,3,4,3,30,10,5,23.48734165,15.73805608,84.18667796,76.51265835,3.620736319,0.02686204,90.01889149,0.171454668,128.2689013,55.9451429,109.4853584
397,G,0.2,3,3,4,30,10,5,11.7159197,15.65752449,166.8029949,88.2840803,2.106844948,0.025521882,49.55695931,0.078697622,62.64665505,27.47935649,56.38126037
401,G,0.3,4,3,4,30,10,5,15.96924377,14.19281107,112.511488,84.03075623,2.33246208,0.029447385,64.01998436,0.123420346,82.06636012,35.01382167,67.49042852
405,G,0.4,3,4,4,30,10,5,21.2361489,14.29095269,84.27964536,78.7638511,4.045797945,0.0251891,93.81841258,0.123074937,124.1163375,51.61967749,97.78344154
409,G,0.2,3,3,3,60,10,5,12.86963302,16.6872021,165.0039075,87.13036698,1.88723493,0.027013833,47.20698029,0.162576568,63.21791661,28.95046726,57.41055992
413,G,0.3,4,3,3,60,10,5,17.48520009,15.04834253,111.728873,82.51479991,2.272649115,0.027567673,58.10635023,0.148646343,80.18246144,38.25500853,78.14711786
417,G,0.4,3,4,3,60,10,5,23.4891083,15.59209092,84.31823987,76.5108917,4.669677193,0.026373251,113.8152142,0.149896085,149.6580391,61.89094861,110.858156
421,G,0.2,3,3,4,60,10,5,11.83746474,15.49966394,166.1902066,88.16253526,1.573491435,0.027119686,39.52561116,0.175235319,49.92649441,24.30732133,50.02493855
425,G,0.3,4,3,4,60,10,5,16.14720489,14.30392282,111.7639033,83.85279511,1.827495733,0.027939774,47.40482602,0.107943535,64.10766914,30.53869209,62.65299598
429,G,0.4,3,4,4,60,10,5,21.44448097,14.54504192,85.2649215,78.55551903,4.151541652,0.025313072,96.78519084,0.11932857,125.2361771,54.18321852,105.8855074
433,G,0.2,3,3,3,0,15,5,12.87657568,25.0795833,163.2994191,87.12342432,1.80177927,0.027923747,46.70886975,0.130342929,60.27380398,27.66494943,56.44428112
437,G,0.3,4,3,3,0,15,5,17.65985262,23.23604893,111.2064209,82.34014738,2.573436468,0.023665032,55.75358225,0.155120786,78.91036744,35.80751421,71.51614168
441,G,0.4,3,4,3,0,15,5,23.46634671,23.51171178,84.10269676,76.53365329,3.467375704,0.024223768,77.05815392,0.177843221,108.3379041,49.77958479,99.79842094
445,G,0.2,3,3,4,0,15,5,11.65870874,23.10109115,166.1077696,88.34129126,2.4316665,0.02396645,53.41507963,0.078204521,64.99752992,28.54019704,55.69717864
449,G,0.3,4,3,4,0,15,5,16.02379685,21.42545713,112.2460975,83.97620315,3.097888084,0.022861706,64.62722916,0.132414214,84.45361446,37.38423128,72.80604685
453,G,0.4,3,4,4,0,15,5,21.29612563,21.64705475,85.5366522,78.70387437,4.049591083,0.023840122,88.44356504,0.162726498,115.2966475,50.57568049,93.95847435
457,G,0.2,3,3,3,30,15,5,12.88638032,24.81111523,163.3659551,87.11361968,2.164372869,0.024901655,49.56772025,0.102386713,63.92163703,29.32106035,58.04808796
461,G,0.3,4,3,3,30,15,5,17.61018225,23.30954019,111.2581637,82.38981775,2.529485228,0.02552475,59.5055073,0.113751554,80.40547643,37.79892909,76.45830975
465,G,0.4,3,4,3,30,15,5,23.49859078,23.29974917,83.85497318,76.50140922,4.049895047,0.024975195,93.04712861,0.09476018,121.3536008,55.44073219,112.8282787
469,G,0.2,3,3,4,30,15,5,11.72693551,22.77469783,166.0524513,88.27306449,2.217641888,0.024756563,50.4659082,0.06316539,60.62668702,27.00819132,53.68164492
473,G,0.3,4,3,4,30,15,5,15.95982154,21.20224318,111.825748,84.04017846,2.808012278,0.024707665,63.76340078,0.101076889,80.61118462,35.30842484,70.83232973
477,G,0.4,3,4,4,30,15,5,21.32845907,21.2802696,84.38950036,78.67154093,4.233460464,0.024711981,96.15027203,0.108742269,122.5840222,43.74134031,89.33288635
481,G,0.2,3,3,3,60,15,5,12.88209915,24.75898035,163.5458797,87.11790085,2.086382052,0.025668895,49.38235823,0.107421915,64.08397524,29.42194389,57.66639977
485,G,0.3,4,3,3,60,15,5,17.50643065,23.16422406,111.2718381,82.49356935,2.756760586,0.023662751,59.71901771,0.140024773,79.55646259,37.47456004,75.2063262
489,G,0.4,3,4,3,60,15,5,23.5050554,23.47428422,83.76418345,76.4949446,4.973836045,0.025201599,115.400947,0.127745247,147.5437284,58.28197941,115.0078095
493,G,0.2,3,3,4,60,15,5,11.8180786,23.21758028,166.2165313,88.1819214,1.81985574,0.024520973,40.98492197,0.074560388,52.14592051,24.24746522,48.94810561
497,G,0.3,4,3,4,60,15,5,16.04833914,21.27128132,111.9770901,83.95166086,2.083135636,0.024329729,46.51585429,0.082145802,62.51614625,29.2296684,58.77832864
501,G,0.4,3,4,4,60,15,5,21.4223795,21.44575416,84.73326687,78.5776205,4.289958918,0.024996435,98.65376114,0.092342138,123.819504,52.41965394,105.4560959
505,G,0.2,3,3,3,0,20,5,12.81069753,33.28718285,162.7275241,87.18930247,2.261653327,0.022612154,46.61754624,0.118198562,59.3325076,26.90756314,53.14408048
509,G,0.3,4,3,3,0,20,5,17.58274353,30.5945643,111.577285,82.41725647,2.76218241,0.022909447,57.75570565,0.106866181,77.14500025,34.7682955,67.97967849
513,G,0.4,3,4,3,0,20,5,23.42388334,31.33566733,84.38301345,76.57611666,3.697957842,0.022933054,77.40955267,0.144618297,104.8663877,48.01282701,95.26847566
517,G,0.2,3,3,4,0,20,5,11.69880644,30.55979369,166.2008594,88.30119356,2.648032815,0.022311366,53.78516466,0.072958672,64.39210208,28.49687623,56.51019075
521,G,0.3,4,3,4,0,20,5,15.9905022,28.22468046,111.7236223,84.0094978,3.176728315,0.022961137,66.5878375,0.100777435,84.38387247,36.74991405,71.49413654
525,G,0.4,3,4,4,0,20,5,21.30711647,28.11607799,84.5470316,78.69288353,4.459397681,0.02238357,90.89844457,0.104376817,113.7416194,49.68887517,94.39814614
529,G,0.2,3,3,3,30,20,5,12.94659244,33.07385571,162.5594498,87.05340756,2.21540621,0.023921164,48.56428391,0.089501268,63.67931857,28.92531274,58.71000699
533,G,0.3,4,3,3,30,20,5,17.58676064,30.69973062,110.7721757,82.41323936,2.684446832,0.024167297,59.50692898,0.108388352,79.51031873,35.38539371,69.92723774
537,G,0.4,3,4,3,30,20,5,23.48853716,30.98631013,83.93528089,76.51146284,4.211272965,0.023759762,91.63629653,0.10711844,120.5797076,52.21395385,105.4137942
541,G,0.2,3,3,4,30,20,5,11.7241613,30.42183411,166.107094,88.2758387,2.352117119,0.023520583,50.61893096,0.059234738,61.06883868,25.82713166,51.48809797
545,G,0.3,4,3,4,30,20,5,16.00892103,28.0574448,111.4086552,83.99107897,3.091733671,0.023165987,65.43959473,0.074299085,79.83331913,35.23827773,69.60109324
549,G,0.4,3,4,4,30,20,5,21.3414455,28.42501818,84.11642407,78.6585545,4.583812819,0.023095875,96.69954451,0.079364848,119.8594541,39.06037383,90.05822453
553,G,0.2,3,3,3,60,20,5,12.90823976,33.07590873,163.3577822,87.09176024,2.253096575,0.023823293,49.1699868,0.088189512,63.37532188,28.45634373,56.65791761
557,G,0.3,4,3,3,60,20,5,17.58738327,30.90673855,111.1217435,82.41261673,2.793399601,0.023666854,60.52418185,0.096999872,78.71798166,36.65769751,73.01876546
561,G,0.4,3,4,3,60,20,5,23.44545966,30.92825874,83.93482512,76.55454034,5.382177465,0.023053033,113.3111575,0.09319402,144.0972073,60.57589773,120.8046781
565,G,0.2,3,3,4,60,20,5,11.75149441,30.66486622,165.3861097,88.24850559,1.783172825,0.023833428,38.93277599,0.051672876,48.72156876,22.82281152,48.20228598
569,G,0.3,4,3,4,60,20,5,16.01864524,28.1794825,111.6987943,83.98135476,2.156028918,0.023301303,45.92622457,0.070560491,61.7821761,24.31719807,51.0061986
573,G,0.4,3,4,4,60,20,5,21.40677136,28.38401769,84.24635318,78.59322864,4.48576809,0.023478429,96.34725263,0.08191998,120.2592359,44.85680435,93.69523097
577,G,0.2,3,3,3,0,8,7.5,12.78345218,29.86866245,163.5072611,87.21654782,1.603491019,0.032557437,48.99857551,0.173186392,62.49006197,30.09592282,63.05417237
581,G,0.3,4,3,3,0,8,7.5,17.47150314,27.35944442,110.805475,82.52849686,1.851406031,0.034319094,59.83576635,0.155417904,77.22889089,36.82216384,77.1362637
585,G,0.4,3,4,3,0,8,7.5,23.36310504,28.07054264,84.37721334,76.63689496,3.735540532,0.024036607,82.31863907,0.163394094,113.0807345,53.31469881,107.9018867
589,G,0.2,3,3,4,0,8,7.5,11.70169579,27.30007416,165.1923474,88.29830421,2.650383036,0.022850272,55.26120813,0.094862834,69.15609436,31.42205485,63.2998907
593,G,0.3,4,3,4,0,8,7.5,15.9965715,25.29507624,111.4820861,84.0034285,2.078886409,0.036841821,72.43218823,0.125231862,86.548926,37.95064864,74.49085872
597,G,0.4,3,4,4,0,8,7.5,21.32751993,25.46088371,84.20655126,78.67248007,2.899096734,0.036372207,99.64835225,0.159413099,123.1190362,54.69039369,113.6363455
601,G,0.2,3,3,3,30,8,7.5,12.84417185,29.68921659,163.3000004,87.15582815,1.815190408,0.029725368,50.32682285,0.101970598,65.5406348,30.2386595,59.48689173
605,G,0.3,4,3,3,30,8,7.5,17.56371783,27.97279121,111.3583984,82.43628217,2.43170108,0.027509288,62.03096346,0.133643478,85.90257277,40.20538756,81.24776376
609,G,0.4,3,4,3,30,8,7.5,23.45641167,27.9681832,83.60539855,76.54358833,3.450093309,0.030436849,98.10978157,0.165783584,132.9445691,59.20036578,117.6992069
613,G,0.2,3,3,4,30,8,7.5,11.71130763,27.51025297,166.4815018,88.28869237,1.878798124,0.030119803,52.83143407,0.079019457,65.91128526,28.23874113,55.65119759
617,G,0.3,4,3,4,30,8,7.5,15.95768931,25.34580845,111.9650848,84.04231069,1.557104333,0.05209405,78.00166291,0.116640627,85.50621392,37.37552884,73.57504231
621,G,0.4,3,4,4,30,8,7.5,21.25155096,25.12199707,84.60623839,78.74844904,3.685647888,0.029395611,100.9705776,0.140327811,132.4940785,54.91889293,102.8221859
625,G,0.2,3,3,3,60,8,7.5,12.88083226,29.94716138,163.920918,87.11916774,1.664939777,0.032721135,51.14883959,0.178715423,65.57912196,30.4009844,61.15083662
629,G,0.3,4,3,3,60,8,7.5,17.44502375,27.68171634,111.2190338,82.55497625,2.132313656,0.031600215,63.11694254,0.135299951,82.66498434,39.37156055,80.26718815
633,G,0.4,3,4,3,60,8,7.5,23.43953012,27.76473453,83.18687933,76.56046988,3.425448972,0.039601444,128.8018261,0.120310947,152.2247388,65.13435817,125.0656444
637,G,0.2,3,3,4,60,8,7.5,11.69025391,27.34247704,166.6548364,88.30974609,1.360557369,0.032975514,42.1439639,0.108550213,54.04222753,24.85953134,49.00480004
641,G,0.3,4,3,4,60,8,7.5,15.83889304,25.07692831,111.4375211,84.16110696,1.83806465,0.028565486,48.82908131,0.114680894,66.11844908,30.77805362,62.35902001
645,G,0.4,3,4,4,60,8,7.5,21.16515613,25.04283057,83.99148706,78.83484387,2.749504836,0.042443276,111.1989835,0.122952178,128.5469136,55.17957188,111.5634703
649,G,0.2,3,3,3,0,10,7.5,12.98037975,37.50620466,162.0248358,87.01962025,1.61532851,0.034369404,52.28722117,0.170207083,64.76125023,29.11850643,57.93261738
653,G,0.3,4,3,3,0,10,7.5,17.716173,34.54952401,109.917609,82.283827,2.868355073,0.022899472,59.94710526,0.14999578,80.47466337,36.40846701,70.93986654
657,G,0.4,3,4,3,0,10,7.5,23.59408702,35.36680634,83.44399435,76.40591298,3.989134266,0.023057471,84.00108099,0.195340657,115.0412854,52.02299906,103.886815
661,G,0.2,3,3,4,0,10,7.5,11.68119814,33.99434103,166.3861799,88.31880186,2.667358429,0.023227327,56.62089074,0.095792586,68.90696988,30.16994056,59.23822789
665,G,0.3,4,3,4,0,10,7.5,15.96820416,31.5415504,111.2094423,84.03179584,2.876320304,0.025313837,67.05806223,0.147972965,85.54090798,37.51925997,74.76348331
669,G,0.4,3,4,4,0,10,7.5,21.31987865,31.63268441,84.06191255,78.68012135,4.302657177,0.02396514,94.50846821,0.128963876,120.7425121,52.9120133,102.6064213
673,G,0.2,3,3,3,30,10,7.5,12.92087633,37.13980747,163.5802427,87.07912367,1.90576708,0.028361831,50.23950978,0.148770738,64.82902272,30.16012616,59.42526806
677,G,0.3,4,3,3,30,10,7.5,17.54032703,34.26584198,110.8421192,82.45967297,2.431615851,0.02748708,61.97478816,0.161288857,85.71470268,39.50458841,80.93790651
681,G,0.4,3,4,3,30,10,7.5,23.43686799,34.9505705,82.68068844,76.56313201,3.773974574,0.027487302,96.18843041,0.162610853,132.7124755,59.25116841,117.7138975
685,G,0.2,3,3,4,30,10,7.5,11.72670584,34.67635323,165.6930372,88.27329416,2.233798638,0.025485375,52.46159781,0.074906081,65.54355465,29.0099415,57.48356334
689,G,0.3,4,3,4,30,10,7.5,15.95460435,31.36565864,111.4304705,84.04539565,2.376964311,0.0298742,66.25597808,0.091599602,83.93786154,37.84765862,74.19345654
693,G,0.4,3,4,4,30,10,7.5,21.28381177,31.78270255,83.72318389,78.71618823,3.967763063,0.027192939,99.95961229,0.118183362,131.384412,54.29901684,102.1468289
697,G,0.2,3,3,3,60,10,7.5,12.90883245,37.13422986,163.2388263,87.09116755,1.920261839,0.027845229,49.62960659,0.101635289,65.68664201,30.15054828,60.02547143
701,G,0.3,4,3,3,60,10,7.5,17.48799181,34.4389399,110.5480904,82.51200819,2.358724457,0.027899068,61.08876508,0.195602083,85.80270087,39.29265074,79.00548952
705,G,0.4,3,4,3,60,10,7.5,23.4887258,34.81923688,83.26944903,76.5112742,4.378367636,0.029249702,119.3092142,0.160376942,155.9038925,64.06616935,115.4260303
709,G,0.2,3,3,4,60,10,7.5,11.72097026,33.97118612,165.1688794,88.27902974,1.620639476,0.026659587,39.96429981,0.076199383,51.85114294,24.89423493,50.49266534
713,G,0.3,4,3,4,60,10,7.5,15.81504285,31.57590414,111.483002,84.18495715,1.92165004,0.027323215,48.66235652,0.130766129,66.31890829,30.96656594,63.27125141
717,G,0.4,3,4,4,60,10,7.5,21.15877922,31.59554627,83.67343312,78.84122078,4.099592186,0.026134534,98.94174531,0.106731081,127.9748033,53.57444003,100.1910053
721,G,0.2,3,3,3,0,15,7.5,12.92519341,54.88391585,160.5641551,87.07480659,1.954215901,0.026663867,48.19852051,0.183490006,63.84493913,29.17261628,57.48950262
725,G,0.3,4,3,3,0,15,7.5,17.6044281,51.92176136,109.2333301,82.3955719,2.655031375,0.023542797,57.19680095,0.184166272,79.34283583,35.97518093,70.77762957
729,G,0.4,3,4,3,0,15,7.5,23.50053987,51.69387344,82.96770957,76.49946013,3.705957447,0.024202504,82.28153507,0.195541175,114.4875125,51.46991316,101.6347575
733,G,0.2,3,3,4,0,15,7.5,11.68496288,50.87615546,165.2898405,88.31503712,2.597645993,0.023776766,56.56832918,0.084512329,69.86264683,29.10534059,54.03031078
737,G,0.3,4,3,4,0,15,7.5,15.97810095,47.86554615,111.0272187,84.02189905,3.179231263,0.023010456,66.79709961,0.119813347,84.81025885,37.72840794,74.47871605
741,G,0.4,3,4,4,0,15,7.5,21.32247253,47.75190428,84.10712655,78.67752747,4.400605766,0.023571834,94.92913567,0.145072826,120.8951412,51.96114049,96.46340378
745,G,0.2,3,3,3,30,15,7.5,12.87208609,55.73281079,162.8305745,87.12791391,2.212734978,0.025095991,51.10530748,0.111227036,66.41507118,30.67007716,60.19837813
749,G,0.3,4,3,3,30,15,7.5,17.53735216,51.51837371,110.377031,82.46264784,2.598685617,0.025911907,62.139528,0.146625805,83.94100983,39.44736852,77.74726697
753,G,0.4,3,4,3,30,15,7.5,23.4702092,51.06942848,82.29916131,76.5297908,4.258233084,0.024736478,96.81722422,0.132663711,130.5429811,58.51829594,115.321455
757,G,0.2,3,3,4,30,15,7.5,11.75062604,51.7828737,165.9115161,88.24937396,2.403294216,0.024391135,53.81248513,0.066969816,65.01625758,29.00616996,57.93892474
761,G,0.3,4,3,4,30,15,7.5,15.96544923,47.24908767,111.4294364,84.03455077,2.955749544,0.024523577,66.57405202,0.096022924,84.1893861,37.33411083,72.56615931
765,G,0.4,3,4,4,30,15,7.5,21.29747403,47.52648945,83.43591058,78.70252597,4.372787759,0.025006621,100.6030724,0.123957904,129.7524821,54.30674386,100.5590645
769,G,0.2,3,3,3,60,15,7.5,12.8856832,55.56754716,162.3922218,87.1143168,2.168807554,0.025598148,51.17984263,0.113782358,66.05235205,30.37720426,59.43709763
773,G,0.3,4,3,3,60,15,7.5,17.52337757,51.50738804,110.5486952,82.47662243,2.780373038,0.024337017,62.10523993,0.178042126,84.53847735,39.60643425,79.79039359
777,G,0.4,3,4,3,60,15,7.5,23.4511293,52.28013818,82.6689686,76.5488707,5.075508966,0.025256347,118.0377988,0.139112155,152.4905279,58.77084231,111.5055103
781,G,0.2,3,3,4,60,15,7.5,11.74181595,51.01323507,165.2447514,88.25818405,1.80894373,0.024407642,40.53416428,0.094776599,53.38139367,24.28102285,47.75956741
785,G,0.3,4,3,4,60,15,7.5,15.88482352,46.99216556,110.5137789,84.11517648,2.15126112,0.024582416,48.58067391,0.101135969,66.8552952,30.92964146,63.06627475
789,G,0.4,3,4,4,60,15,7.5,21.23919698,47.22390616,82.88613999,78.76080302,4.296975171,0.025075481,99.15476881,0.137875128,127.5385554,52.59555719,94.32180697
793,G,0.2,3,3,3,0,20,7.5,12.87314154,73.58213938,161.5534162,87.12685846,2.269310452,0.023411074,48.58837514,0.128433394,63.20297142,29.6933796,60.40544176
797,G,0.3,4,3,3,0,20,7.5,17.52984559,68.57200787,110.3655083,82.47015441,2.800025549,0.0227274,58.03724886,0.199917603,78.51945021,36.90410091,75.73630703
801,G,0.4,3,4,3,0,20,7.5,23.39226962,68.90060924,83.22289171,76.60773038,3.983968798,0.023035836,83.80611599,0.163467264,113.4066543,52.78101625,108.2821812
805,G,0.2,3,3,4,0,20,7.5,11.69169984,68.18094024,163.509124,88.30830016,2.786720252,0.022315427,56.61341129,0.159804511,69.65094565,31.18535561,59.58255724
809,G,0.3,4,3,4,0,20,7.5,15.96205644,62.36252184,110.2233529,84.03794356,3.239278377,0.02286072,67.57367874,0.089453423,85.12896785,36.6221543,67.6393783
813,G,0.4,3,4,4,0,20,7.5,21.35926016,62.87771754,83.06284791,78.64073984,4.672827635,0.02237287,95.19891052,0.152159405,120.4751909,51.76000567,95.63042596
817,G,0.2,3,3,3,30,20,7.5,12.87906632,74.4865549,162.3379989,87.12093368,2.318513264,0.023849299,50.65788842,0.115960932,65.93313921,30.37057349,60.27830166
821,G,0.3,4,3,3,30,20,7.5,17.57132135,68.31716777,110.3496165,82.42867865,2.79108027,0.024121963,61.74417366,0.146193767,84.51004454,38.62824107,75.92073191
825,G,0.4,3,4,3,30,20,7.5,23.42171127,67.71595346,82.12829134,76.57828873,4.451948385,0.023526758,95.83601448,0.114680648,129.6556839,56.60911791,110.1672218
829,G,0.2,3,3,4,30,20,7.5,11.72464112,68.13975512,164.2988734,88.27535888,2.471476551,0.023538011,53.23068838,0.075623059,65.7187431,27.8706821,53.97096831
833,G,0.3,4,3,4,30,20,7.5,15.91451544,62.19063208,110.7323944,84.08548456,3.139346672,0.023310622,66.90143147,0.09571473,83.97800985,36.72807563,71.12585324
837,G,0.4,3,4,4,30,20,7.5,21.32971507,62.19921737,82.6781879,78.67028493,4.788883014,0.023046231,100.787938,0.144873643,130.4199599,54.51445359,101.6839349
841,G,0.2,3,3,3,60,20,7.5,12.88943838,73.36245305,161.737324,87.11056162,2.350546486,0.023687162,50.97668276,0.115943599,66.19185792,30.32750352,59.49529175
845,G,0.3,4,3,3,60,20,7.5,17.50126494,68.09639092,110.3831394,82.49873506,2.751202426,0.024277424,61.28970249,0.121017742,83.58208625,38.80359575,76.91120139
849,G,0.4,3,4,3,60,20,7.5,23.46846015,68.19758302,82.06683248,76.53153985,5.554249943,0.023125472,117.336154,0.117183828,150.9500107,63.64150536,122.6785582
853,G,0.2,3,3,4,60,20,7.5,11.67369042,67.7152309,165.4702911,88.32630958,1.86604949,0.023919391,40.9026687,0.092029262,53.8506051,23.95985195,46.56565489
857,G,0.3,4,3,4,60,20,7.5,15.89950816,62.43733333,110.5381758,84.10049184,2.263751532,0.023555098,48.79538573,0.115936208,67.70143468,31.15477691,62.01115402
861,G,0.4,3,4,4,60,20,7.5,21.21656869,62.30845841,82.98768558,78.78343131,4.566649701,0.023729319,99.230187,0.133660221,128.3386926,53.96693818,101.9440662
865,G,0.2,3,3,3,0,8,10,12.81029322,52.65987684,163.8320905,87.18970678,1.64466523,0.032382488,49.96902081,0.12988624,62.83115969,30.5252055,63.87789396
869,G,0.3,4,3,3,0,8,10,17.48548634,49.66033664,109.7357626,82.51451366,1.955760599,0.034456004,63.47617457,0.145203263,81.22290276,39.12407187,81.48010675
873,G,0.4,3,4,3,0,8,10,23.32754189,49.07731459,83.46914509,76.67245811,2.916724242,0.031640311,86.45261445,0.170607924,114.8614055,53.46111545,107.2183194
877,G,0.2,3,3,4,0,8,10,11.70636406,48.57208066,166.3876094,88.29363594,2.655459826,0.022951123,55.63486522,0.080964699,69.38846197,31.94336212,65.607138
881,G,0.3,4,3,4,0,8,10,16.01165599,44.84276426,111.1943698,83.98834401,2.219308507,0.03668686,76.98084373,0.111177608,91.30040576,40.971385,81.80208983
885,G,0.4,3,4,4,0,8,10,21.2974774,45.02099564,83.50315596,78.7025226,2.980638125,0.036115941,101.6872757,0.151764393,125.002775,56.52810908,118.8758758
889,G,0.2,3,3,3,30,8,10,12.876448,52.95175374,163.1462975,87.123552,1.485779299,0.040297723,56.9019643,0.115050755,67.52620676,31.22336461,63.33782864
893,G,0.3,4,3,3,30,8,10,17.56926749,49.28772131,109.9660164,82.43073251,2.37785065,0.029214963,64.71311765,0.13758029,87.8138138,41.06116516,83.06573773
897,G,0.4,3,4,3,30,8,10,23.41114623,49.19686542,83.13931315,76.58885377,3.482327952,0.030514968,99.2984695,0.16708079,133.7557004,59.38858668,117.4578977
901,G,0.2,3,3,4,30,8,10,11.70363384,48.64157468,165.699063,88.29636616,1.937557097,0.029955711,54.16578651,0.073924839,67.18910783,28.82542438,57.24604068
905,G,0.3,4,3,4,30,8,10,15.97525592,44.8577992,110.5044593,84.02474408,1.669334909,0.050667747,81.24276934,0.09998475,88.44823967,38.74823492,76.40319225
909,G,0.4,3,4,4,30,8,10,21.27386204,44.90367163,83.99870658,78.72613796,3.78549663,0.029375804,103.6310154,0.108466268,133.4526922,56.9604166,111.4463749
913,G,0.2,3,3,3,60,8,10,12.86759323,53.12362281,163.0538309,87.13240677,1.757343187,0.031898848,52.54253737,0.107215807,67.28974224,31.37437594,63.52794303
917,G,0.3,4,3,3,60,8,10,17.55954699,49.1661156,110.1576222,82.44045301,2.194192036,0.032107901,66.06251632,0.15827778,87.08692616,40.66402099,82.05227877
921,G,0.4,3,4,3,60,8,10,23.41791201,49.12714582,83.38093543,76.58208799,3.480574961,0.040126561,132.7023527,0.120279573,156.8840396,66.79843974,129.5432255
925,G,0.2,3,3,4,60,8,10,11.6446002,48.13820478,164.8571448,88.3553998,1.356104246,0.034278628,43.77318437,0.114936866,55.15466657,25.1930901,50.09101651
929,G,0.3,4,3,4,60,8,10,15.96550476,44.97249938,111.2442733,84.03449524,1.861457684,0.030023303,52.16419266,0.127517715,70.96748806,32.54034711,64.50513682
933,G,0.4,3,4,4,60,8,10,21.37805511,45.3993402,82.85898917,78.62194489,2.810123315,0.043840492,117.5769408,0.11399354,134.1467221,57.56242598,112.7985875
937,G,0.2,3,3,3,0,10,10,12.965173,65.95533031,162.2216908,87.034827,1.636419329,0.034092587,52.516929,0.167660451,65.33199043,29.80586949,60.0325411
941,G,0.3,4,3,3,0,10,10,17.7664291,61.52414052,110.2649904,82.2335709,3.033152554,0.022923098,63.46294701,0.168895769,84.73839459,38.67694244,77.15012383
945,G,0.4,3,4,3,0,10,10,23.56850567,61.71581388,82.75299095,76.43149433,4.050396688,0.023013906,85.11465341,0.19916935,117.3430546,53.15894115,108.4166372
949,G,0.2,3,3,4,0,10,10,11.69167832,60.6659015,164.666002,88.30832168,2.379795437,0.026095345,57.34199148,0.093586272,69.77896181,31.20508749,63.08089333
953,G,0.3,4,3,4,0,10,10,16.01983841,55.55642537,109.4470223,83.98016159,2.878328616,0.026630217,70.89385714,0.127842259,89.77918988,40.29849544,82.12097349
957,G,0.4,3,4,4,0,10,10,21.29239207,55.68233621,82.90279085,78.70760793,4.350093824,0.024147601,96.34414024,0.132773471,123.818347,54.70291036,107.6303833
961,G,0.2,3,3,3,30,10,10,12.87455368,65.69385259,162.5426874,87.12544632,1.945016481,0.028358011,51.26676571,0.110644698,67.30351698,31.0532254,62.37472717
965,G,0.3,4,3,3,30,10,10,17.56902029,61.50298455,110.2144009,82.43097971,2.55942546,0.02715716,64.38787547,0.154940772,87.84731661,40.86979603,83.32835895
969,G,0.4,3,4,3,30,10,10,23.45848566,61.440837,82.87966842,76.54151434,3.841474085,0.027311564,97.23371658,0.177859771,134.895952,59.28546507,114.5877255
973,G,0.2,3,3,4,30,10,10,11.68849112,60.65167611,166.0392128,88.31150888,2.108595402,0.027261422,53.26611889,0.076262259,66.53728701,29.15606195,58.1644463
977,G,0.3,4,3,4,30,10,10,15.97519232,55.82216096,110.7396776,84.02480768,2.494774595,0.029895219,69.59228347,0.100504947,88.00646438,38.90438312,76.56746673
981,G,0.4,3,4,4,30,10,10,21.30455897,56.13819849,83.24506381,78.69544103,4.068978555,0.027018483,101.7996728,0.118155968,133.6504669,56.85634135,109.0771909
985,G,0.2,3,3,3,60,10,10,12.88728209,65.44034524,161.9524722,87.11271791,1.654621556,0.035071685,54.72112231,0.129982328,67.02446499,30.9146424,61.9152002
989,G,0.3,4,3,3,60,10,10,17.51990374,60.50545053,110.1999143,82.48009626,2.492195927,0.02778045,64.24993149,0.135904312,87.10995445,40.41508655,82.13413814
993,G,0.4,3,4,3,60,10,10,23.45042405,60.9375541,82.87109645,76.54957595,4.541117603,0.028807269,121.7349633,0.127241397,157.4368201,65.99079987,123.7403332
997,G,0.2,3,3,4,60,10,10,11.66053876,60.70127989,165.4562338,88.33946124,1.494592504,0.030000648,41.84955838,0.192189598,54.94055255,25.34015751,51.37017392
1001,G,0.3,4,3,4,60,10,10,16.01367109,55.65938107,110.2537122,83.98632891,2.062790947,0.027102041,51.78026346,0.13332628,70.98204128,32.7341681,64.91969776
1005,G,0.4,3,4,4,60,10,10,21.33579514,56.40662381,83.07893695,78.66420486,3.370109476,0.034003043,107.8537598,0.12622683,132.255907,55.72153249,107.1121548
1009,G,0.2,3,3,3,0,15,10,12.9029202,98.71842506,160.5392897,87.0970798,1.937021036,0.027197801,48.80867118,0.160759576,63.86748166,29.23586827,57.95494277
1013,G,0.3,4,3,3,0,15,10,17.64531922,91.16762552,109.1414762,82.35468078,2.608401333,0.025305853,60.79101737,0.161805534,82.98279231,37.65355933,75.34138172
1017,G,0.4,3,4,3,0,15,10,23.4639983,90.60433668,82.11661629,76.5360017,3.741108472,0.024356273,83.6372409,0.185433547,115.0673447,51.66756912,102.6051555
1021,G,0.2,3,3,4,0,15,10,11.72522236,91.09614844,163.9591201,88.27477764,2.607831081,0.023773826,56.78246137,0.092083899,70.04996315,29.59818343,55.89237165
1025,G,0.3,4,3,4,0,15,10,15.99952555,82.97896318,110.5867219,84.00047445,3.361532771,0.023017331,70.65044596,0.100912237,89.09631757,38.57406709,72.20290102
1029,G,0.4,3,4,4,0,15,10,21.31108982,83.88905956,83.07473075,78.68891018,4.460745859,0.023411592,95.51166869,0.141284084,121.786489,52.33358825,99.71791784
1033,G,0.2,3,3,3,30,15,10,12.89727773,98.02226878,161.1140609,87.10272227,2.172551922,0.025957574,52.04907277,0.136605708,67.42527555,30.88316943,60.36873366
1037,G,0.3,4,3,3,30,15,10,17.55874718,91.85924363,109.890057,82.44125282,2.728120573,0.025635396,64.48021054,0.174429401,86.68408807,39.87244454,79.37242925
1041,G,0.4,3,4,3,30,15,10,23.44633999,91.51168195,82.18155604,76.55366001,4.309251059,0.02492064,98.77079276,0.161720689,134.1000714,59.98371821,119.5010959
1045,G,0.2,3,3,4,30,15,10,11.68890077,91.78929985,164.5548283,88.31109923,2.41400156,0.024505343,54.32793316,0.072013887,66.26702395,28.46426002,54.46582915
1049,G,0.3,4,3,4,30,15,10,15.95069385,83.52016766,110.4814801,84.04930615,2.968986708,0.025412226,69.51058925,0.103710079,86.97297039,37.93000336,73.16581917
1053,G,0.4,3,4,4,30,15,10,21.27551812,82.7275293,82.33970449,78.72448188,4.183025258,0.026702217,103.3299963,0.096224546,129.6324901,54.62106842,100.8568621
1057,G,0.2,3,3,3,60,15,10,12.88323099,99.34321745,162.1237804,87.11676901,2.15106531,0.026274658,52.21637528,0.126506352,66.91316836,30.70337274,59.98055152
1061,G,0.3,4,3,3,60,15,10,17.53752847,91.92022795,110.1361511,82.46247153,2.801500074,0.02507167,64.63528489,0.139001576,86.75499678,40.09214413,79.19304004
1065,G,0.4,3,4,3,60,15,10,23.45401661,91.01596172,82.1389139,76.54598339,5.216383446,0.024988632,119.9175172,0.129009501,153.380803,64.28389745,119.2382001
1069,G,0.2,3,3,4,60,15,10,11.65386959,90.41806546,165.5497553,88.34613041,1.843347335,0.024558106,41.58242416,0.126377392,55.30492741,25.68001077,51.28407473
1073,G,0.3,4,3,4,60,15,10,15.98575715,82.67808231,109.7296082,84.01424285,2.242551877,0.024981211,51.53655889,0.125144895,70.38943004,32.58227437,65.65782775
1077,G,0.4,3,4,4,60,15,10,21.35569432,84.44976645,82.50116174,78.64430568,4.456406949,0.025105103,102.9657425,0.1075188,131.2049533,54.56063996,99.20165244
1081,G,0.2,3,3,3,0,20,10,12.82213582,131.0297754,162.1739135,87.17786418,2.30565227,0.023091093,48.62872688,0.139771259,63.45036776,29.15713016,58.12384889
1085,G,0.3,4,3,3,0,20,10,17.60606598,120.9166144,109.4427684,82.39393402,3.000794202,0.022683752,62.06768421,0.182328916,81.77822797,38.0501964,78.56722953
1089,G,0.4,3,4,3,0,20,10,23.38310262,120.263053,82.2671163,76.61689738,4.009896616,0.022818887,83.48158645,0.19995842,114.6456701,51.49600241,101.927667
1093,G,0.2,3,3,4,0,20,10,11.7063897,120.979992,164.3769181,88.2936103,2.811048857,0.022284219,57.01993177,0.118227696,69.14021999,29.546175,54.35991736
1097,G,0.3,4,3,4,0,20,10,15.9897625,110.3225634,109.5830073,84.0102375,3.453159622,0.022698719,71.4759797,0.109604526,89.00550803,38.03034545,70.6147885
1101,G,0.4,3,4,4,0,20,10,21.32908174,110.291159,82.05808129,78.67091826,4.745128357,0.022279746,96.23000007,0.121977806,120.5676853,51.65332564,95.99170461
1105,G,0.2,3,3,3,30,20,10,12.86872633,131.5082016,161.9703915,87.13127367,2.31440923,0.023833575,50.53182796,0.15885675,67.25590128,30.96528842,60.67469952
1109,G,0.3,4,3,3,30,20,10,17.58586707,119.6802037,109.3473016,82.41413293,2.907530991,0.023929277,63.76005158,0.153768671,86.88809333,40.04021229,78.92647165
1113,G,0.4,3,4,3,30,20,10,23.42742612,121.5483788,81.8600532,76.57257388,4.437574132,0.023752033,96.52625895,0.158818412,133.3727065,59.00162637,115.7370316
1117,G,0.2,3,3,4,30,20,10,11.71340023,121.2430172,165.3097286,88.28659977,2.510571855,0.023292134,53.45543228,0.079402912,66.05665213,28.79954417,56.92851237
1121,G,0.3,4,3,4,30,20,10,16.01033225,110.1269663,109.5105168,83.98966775,3.070665538,0.024155462,68.03201365,0.105943251,87.12170435,37.83623084,72.7579962
1125,G,0.4,3,4,4,30,20,10,21.28505809,110.7635355,82.45020435,78.71494191,4.83537214,0.022979934,101.44579,0.112108147,129.6491315,48.42488371,95.02801863
1129,G,0.2,3,3,3,60,20,10,12.87924914,131.2171302,161.7549885,87.12075086,2.349713833,0.023691579,50.96900261,0.136167037,67.46235528,31.09163059,61.34249332
1133,G,0.3,4,3,3,60,20,10,17.58553617,119.1254365,109.3478458,82.41446383,2.848286877,0.024167904,63.14054915,0.160117674,87.17785678,40.54318018,81.04885367
1137,G,0.4,3,4,3,60,20,10,23.46449061,121.6499714,81.85153934,76.53550939,5.749783217,0.022749187,119.3033255,0.14364022,153.8420647,60.07014546,116.1225524
1141,G,0.2,3,3,4,60,20,10,11.66659312,120.5922141,165.3809181,88.33340688,1.856091028,0.024420033,41.61362176,0.103458905,55.36946323,25.44517135,50.88702609
1145,G,0.3,4,3,4,60,20,10,15.96261976,110.8395568,110.6065713,84.03738024,2.341108164,0.023443897,50.20248279,0.105857956,69.41652554,32.10467391,64.2435839
1149,G,0.4,3,4,4,60,20,10,21.34608748,110.3314529,81.15586863,78.65391252,4.71641001,0.023453597,101.1839584,0.126104188,130.6535962,45.05774654,95.08604044
1152,G,0.4,4,4,4,60,20,10,19.33315515,99.61648474,81.59545025,80.66684485,3.37522168,0.025089419,77.93190882,0.107320452,102.4776746,44.66773669,85.20822271