File: data/results_table3.csv
num,Code,Thickness (mm),xCell,yCell,zCell,Angle (°),Height (mm),Radius (mm),RD,SA (cm^2),SA/VR (1/cm),Porosity,Elastic Modulus (GPa),Yield Strain (-),Yield Stress (MPa),Ultimate Strain (-),Ultimate Stress (MPa),Energy Absorption (MJ/m^3),Plateau Stress (MPa)
1,S,0.2,3,3,3,0,8,2.5,17.58934038,5.592177866,204.2942366,82.41065962,4.463270806,0.02268299,92.31378537,0.171498284,134.1235902,61.92569858,126.1702631
5,S,0.3,4,3,3,0,8,2.5,23.69453307,5.24020953,138.0728221,76.30546693,5.217364089,0.02311727,110.1764845,0.184093118,166.2117982,78.7182901,164.4950544
9,S,0.4,3,4,3,0,8,2.5,32.07480234,5.185877164,103.1635703,67.92519766,8.621088276,0.023469403,185.0896187,0.184022278,280.6828905,115.432942,222.6023749
13,S,0.2,3,3,4,0,8,2.5,15.79726734,5.103857799,208.6589718,84.20273266,4.360547788,0.023352189,93.10724086,0.127305806,126.5314692,57.7343284,117.737351
17,S,0.3,4,3,4,0,8,2.5,21.23779126,4.679654001,138.9124796,78.76220874,5.574112194,0.022759371,115.715064,0.146123469,161.4731511,72.28902406,144.3507252
21,S,0.4,3,4,4,0,8,2.5,28.7308273,4.744569043,104.2712153,71.2691727,8.955961218,0.022959431,187.7118481,0.18023333,270.384662,115.4138681,226.6160917
25,S,0.2,3,3,3,30,8,2.5,17.53019771,5.634806509,205.6156493,82.46980229,4.049334275,0.02436733,90.57279613,0.17599526,129.9222197,64.59448101,136.2583154
29,S,0.3,4,3,3,30,8,2.5,23.59235878,5.185559862,138.0705263,76.40764122,4.078712532,0.027845534,105.4165036,0.167353988,167.7513062,80.30580027,167.9387024
33,S,0.4,3,4,3,30,8,2.5,31.71435353,5.230119222,103.3740502,68.28564647,7.642978184,0.024352143,170.8369408,0.155759916,254.3596775,119.4435256,238.9463418
37,S,0.2,3,3,4,30,8,2.5,16.00067407,5.226262201,210.3336715,83.99932593,3.393384869,0.026898106,84.48885732,0.164957672,117.772194,54.81415161,113.023426
41,S,0.3,4,3,4,30,8,2.5,21.27635421,4.58955863,139.0242465,78.72364579,4.449972904,0.025553719,104.8134131,0.163479388,147.4475309,72.01750819,144.2721932
45,S,0.4,3,4,4,30,8,2.5,28.8143008,4.825647852,104.4980117,71.1856992,7.703383175,0.02433883,172.0845699,0.150715858,242.538949,105.4867384,209.374182
49,S,0.2,3,3,3,60,8,2.5,17.4990717,5.613412345,205.7926588,82.5009283,3.618344735,0.025440676,84.81644732,0.196127474,127.813888,60.94173558,125.4942904
53,S,0.3,4,3,3,60,8,2.5,23.51412906,5.266591263,139.8292283,76.48587094,4.610027948,0.025199675,106.951152,0.185939997,161.8618656,79.59113128,165.6014431
57,S,0.4,3,4,3,60,8,2.5,31.4921489,5.213476424,103.8821046,68.5078511,9.041025107,0.024250867,201.1706489,0.126536757,274.3278351,126.8833273,261.6829993
61,S,0.2,3,3,4,60,8,2.5,15.95624846,5.164210361,208.6807118,84.04375154,3.297313893,0.024296535,73.5186753,0.125231564,100.2730831,48.07244988,99.81725571
65,S,0.3,4,3,4,60,8,2.5,21.06104553,4.653401584,138.9476086,78.93895447,3.750351811,0.025618993,88.57953435,0.115205362,127.1433748,53.14761244,104.5094339
69,S,0.4,3,4,4,60,8,2.5,29.24042889,4.80377504,104.0259512,70.75957111,7.018140448,0.025669704,166.1173048,0.198769405,233.0108352,104.5035823,210.9578436
73,S,0.2,3,3,3,0,10,2.5,17.25030259,6.911394167,206.6687522,82.74969741,3.438617815,0.027365407,87.22194095,0.179702604,127.0602289,58.17670481,122.8972078
77,S,0.3,4,3,3,0,10,2.5,23.11270568,6.4079813,139.7143688,76.88729432,4.768900641,0.023804747,103.984674,0.146208763,156.7268983,73.05590955,147.6799588
81,S,0.4,3,4,3,0,10,2.5,31.36714147,6.408450209,103.371104,68.63285853,7.874593717,0.024151171,174.4314705,0.18786931,258.2511773,116.1311775,246.9233202
85,S,0.2,3,3,4,0,10,2.5,15.81316646,6.401670451,208.2094839,84.18683354,3.968339106,0.02440562,88.91309667,0.113916564,124.3455596,52.47664332,103.9265927
89,S,0.3,4,3,4,0,10,2.5,21.21406897,5.846551439,138.7008789,78.78593103,4.540991661,0.025694946,107.598553,0.134147048,158.9976941,68.85370833,137.1487293
93,S,0.4,3,4,4,0,10,2.5,28.73615953,5.94752254,103.8690651,71.26384047,8.530724028,0.024013197,187.7885054,0.147597218,263.1358339,112.3805066,219.4990507
97,S,0.2,3,3,3,30,10,2.5,17.4581444,7.019472452,205.5761362,82.5418556,4.092304232,0.024175916,90.75059475,0.165399814,126.4864025,60.97543257,131.3177211
101,S,0.3,4,3,3,30,10,2.5,23.49444378,6.394023054,137.7975532,76.50555622,4.894614976,0.023855537,106.9744378,0.142585814,159.418554,78.24595359,162.0799083
105,S,0.4,3,4,3,30,10,2.5,31.79917125,6.46754214,102.6068242,68.20082875,7.720978889,0.024362757,172.6623779,0.137773049,248.7328353,114.9673919,238.8099737
109,S,0.2,3,3,4,30,10,2.5,15.97757336,6.469573187,208.9824312,84.02242664,3.919880578,0.023909065,85.88091711,0.173003483,115.0861359,52.01606694,105.8004918
113,S,0.3,4,3,4,30,10,2.5,21.32829395,5.845783585,138.0424082,78.67170605,4.754358668,0.024084681,104.998494,0.189347851,148.9562549,69.35793105,146.4434725
117,S,0.4,3,4,4,30,10,2.5,28.71826781,5.986380308,104.3100949,71.28173219,8.329337455,0.022969983,174.6660641,0.17912004,238.7660201,105.8327823,204.4040708
121,S,0.2,3,3,3,60,10,2.5,17.51111658,6.913990919,204.5607202,82.48888342,3.819272424,0.025396384,89.35716351,0.130156934,122.3326463,58.75217649,120.4717376
125,S,0.3,4,3,3,60,10,2.5,23.43224242,6.325846155,138.7490667,76.56775758,4.552160991,0.026057611,109.5141204,0.17817378,158.4413071,76.87338659,160.9248496
129,S,0.4,3,4,3,60,10,2.5,31.96970319,6.564688287,103.3921489,68.03029681,8.439738145,0.025447773,197.8930609,0.128927898,272.9556959,122.3980589,249.1188622
133,S,0.2,3,3,4,60,10,2.5,15.90638694,6.449884919,209.1674128,84.09361306,3.100527726,0.02483151,70.7897293,0.197018039,98.6401095,47.73859403,97.10241479
137,S,0.3,4,3,4,60,10,2.5,21.12946475,5.747127502,138.6086148,78.87053525,3.942309102,0.025718231,93.50459676,0.166428411,124.2273064,59.24772781,123.596517
141,S,0.4,3,4,4,60,10,2.5,29.12423311,5.994966638,103.9224788,70.87576689,7.161831345,0.026168074,173.087671,0.118974471,228.2615156,105.4914723,214.3836514
289,S,0.2,3,3,3,0,8,5,17.53391006,21.98368655,201.3420502,82.46608994,4.644591155,0.022942094,97.26746472,0.186629921,143.2002055,64.7351422,130.5655596
293,S,0.3,4,3,3,0,8,5,23.85011454,20.10872717,134.8622788,76.14988546,5.736686076,0.023047574,120.7433254,0.167723924,182.4181706,83.29866805,169.2154536
297,S,0.4,3,4,3,0,8,5,31.99136041,20.34280941,100.8891788,68.00863959,8.550586351,0.0230342,179.8547457,0.173989624,268.6272067,118.6674599,238.5997231
301,S,0.2,3,3,4,0,8,5,15.73743929,19.94166279,206.0725044,84.26256071,4.642871603,0.023102881,97.97796863,0.15506801,135.9494411,59.61660939,116.2779409
305,S,0.3,4,3,4,0,8,5,21.38547122,18.48559172,136.3712939,78.61452878,6.217394288,0.022578703,127.9459109,0.148713663,178.0872865,76.84266197,148.6981745
309,S,0.4,3,4,4,0,8,5,28.64628631,18.20588253,101.3313304,71.35371369,7.390267055,0.026207884,178.9027298,0.18748495,259.6848754,110.8953912,223.7826474
313,S,0.2,3,3,3,30,8,5,17.41550484,21.75806124,201.9704823,82.58449516,4.112988657,0.025112538,95.06160755,0.198877513,147.8629293,67.85495903,141.1200167
317,S,0.3,4,3,3,30,8,5,23.7490583,20.25163685,134.7262633,76.2509417,4.789022427,0.026540296,117.5240284,0.198864192,185.2292726,87.65313194,183.4483609
321,S,0.4,3,4,3,30,8,5,31.64886663,20.16200453,100.2673231,68.35113337,7.861531532,0.025437924,184.2579816,0.183709502,279.6973848,125.0444984,256.0705082
325,S,0.2,3,3,4,30,8,5,15.87238208,19.99568019,205.8494878,84.12761792,3.6885393,0.027366276,93.56450512,0.196682811,133.8725882,60.53344324,123.0297756
329,S,0.3,4,3,4,30,8,5,21.62476575,18.44703171,135.6272768,78.37523425,4.809722062,0.026520713,117.9378133,0.198959395,176.0867197,80.64003299,168.3814277
333,S,0.4,3,4,4,30,8,5,28.77806508,18.39482748,101.6068012,71.22193492,7.703764642,0.02589465,184.0787617,0.169913828,267.548558,114.8725341,232.3118256
337,S,0.2,3,3,3,60,8,5,17.33836042,21.91367425,203.1453049,82.66163958,3.883680142,0.026245775,94.16283681,0.198868111,139.730265,66.2840529,139.4163821
341,S,0.3,4,3,3,60,8,5,23.67624829,20.24371117,134.9743952,76.32375171,4.877699677,0.026149062,117.7918721,0.198911518,175.0574914,85.27708911,179.4628265
345,S,0.4,3,4,3,60,8,5,31.61646864,20.11720858,99.67700198,68.38353136,8.801821368,0.026401908,214.7812337,0.197800338,310.8067188,137.4029687,282.9968383
349,S,0.2,3,3,4,60,8,5,15.88918115,20.18892838,207.1824418,84.11081885,3.34747474,0.026046675,80.49563701,0.186234295,114.2900528,54.71444233,113.3559898
353,S,0.3,4,3,4,60,8,5,21.68409636,18.57725613,135.9770432,78.31590364,4.064940973,0.026700665,100.4067435,0.178637147,146.5319782,69.3865379,144.165539
357,S,0.4,3,4,4,60,8,5,28.90325147,18.39489028,101.006227,71.09674853,7.72813475,0.025255711,179.7232668,0.174811691,259.007926,116.5118751,240.1891042
361,S,0.2,3,3,3,0,10,5,17.16753362,27.18653571,205.1355555,82.83246638,3.592032957,0.027332986,90.9969208,0.183500457,139.164811,65.09197035,136.7216406
365,S,0.3,4,3,3,0,10,5,23.29094305,25.11336593,136.0554699,76.70905695,5.549101141,0.02316833,117.465202,0.186552596,183.3469016,84.03785848,175.2690426
369,S,0.4,3,4,3,0,10,5,31.21323845,24.79844947,100.5722064,68.78676155,7.700677101,0.02381364,167.9797988,0.153887796,253.8575795,119.2248272,247.6643023
373,S,0.2,3,3,4,0,10,5,15.71929333,25.12131526,206.5701868,84.28070667,4.116815133,0.02552876,96.86355636,0.167042255,135.9373689,60.38872097,117.8560865
377,S,0.3,4,3,4,0,10,5,21.40192746,22.91729197,135.5424397,78.59807254,5.176031858,0.025933342,123.8797408,0.160756779,178.6484289,77.98393323,153.9533999
381,S,0.4,3,4,4,0,10,5,28.67565796,23.10707338,101.4634027,71.32434204,8.265377247,0.0242079,183.5566712,0.188017631,261.8730063,111.9741916,223.2993734
385,S,0.2,3,3,3,30,10,5,17.39660158,27.47377019,202.6214453,82.60339842,4.330799254,0.024242725,96.32877876,0.199481273,146.1489205,68.66931497,144.5650138
389,S,0.3,4,3,3,30,10,5,23.72417348,25.08385091,133.7647092,76.27582652,5.266629157,0.024618873,119.1252184,0.190644455,184.0347255,87.82467676,184.2708474
393,S,0.4,3,4,3,30,10,5,31.62754045,24.97794987,99.39876265,68.37245955,8.016614554,0.024261932,178.4653278,0.182009745,279.3398151,125.0852779,256.959373
397,S,0.2,3,3,4,30,10,5,15.75093837,24.76201433,205.4950056,84.24906163,3.918844703,0.026602679,96.41407846,0.187284231,133.2622883,61.42169058,125.5356667
401,S,0.3,4,3,4,30,10,5,21.51086096,22.7880238,135.1012386,78.48913904,5.147924864,0.024845984,117.6094116,0.194604087,173.1204351,80.09673101,163.579511
405,S,0.4,3,4,4,30,10,5,28.75445501,23.02396303,101.0926619,71.24554499,7.900086838,0.025516926,185.7857602,0.168224216,265.169729,114.8835578,230.1486373
409,S,0.2,3,3,3,60,10,5,17.38203367,27.09401144,202.0326595,82.61796633,4.150839784,0.025252218,96.51623037,0.187019038,139.410865,66.07921162,138.5227773
413,S,0.3,4,3,3,60,10,5,23.67551031,24.86382456,133.9059942,76.32448969,4.84314007,0.02695353,120.8534413,0.177065229,175.3585407,85.15891196,180.4299764
417,S,0.4,3,4,3,60,10,5,31.63758069,24.87084499,100.0828614,68.36241931,9.389107837,0.02480237,214.0939122,0.188311517,307.3547046,137.8806426,278.693974
421,S,0.2,3,3,4,60,10,5,15.84567195,25.0903306,206.4503607,84.15432805,3.660776738,0.024569994,82.6237103,0.199664664,116.071637,54.81265708,111.694742
425,S,0.3,4,3,4,60,10,5,21.66181492,22.98143753,134.4517277,78.33818508,4.437967964,0.025016233,102.1453031,0.199428177,144.9471819,69.57963668,145.3132526
429,S,0.4,3,4,4,60,10,5,28.7624077,22.76165531,100.5704925,71.2375923,7.462536252,0.026934955,186.0780078,0.167062545,257.1522738,117.4301491,237.6964467
433,S,0.2,3,3,3,0,15,5,17.32391451,40.86274917,202.1229996,82.67608549,4.112084776,0.024518418,92.59764322,0.198969873,143.0406405,64.54999335,132.1003976
437,S,0.3,4,3,3,0,15,5,23.56354336,37.49043782,133.879592,76.43645664,4.961388006,0.02517354,114.9729239,0.170303154,181.0792165,82.09443334,171.7392132
441,S,0.4,3,4,3,0,15,5,31.56503725,36.93304092,99.6417474,68.43496275,7.698426321,0.024383728,172.3194799,0.198889669,269.2940175,119.011999,245.2799887
445,S,0.2,3,3,4,0,15,5,15.98543634,37.88498002,202.4583735,84.01456366,4.647009436,0.02334528,99.19171662,0.149756384,136.5800207,60.38426626,118.5833363
449,S,0.3,4,3,4,0,15,5,21.68668225,34.00480973,132.8605059,78.31331775,5.659770963,0.024077192,124.9518489,0.144819291,177.5296572,79.03473453,157.6826685
453,S,0.4,3,4,4,0,15,5,28.97787665,34.54178999,100.2730248,71.02212335,9.198978754,0.022361909,187.3087658,0.169504325,262.1715128,112.3406075,219.5036184
457,S,0.2,3,3,3,30,15,5,17.41743923,40.92620803,201.2648301,82.58256077,4.368524595,0.023980681,96.02314349,0.192774852,146.0178093,67.75217613,141.437109
461,S,0.3,4,3,3,30,15,5,23.71670995,37.35883438,133.1771845,76.28329005,5.312517249,0.023985152,116.7964991,0.19891812,180.718431,86.63247353,181.0883186
465,S,0.4,3,4,3,30,15,5,31.67619482,37.03516156,99.11837936,68.32380518,8.59260751,0.023598623,185.5884903,0.193911282,281.3695103,125.5104465,256.5988513
469,S,0.2,3,3,4,30,15,5,15.80217403,37.17485545,206.1036994,84.19782597,4.480174891,0.023227555,95.10315799,0.13222429,129.9684316,60.96630859,124.1548681
473,S,0.3,4,3,4,30,15,5,21.54452588,34.39087918,134.6858011,78.45547412,5.435139438,0.02356709,117.2201439,0.172489802,169.3173515,78.77633409,162.0747389
477,S,0.4,3,4,4,30,15,5,28.71526755,34.22069346,100.0779134,71.28473245,8.643608846,0.023311001,184.203955,0.147393703,258.9818796,111.9511973,224.6823967
481,S,0.2,3,3,3,60,15,5,17.32141533,40.528602,201.80198,82.67858467,4.338183934,0.024047776,95.64730951,0.172549566,138.9204242,65.71961869,136.2943397
485,S,0.3,4,3,3,60,15,5,23.65922828,37.58296506,133.5861522,76.34077172,5.415644719,0.024081631,119.5862702,0.187593238,174.9753365,84.71332083,178.742672
489,S,0.4,3,4,3,60,15,5,31.62887044,36.99746309,98.82085929,68.37112956,10.09192048,0.023102976,212.9695523,0.185108153,302.6732177,135.4295915,276.9651076
493,S,0.2,3,3,4,60,15,5,15.83710009,37.52602717,205.9107221,84.16289991,3.826798957,0.025118332,88.46920867,0.076760292,113.5974849,53.31705179,109.3153858
497,S,0.3,4,3,4,60,15,5,21.6333904,34.48909217,134.3554228,78.3666096,4.452766828,0.024216655,98.92558588,0.125923856,141.7969861,69.16643359,144.85558
501,S,0.4,3,4,4,60,15,5,28.87360273,34.31829365,99.93343859,71.12639727,8.766770547,0.023124087,185.1900265,0.154886055,259.4276341,115.2603312,231.9541339
505,S,0.2,3,3,3,0,20,5,17.40647934,54.83235738,201.1056435,82.59352066,4.196034613,0.023994408,92.28929519,0.145963275,140.7397068,63.04455832,126.9159853
509,S,0.3,4,3,3,0,20,5,23.72567281,50.07218881,133.9938753,76.27432719,5.903047678,0.0218063,116.9175356,0.17796967,180.2873365,81.03203466,166.3840676
513,S,0.4,3,4,3,0,20,5,31.76985645,49.51697251,99.04074404,68.23014355,8.618666981,0.021789596,170.559939,0.181739545,269.2827924,116.4216718,234.8774937
517,S,0.2,3,3,4,0,20,5,15.72904035,50.12163354,205.3838312,84.27095965,4.971852811,0.021643685,97.66551153,0.13666327,133.4219301,58.85550469,114.2319198
521,S,0.3,4,3,4,0,20,5,21.40198166,45.55774185,134.3044853,78.59801834,5.714113784,0.022982617,119.8970609,0.137113166,175.5866875,76.18936839,150.3685196
525,S,0.4,3,4,4,0,20,5,28.66701038,45.45030699,100.4922468,71.33298962,9.04296602,0.021754961,178.6434405,0.1391958,253.9425477,106.3699665,201.7850889
529,S,0.2,3,3,3,30,20,5,17.28763903,53.62260967,200.8813727,82.71236097,4.251887547,0.02371107,92.3130261,0.182732511,150.8860747,66.39635169,136.5389469
533,S,0.3,4,3,3,30,20,5,23.52146319,49.54317219,133.2666177,76.47853681,5.293760537,0.023611633,114.4068121,0.196614289,180.4549242,84.66184139,176.9223979
537,S,0.4,3,4,3,30,20,5,31.3691651,49.07852761,99.34832519,68.6308349,8.237306807,0.023124379,174.0079938,0.168859434,272.6911272,119.1093269,243.4793451
541,S,0.2,3,3,4,30,20,5,15.63021117,49.39515259,206.3198628,84.36978883,4.295622582,0.023053559,90.43814556,0.128558934,129.9907999,58.23722808,117.7177389
545,S,0.3,4,3,4,30,20,5,21.34486887,44.90315098,134.9429444,78.65513113,5.182553443,0.023352491,110.6604278,0.1424088,192.9406476,72.9383087,148.5816647
549,S,0.4,3,4,4,30,20,5,28.46065754,44.66846344,99.97902576,71.53934246,8.358904763,0.022867328,174.4280071,0.134836292,253.82387,102.4093866,212.5051797
553,S,0.2,3,3,3,60,20,5,17.23007702,52.97162876,201.6221782,82.76992298,4.363041036,0.02326037,92.75986574,0.136084867,136.7784553,63.79344172,129.754402
557,S,0.3,4,3,3,60,20,5,23.48487633,49.44787149,133.0641195,76.51512367,5.42615017,0.023597855,117.193203,0.152489829,180.0728943,82.30678171,169.4934545
561,S,0.4,3,4,3,60,20,5,31.35586241,48.8613983,98.49423535,68.64413759,9.668735129,0.022827668,201.3772078,0.133590817,292.4612357,116.4942494,249.1428322
565,S,0.2,3,3,4,60,20,5,15.65267033,49.50613072,206.1914501,84.34732967,3.659646308,0.02361336,79.09725362,0.134890389,111.4558321,52.50968268,106.7872898
569,S,0.3,4,3,4,60,20,5,21.37162622,44.82160191,133.7455353,78.62837378,3.969740386,0.022482626,81.31070622,0.137433243,165.5750793,66.17647007,138.1012497
573,S,0.4,3,4,4,60,20,5,28.60027734,45.20624623,99.74796235,71.39972266,8.309081361,0.024202444,184.4819116,0.137436318,273.6364955,109.4290341,215.325902
577,S,0.2,3,3,3,0,8,7.5,17.72331146,49.63035361,199.776296,82.27668854,4.913836558,0.02302256,103.3014251,0.166452318,148.2524872,68.0825886,137.9158728
581,S,0.3,4,3,3,0,8,7.5,24.16470288,45.77582347,132.051576,75.83529712,6.061250212,0.023147369,128.1794927,0.16141057,190.3758996,87.36855672,177.8627912
585,S,0.4,3,4,3,0,8,7.5,32.30019057,44.96607725,98.29779955,67.69980943,8.561531921,0.023684442,185.6520463,0.165382385,275.6029418,122.7174951,247.3716106
589,S,0.2,3,3,4,0,8,7.5,15.94859908,45.09536284,203.6947241,84.05140092,4.767514082,0.023535939,102.6728932,0.157764435,140.9958648,63.19969376,123.926563
593,S,0.3,4,3,4,0,8,7.5,21.67906614,41.34409811,133.5771032,78.32093386,6.602769508,0.022614457,136.1125089,0.137388855,186.0950081,81.31713343,159.9266579
597,S,0.4,3,4,4,0,8,7.5,28.94344813,41.28562171,99.15730069,71.05655187,7.296422282,0.029101922,197.7470708,0.136942685,271.8403179,113.8784863,233.1914132
601,S,0.2,3,3,3,30,8,7.5,17.43328784,48.66970575,201.2765804,82.56671216,4.218587169,0.025344715,98.48171696,0.196329981,149.5550818,69.63534988,145.3718417
605,S,0.3,4,3,3,30,8,7.5,23.88228062,45.15586322,132.9950967,76.11771938,4.657379891,0.028721582,124.4525588,0.19926782,193.4935463,90.08160607,190.0952324
609,S,0.4,3,4,3,30,8,7.5,31.81337696,44.27948151,98.60409012,68.18662304,8.070158699,0.025626884,190.6727048,0.198921859,291.8197429,128.9413918,264.5747629
613,S,0.2,3,3,4,30,8,7.5,15.84505767,44.88459757,205.8944948,84.15494233,3.84271558,0.027311179,97.26366328,0.161258042,134.9589335,62.94221227,128.3125517
617,S,0.3,4,3,4,30,8,7.5,21.69033734,41.15864791,134.3464871,78.30966266,5.064184374,0.026440376,123.7705724,0.191419125,181.041022,82.27324446,169.3840302
621,S,0.4,3,4,4,30,8,7.5,28.90394916,40.87735358,99.63724503,71.09605084,8.007426896,0.025963468,191.8857221,0.157221496,274.6252264,118.8400355,234.5153749
625,S,0.2,3,3,3,60,8,7.5,17.40593207,48.62773474,200.4055123,82.59406793,4.021988683,0.026110884,96.97370133,0.195144311,143.8756136,67.29508163,139.4975636
629,S,0.3,4,3,3,60,8,7.5,23.87723266,44.85728491,132.8224536,76.12276734,5.342287317,0.024850751,122.0752789,0.175765514,192.5883518,86.93258821,181.148626
633,S,0.4,3,4,3,60,8,7.5,31.79702135,44.39979005,98.29679603,68.20297865,9.054752111,0.026220216,219.308048,0.168630183,315.8163794,139.6014126,281.3342841
637,S,0.2,3,3,4,60,8,7.5,15.92686548,45.01267156,204.7678672,84.07313452,3.414588529,0.026410508,83.35184077,0.196466655,117.6329973,55.07249068,112.8283737
641,S,0.3,4,3,4,60,8,7.5,21.64014781,41.30800309,134.0738432,78.35985219,4.148517805,0.026909334,103.3368157,0.171132699,151.4078298,70.50806567,145.1437577
645,S,0.4,3,4,4,60,8,7.5,28.87458951,41.06878678,99.84221591,71.12541049,7.962285541,0.025258437,185.1903171,0.169790983,265.8463482,117.8565786,238.6279817
649,S,0.2,3,3,3,0,10,7.5,17.37862256,60.65841627,201.8186519,82.62137744,3.940411252,0.026057305,94.79567429,0.184767139,145.9019884,68.14287602,142.8394374
653,S,0.3,4,3,3,0,10,7.5,23.6861104,55.60379437,134.4084636,76.3138896,6.032429087,0.022255388,122.1891932,0.16519748,201.8445538,85.49065735,176.891845
657,S,0.4,3,4,3,0,10,7.5,31.58078563,55.98867774,98.96604856,68.41921437,7.982403258,0.023812419,174.1155209,0.161467135,265.096655,123.2593376,257.2060228
661,S,0.2,3,3,4,0,10,7.5,15.89269854,55.81974487,203.6027409,84.10730146,4.355353338,0.02578744,103.6027061,0.140476966,141.9847938,62.81433316,121.8834096
665,S,0.3,4,3,4,0,10,7.5,21.6730971,51.59965375,133.3967955,78.3269029,5.283625016,0.026810445,131.0890871,0.144313157,185.8633864,81.35096746,160.5283102
669,S,0.4,3,4,4,0,10,7.5,28.96126033,50.875533,98.83719104,71.03873967,9.005164762,0.023879043,197.0243859,0.134970975,277.9046054,114.1090473,225.4141346
673,S,0.2,3,3,3,30,10,7.5,17.53036709,60.53579627,198.6943919,82.46963291,4.450959685,0.02443209,99.84432943,0.19451952,150.0735175,69.73628298,144.5908566
677,S,0.3,4,3,3,30,10,7.5,23.87773271,56.24533103,132.9980435,76.12226729,5.201732087,0.025688824,123.2229167,0.199703884,190.3165266,89.55323371,188.6676828
681,S,0.4,3,4,3,30,10,7.5,31.78498893,55.21526985,98.52378448,68.21501107,8.355608276,0.024855121,190.9684375,0.188309026,288.7473104,128.2172375,261.9802571
685,S,0.2,3,3,4,30,10,7.5,15.87217861,56.19714696,204.6094955,84.12782139,4.121477886,0.026186262,99.68314242,0.16705215,136.8914308,62.73338983,127.1711193
689,S,0.3,4,3,4,30,10,7.5,21.68586061,51.18191261,133.6821125,78.31413939,5.275263764,0.025440916,123.6570146,0.185863256,180.0313999,81.73287949,168.5466243
693,S,0.4,3,4,4,30,10,7.5,28.94053913,51.29758328,99.16709708,71.05946087,8.302774284,0.025311509,193.5501937,0.158131456,272.728665,117.8902681,231.309732
697,S,0.2,3,3,3,60,10,7.5,17.45807432,60.77394248,200.7669631,82.54192568,4.302351827,0.025274507,100.1351163,0.187056625,145.0507867,67.62226071,139.2649729
701,S,0.3,4,3,3,60,10,7.5,23.88023764,56.06145338,133.3126692,76.11976236,4.813576974,0.031568052,142.3280953,0.174401879,201.9932709,87.04087469,183.1490963
705,S,0.4,3,4,3,60,10,7.5,31.87347851,55.54888782,97.871543,68.12652149,9.239781106,0.026122739,222.8888325,0.160753703,311.3663644,138.3597132,281.6520055
709,S,0.2,3,3,4,60,10,7.5,15.91665027,56.29971713,204.7381711,84.08334973,3.644420881,0.02542276,85.36239488,0.174538565,120.8783346,54.95271374,113.0141934
713,S,0.3,4,3,4,60,10,7.5,21.62842683,51.6823904,133.6949379,78.37157317,4.43278501,0.02571685,105.1316988,0.166786432,151.6456219,70.43842671,145.2337176
717,S,0.4,3,4,4,60,10,7.5,28.79824796,50.58061643,99.10115881,71.20175204,7.822089903,0.026326436,190.283569,0.167104483,262.6678363,116.7258749,233.1087196
721,S,0.2,3,3,3,0,15,7.5,17.5191965,91.40074162,199.4217719,82.4808035,4.339130358,0.024350064,96.97984193,0.198966821,150.3008531,68.31675668,142.4700154
725,S,0.3,4,3,3,0,15,7.5,23.87237914,83.39522307,131.3706248,76.12762086,5.207347257,0.025024998,119.8991577,0.189306577,191.0851603,86.78396749,179.695965
729,S,0.4,3,4,3,0,15,7.5,31.88904953,82.71156001,96.86174998,68.11095047,7.870085558,0.024641982,178.1943387,0.197700977,278.0404999,123.2694543,252.4387179
733,S,0.2,3,3,4,0,15,7.5,16.15954508,84.39657149,201.1183545,83.84045492,4.898325351,0.023450004,105.0691008,0.133431768,141.9435412,62.9351138,124.371475
737,S,0.3,4,3,4,0,15,7.5,21.93950771,76.2441052,131.3865586,78.06049229,5.976356831,0.023793619,130.2464453,0.136005084,186.2942899,81.79716482,160.687165
741,S,0.4,3,4,4,0,15,7.5,29.29004766,75.68312989,97.66043631,70.70995234,8.474418426,0.023908549,185.6622106,0.149781736,281.0096594,111.8968872,214.9560837
745,S,0.2,3,3,3,30,15,7.5,17.50200052,91.01130447,199.4250014,82.49799948,4.524865508,0.023676802,98.08461524,0.199082232,152.0213767,70.44043123,146.7964637
749,S,0.3,4,3,3,30,15,7.5,23.92515258,83.05515329,131.6742081,76.07484742,5.583146733,0.023610939,120.6570445,0.198917818,188.7599435,88.96809822,186.0570307
753,S,0.4,3,4,3,30,15,7.5,31.75687628,82.28028647,97.29845661,68.24312372,8.900228225,0.023317389,189.7296294,0.198960845,288.4617674,114.5577509,258.3789657
757,S,0.2,3,3,4,30,15,7.5,15.90137801,84.02870788,204.2768649,84.09862199,4.682765739,0.023088586,98.75290861,0.16118199,139.9195735,63.33462664,127.8502909
761,S,0.3,4,3,4,30,15,7.5,21.65166223,76.89657945,132.805815,78.34833777,5.692067896,0.02335032,121.5274725,0.185065842,177.4577796,82.26572408,169.2734583
765,S,0.4,3,4,4,30,15,7.5,28.89125791,75.70607825,98.52092617,71.10874209,8.90841969,0.02322409,189.0731042,0.17887675,272.2150348,117.7416916,233.1038936
769,S,0.2,3,3,3,60,15,7.5,17.50718533,91.24893011,199.1121801,82.49281467,4.522588907,0.023867798,98.89906234,0.199007193,144.9163365,67.74014215,140.6683103
773,S,0.3,4,3,3,60,15,7.5,23.88170332,83.47015053,131.4599227,76.11829668,5.360334235,0.022988745,112.5066908,0.19929053,206.0029808,88.32038804,182.7459478
777,S,0.4,3,4,3,60,15,7.5,31.8366444,82.18644543,97.57082941,68.1633556,10.3999043,0.023001583,218.4144487,0.17376922,314.3788311,136.8652896,273.4697303
781,S,0.2,3,3,4,60,15,7.5,15.85845316,84.13201628,205.4505106,84.14154684,3.760524793,0.023907291,82.38291148,0.181415081,117.0678848,55.87229886,115.4806947
785,S,0.3,4,3,4,60,15,7.5,21.64044352,76.66768581,133.031289,78.35955648,4.597390976,0.024260651,102.3409168,0.166275756,149.6810231,70.72885685,147.3626775
789,S,0.4,3,4,4,60,15,7.5,28.88721669,74.94842322,98.70418447,71.11278331,8.905496788,0.023083187,187.7562581,0.157401244,264.8707384,114.9225128,228.9561355
793,S,0.2,3,3,3,0,20,7.5,17.63491226,121.001204,198.31978,82.36508774,4.482823344,0.023551153,96.6100117,0.19874444,152.0779207,67.51208879,139.3773625
797,S,0.3,4,3,3,0,20,7.5,23.97833781,111.805573,131.693026,76.02166219,5.486830696,0.023734085,119.2512471,0.18113054,191.649289,86.63626228,178.5040066
801,S,0.4,3,4,3,0,20,7.5,32.06435008,109.9666999,97.04410779,67.93564992,7.950766299,0.023635675,172.0201935,0.192466187,279.1682076,122.9125362,248.8474398
805,S,0.2,3,3,4,0,20,7.5,15.95304138,112.3516813,201.6228174,84.04695862,5.212892951,0.02202153,104.370095,0.16183517,143.0745895,63.23490138,124.9640992
809,S,0.3,4,3,4,0,20,7.5,21.68465348,102.0544457,132.1993068,78.31534652,6.026700037,0.023151831,127.4757393,0.148438287,187.3167715,82.7238366,163.3838982
813,S,0.4,3,4,4,0,20,7.5,28.94137821,101.1064792,97.65479902,71.05862179,10.06733761,0.022588439,207.2707668,0.188305044,301.5552757,113.3524425,224.8704308
817,S,0.2,3,3,3,30,20,7.5,16.83922106,116.3559771,200.2937143,83.16077894,4.255511561,0.024794002,97.00013937,0.195611453,168.4669317,69.74642368,145.9315012
821,S,0.3,4,3,3,30,20,7.5,23.01643425,107.0373387,130.8800307,76.98356575,5.425449723,0.02378729,118.2058466,0.197913384,193.6685679,89.94691174,189.5332521
825,S,0.4,3,4,3,30,20,7.5,30.62947017,105.5221074,96.96629025,69.37052983,8.889767614,0.024406433,199.1879851,0.165101707,284.2680148,123.3260558,243.5341915
829,S,0.2,3,3,4,30,20,7.5,15.25987215,107.4528268,203.8688775,84.74012785,4.558960158,0.02447145,102.4464471,0.14619472,136.848569,60.69175969,119.4855105
833,S,0.3,4,3,4,30,20,7.5,20.83347011,97.40486739,132.963898,79.16652989,5.69501514,0.026360243,138.7319527,0.146196938,203.0589755,74.34277638,149.2019026
837,S,0.4,3,4,4,30,20,7.5,27.74850666,96.1161003,98.2868926,72.25149334,9.077851421,0.0243123,202.547748,0.146226668,306.6533955,99.05064205,172.5647747
841,S,0.2,3,3,3,60,20,7.5,16.80238731,116.3596419,199.3670119,83.19761269,4.608624229,0.024792298,105.041138,0.199203527,148.2212641,67.04991796,137.7498859
845,S,0.3,4,3,3,60,20,7.5,23.0234044,106.9473165,131.6335274,76.9765956,4.617248902,0.029072184,124.9990111,0.188955641,195.6841129,85.56117862,178.4920013
849,S,0.4,3,4,3,60,20,7.5,30.53972719,105.6734658,96.9411626,69.46027281,10.07286818,0.02384316,220.0232698,0.182719421,315.6305162,134.4625198,261.3735116
853,S,0.2,3,3,4,60,20,7.5,15.2804033,107.4696906,204.4948283,84.7195967,3.767671252,0.025495092,88.52178151,0.129799271,121.3810242,53.85364731,107.672083
857,S,0.3,4,3,4,60,20,7.5,20.83329377,98.12231522,132.3681883,79.16670623,4.594636614,0.02675361,113.7338443,0.149922562,167.9731872,67.7623795,137.4030049
861,S,0.4,3,4,4,60,20,7.5,27.76208234,97.54253096,98.33698633,72.23791766,8.45300598,0.024529103,190.4386462,0.165251851,273.9112635,109.3768002,212.6099123
865,S,0.2,3,3,3,0,8,10,17.68225204,87.21118115,199.5481061,82.31774796,4.929930538,0.02334457,105.2272469,0.148796499,149.6377387,65.37557185,128.8711353
869,S,0.3,4,3,3,0,8,10,24.11118383,79.73969167,130.6298527,75.88881617,5.087344871,0.027135489,127.8729028,0.162140012,190.4301387,83.48899542,165.1004388
873,S,0.4,3,4,3,0,8,10,32.23414002,79.60153056,97.73415551,67.76585998,8.651937054,0.023731286,188.0177213,0.167910948,279.9203757,116.9865564,225.8050657
877,S,0.2,3,3,4,0,8,10,15.88389529,80.35837688,203.4949187,84.11610471,4.810019752,0.023759081,104.6616087,0.133837938,140.9343813,60.99152284,118.8454631
881,S,0.3,4,3,4,0,8,10,21.62598813,73.02123357,133.5845579,78.37401187,6.519712306,0.022818141,135.7282905,0.142535478,187.741205,79.96648719,152.6625381
885,S,0.4,3,4,4,0,8,10,28.91798938,71.867085,98.82138412,71.08201062,7.324084145,0.02823405,192.1403876,0.162356049,267.5887883,111.5263104,218.2592027
889,S,0.2,3,3,3,30,8,10,17.44601124,86.24399087,200.9177778,82.55398876,4.079179396,0.026894373,101.5486117,0.193963826,152.2788098,68.17330294,138.3289333
893,S,0.3,4,3,3,30,8,10,23.78671042,79.3910356,132.4585073,76.21328958,4.689467162,0.02927303,127.8959806,0.199271351,195.6206302,87.7977743,180.6629302
897,S,0.4,3,4,3,30,8,10,31.75126286,78.56757951,97.87333426,68.24873714,8.071933627,0.026078668,194.3614073,0.18755348,291.3997504,124.8928021,246.2179252
901,S,0.2,3,3,4,30,8,10,15.86724031,79.09171852,205.5281572,84.13275969,3.894669848,0.027856166,100.7012313,0.15608114,138.578035,61.89469784,121.4073564
905,S,0.3,4,3,4,30,8,10,21.56766557,72.9643597,133.0836109,78.43233443,4.961457505,0.027597749,127.0021439,0.164890587,180.2507901,80.4979349,156.9160227
909,S,0.4,3,4,4,30,8,10,28.7994836,72.73804206,99.51499134,71.2005164,8.14383144,0.0259769,195.2638333,0.157226011,276.0067206,114.0621692,214.336498
913,S,0.2,3,3,3,60,8,10,17.44237551,86.5512277,199.8783688,82.55762449,4.120492584,0.026502491,100.9623321,0.195154682,145.6520715,67.47972994,139.6851672
917,S,0.3,4,3,3,60,8,10,23.78466937,79.30762378,132.6289227,76.21533063,4.998021384,0.026712322,123.5127128,0.197738439,187.0617095,88.75770357,184.9355189
921,S,0.4,3,4,3,60,8,10,31.77883548,78.62067415,97.81300055,68.22116452,9.203028289,0.026188202,222.6047043,0.171141773,321.6007354,142.6328047,289.7756661
925,S,0.2,3,3,4,60,8,10,15.84318034,79.54374648,204.812356,84.15681966,3.192218158,0.027320102,80.82728958,0.197957441,122.5437419,55.35862103,113.7830996
929,S,0.3,4,3,4,60,8,10,21.66406093,72.51568869,132.8351767,78.33593907,4.001792455,0.028418541,105.7215179,0.191601843,154.120482,71.77657441,149.552104
933,S,0.4,3,4,4,60,8,10,28.85638106,72.20044696,98.64645098,71.14361894,7.962123535,0.025919949,190.4535895,0.166078657,266.5542527,120.416975,243.2056882
937,S,0.2,3,3,3,0,10,10,17.2479616,107.652602,203.553692,82.7520384,4.021764595,0.025700121,95.31630832,0.16200074,144.0571045,68.14958726,143.3303921
941,S,0.3,4,3,3,0,10,10,23.56662406,98.94646809,132.9889306,76.43337594,5.833737468,0.023508996,125.4778364,0.185425949,189.5073598,87.56771779,180.0809672
945,S,0.4,3,4,3,0,10,10,31.47604644,97.29311339,98.54999529,68.52395356,8.150730857,0.023653119,176.4887429,0.171567798,271.8270238,123.9891027,259.1295754
949,S,0.2,3,3,4,0,10,10,15.83493471,99.69228508,203.9518512,84.16506529,4.441002955,0.026005844,106.610026,0.15189476,143.9808767,63.57768128,124.1255526
953,S,0.3,4,3,4,0,10,10,21.6219923,90.40171247,132.9395988,78.3780077,5.334692282,0.026857752,132.6084557,0.13800174,186.5202881,83.00937544,164.7116366
957,S,0.4,3,4,4,0,10,10,28.96143584,88.68354747,98.17974383,71.03856416,7.477882823,0.028231658,196.1572656,0.16949048,279.655336,116.2643043,229.8402821
961,S,0.2,3,3,3,30,10,10,17.38434793,107.4063041,200.2506531,82.61565207,3.699004027,0.029023506,99.96005893,0.198246503,153.6857348,70.98321066,147.7767043
965,S,0.3,4,3,3,30,10,10,23.69651868,98.70197472,132.1940448,76.30348132,4.504264287,0.029619379,124.4049808,0.181727147,192.2418921,90.73563423,190.4387924
969,S,0.4,3,4,3,30,10,10,31.63680016,97.52070099,97.07605495,68.36319984,6.08407852,0.036291854,208.6343343,0.196227145,292.7944378,130.6289576,271.3405537
973,S,0.2,3,3,4,30,10,10,15.77459236,98.4248109,204.0189255,84.22540764,3.5418276,0.029901062,98.82074972,0.146212304,140.6401007,63.95239622,130.4587665
977,S,0.3,4,3,4,30,10,10,21.47419589,89.87564103,133.5180138,78.52580411,4.515615327,0.028815422,121.088131,0.175329757,202.5169026,82.65102216,170.4256353
981,S,0.4,3,4,4,30,10,10,28.67615746,89.3721311,98.88822716,71.32384254,6.85816005,0.028437819,181.3147907,0.16773479,294.6916105,118.9484105,239.2728852
985,S,0.2,3,3,3,60,10,10,17.32620311,106.8801825,200.7697188,82.67379689,3.598773802,0.030535383,102.6923876,0.199641514,146.582009,68.44858492,141.3371795
989,S,0.3,4,3,3,60,10,10,23.74227891,98.00362526,131.4990773,76.25772109,4.420398199,0.030855849,127.5543416,0.199549174,187.5310302,88.7799196,185.6985038
993,S,0.4,3,4,3,60,10,10,31.63448422,97.72880828,97.60286152,68.36551578,8.73138795,0.027581108,223.3585786,0.168983555,320.2343094,141.3370261,286.5163558
997,S,0.2,3,3,4,60,10,10,15.76489448,98.59167612,204.409976,84.23510552,3.080844256,0.029169718,83.70566888,0.195683289,120.0763791,56.17482703,115.9916919
1001,S,0.3,4,3,4,60,10,10,21.55112562,89.62373048,133.0560061,78.44887438,3.7435996,0.029267465,102.0784711,0.11568321,158.895685,69.44489411,144.8951
1005,S,0.4,3,4,4,60,10,10,28.71749538,89.2874165,98.57928187,71.28250462,6.857682,0.030640372,196.4065667,0.159094,268.1735068,119.3733271,239.7087323
1009,S,0.2,3,3,3,0,15,10,17.44645971,160.8562612,200.217412,82.55354029,4.301999306,0.024246618,95.70493357,0.199333763,147.801017,67.08466902,137.5847663
1013,S,0.3,4,3,3,0,15,10,23.84148936,147.2586481,131.3269195,76.15851064,5.603893776,0.024087289,123.7748235,0.183020051,189.7059052,85.98972706,176.6139593
1017,S,0.4,3,4,3,0,15,10,31.86648213,145.8335824,96.90708266,68.13351787,7.737464388,0.025269819,180.0493989,0.163804372,282.8262817,119.5595141,241.6789392
1021,S,0.2,3,3,4,0,15,10,16.07758035,150.2768693,201.2303073,83.92241965,4.671371765,0.024088614,103.1841268,0.114855989,142.3242839,62.33759365,124.3119958
1025,S,0.3,4,3,4,0,15,10,21.88225938,134.7001284,130.9700351,78.11774062,4.827842142,0.0238013,105.2532331,0.143043709,200.5195922,79.25981694,159.0328737
1029,S,0.4,3,4,4,0,15,10,29.24494053,133.601846,97.22829362,70.75505947,8.668517099,0.023707488,188.1717269,0.138757372,266.049753,115.2042027,223.1848922
1033,S,0.2,3,3,3,30,15,10,16.95070843,156.8943086,199.0494419,83.04929157,3.723767302,0.030186481,104.9598974,0.197589207,153.7744297,70.21252907,146.3138629
1037,S,0.3,4,3,3,30,15,10,23.15980392,143.774958,131.3317896,76.84019608,4.864034384,0.029268837,132.6365598,0.178264999,197.5464513,89.21559267,187.7589853
1041,S,0.4,3,4,3,30,15,10,30.85811227,140.9425165,96.74320326,69.14188773,8.216513112,0.025030757,189.2325203,0.197170893,290.3134418,123.4679238,259.0682883
1045,S,0.2,3,3,4,30,15,10,15.41241952,144.5714306,203.401347,84.58758048,4.181721584,0.025284991,97.37134788,0.180766106,146.6663368,63.59416947,128.9306107
1049,S,0.3,4,3,4,30,15,10,20.99648221,131.3129439,131.9955502,79.00351779,4.73085091,0.029867674,131.8378099,0.159392993,186.191679,81.23064872,167.770248
1053,S,0.4,3,4,4,30,15,10,27.99857086,129.8424721,97.85212721,72.00142914,8.474944352,0.023196037,179.6352381,0.074638732,275.5216732,116.7442241,230.1031414
1057,S,0.2,3,3,3,60,15,10,16.96132761,155.2919299,199.4684419,83.03867239,4.160796325,0.026185979,100.6329335,0.199744081,146.2880502,68.19679935,140.5683495
1061,S,0.3,4,3,3,60,15,10,23.13600638,144.119921,131.384662,76.86399362,5.048937714,0.028540562,134.001642,0.189623102,188.9024486,88.49204521,185.7155305
1065,S,0.4,3,4,3,60,15,10,30.88051267,141.3216014,96.85635742,69.11948733,9.383680785,0.025204121,217.7400687,0.160617892,316.145386,137.7709711,277.0689461
1069,S,0.2,3,3,4,60,15,10,15.36980422,144.2951987,203.758808,84.63019578,3.544079879,0.025157413,82.07172302,0.197176886,122.1218787,56.45026942,116.8550859
1073,S,0.3,4,3,4,60,15,10,20.96579248,130.8771994,132.6698512,79.03420752,4.071805196,0.02948406,111.9097366,0.199948692,162.9164169,75.44214979,156.8711393
1077,S,0.4,3,4,4,60,15,10,28.00648163,130.4100951,97.95120847,71.99351837,7.766733616,0.026187782,187.8600561,0.132917054,269.8134162,117.1580345,233.9288518
1081,S,0.2,3,3,3,0,20,10,17.53122098,216.7980134,199.4813248,82.46877902,4.530352846,0.023512981,97.46139393,0.199999869,154.5366475,67.62229926,139.3427535
1085,S,0.3,4,3,3,0,20,10,23.9287329,197.1704518,131.3883356,76.0712671,6.158011322,0.022089914,123.7139152,0.199953246,202.2381933,92.75843115,192.2496058
1089,S,0.4,3,4,3,0,20,10,32.03632162,194.0586452,96.32367132,67.96367838,8.905998902,0.022570224,183.1983921,0.182391715,292.900471,129.7102109,264.8630873
1093,S,0.2,3,3,4,0,20,10,15.81908978,198.8201566,204.0871852,84.18091022,5.273599355,0.022089949,105.9463416,0.149649811,148.31167,66.20679093,131.5761551
1097,S,0.3,4,3,4,0,20,10,21.58493567,177.9458436,132.2106312,78.41506433,6.564989172,0.022025507,131.4672344,0.155926621,192.0865558,85.99496376,170.5429681
1101,S,0.4,3,4,4,0,20,10,28.94295905,176.674688,97.89182713,71.05704095,9.376560041,0.022104487,188.5109295,0.183565307,278.3354826,120.9919236,237.2730958
1105,S,0.2,3,3,3,30,20,10,15.71529686,192.3317467,199.683874,84.28470314,4.424608223,0.023612171,95.62539066,0.181534123,177.7865436,75.67032576,159.711579
1110,S,0.4,4,3,3,30,20,10,28.61072551,173.269203,96.24457126,71.38927449,7.770034196,0.02315035,164.3389424,0.189057374,286.6887778,132.8201679,282.2981964
1114,S,0.2,4,4,3,30,20,10,12.962632,161.9607738,201.2230492,87.037368,2.99727019,0.0246228,67.80664486,0.16882664,119.8524491,48.1073664,99.89919402
1118,S,0.3,3,3,4,30,20,10,21.31964122,177.175553,132.1553606,78.68035878,7.20830985,0.023420182,154.4033075,0.196699607,241.9657083,107.3402866,220.2103582
1122,S,0.4,4,3,4,30,20,10,25.87979573,159.3906803,97.82275924,74.12020427,7.887423766,0.023396556,168.7637036,0.181486702,266.9359312,111.957551,244.8394713
1126,S,0.2,4,4,4,30,20,10,11.75559226,144.4667579,200.2931765,88.24440774,3.051666738,0.023869784,66.73929215,0.162624359,96.66715391,44.73027258,90.15365734
1130,S,0.3,3,3,3,60,20,10,23.53388037,189.6226859,128.5040603,76.46611963,7.343560455,0.023584398,158.5063282,0.195324612,253.6833941,119.3689563,251.6471601
1134,S,0.4,4,3,3,60,20,10,28.5829211,173.2881571,96.49144149,71.4170789,7.982585391,0.023669238,172.9765434,0.191512084,281.4738176,134.5800643,285.300307
1138,S,0.2,4,4,3,60,20,10,12.96427668,161.6866171,201.6303749,87.03572332,3.531261596,0.022977785,74.07804584,0.15747124,122.47254,52.04441749,106.3754411
1142,S,0.3,3,3,4,60,20,10,21.37238186,176.9696146,131.6049225,78.62761814,6.174412524,0.023699482,133.9815532,0.196643734,211.2893615,97.28159211,202.8360582
1146,S,0.4,4,3,4,60,20,10,25.93190112,159.159017,97.96440275,74.06809888,6.79581951,0.023728556,147.6633441,0.190202546,236.679643,108.6948408,224.7626224
1150,S,0.2,4,4,4,60,20,10,11.76449343,144.3706344,200.6365565,88.23550657,3.093990785,0.022961104,64.85346344,0.178976369,94.74511171,42.12900307,84.47645834
1152,S,0.4,4,4,4,60,20,10,23.52827407,143.810817,97.0304232,76.47172593,6.695068682,0.022949286,140.2569074,0.149996281,230.995779,99.11599275,201.2234143