File: data/results_table1.csv
num,Thickness (mm),xCell,yCell,zCell,Angle (°),Height (mm),Radius (mm),RD,SA (cm^2),SA/VR (1/cm),Porosity,Elastic Modulus (GPa),Yield Strain (-),Yield Stress (MPa),Ultimate Strain (-),Ultimate Stress (MPa),Energy Absorption (MJ/m^3),Plateau Stress (MPa)
1,0.2,3,3,3,0,8,2.5,15.0874345,4.127542368,172.5325662,84.9125655,3.073900612,0.023444101,65.9170362,0.123627186,90.52632236,41.71456262,85.84563089
5,0.3,4,3,3,0,8,2.5,20.7393017,3.909905437,119.5258828,79.2606983,3.435057571,0.024218124,76.32053369,0.198524386,108.3612884,49.79082375,100.1748426
9,0.4,3,4,3,0,8,2.5,27.69006476,3.994176845,91.68293011,72.30993524,4.774744252,0.024117142,105.6036947,0.199760482,153.6029934,69.95506743,143.7348413
13,0.2,3,3,4,0,8,2.5,13.81942471,3.830773096,176.0323226,86.18057529,2.596655259,0.03114721,75.68525544,0.105567694,96.86658478,41.53750559,81.71303425
17,0.3,4,3,4,0,8,2.5,18.97231838,3.605435522,119.5860965,81.02768162,4.429698317,0.022791269,92.09905014,0.140099451,121.1098364,51.80861271,101.0819404
21,0.4,3,4,4,0,8,2.5,25.34004988,3.685146134,91.33863483,74.65995012,6.11547347,0.022793581,127.1625929,0.190579295,170.2765372,74.04505232,153.5308048
25,0.2,3,3,3,30,8,2.5,15.39372737,4.182469644,172.9339519,84.60627263,2.587436368,0.026098466,62.35324835,0.160847217,89.69430056,40.74008074,79.12159976
29,0.3,4,3,3,30,8,2.5,20.90646935,3.979629703,119.1973947,79.09353065,3.905178548,0.02461749,88.32533841,0.198839441,125.3646323,55.91795731,110.2102617
33,0.4,3,4,3,30,8,2.5,27.49080633,3.877801937,90.30603054,72.50919367,5.148467097,0.024444618,115.5553786,0.169568211,167.1896243,72.76202582,137.2744389
37,0.2,3,3,4,30,8,2.5,13.87203907,3.876083305,176.1677014,86.12796093,2.534770858,0.024942651,58.15436231,0.11658176,77.92757779,32.86229616,64.27446676
41,0.3,4,3,4,30,8,2.5,19.14204655,3.688252437,120.6180329,80.85795345,4.164310448,0.023621089,90.03692651,0.103672594,113.7197489,48.15516861,88.95312949
45,0.4,3,4,4,30,8,2.5,25.60282688,3.669020634,90.42086125,74.39717312,4.985864676,0.024648995,112.9248226,0.155781418,159.5855264,66.32986721,122.2513191
49,0.2,3,3,3,60,8,2.5,15.42468743,4.241779231,171.9711465,84.57531257,2.584083139,0.025992313,61.99813198,0.167174131,90.02996461,40.53386298,78.30292937
53,0.3,4,3,3,60,8,2.5,20.90357752,3.933053845,119.4509552,79.09642248,3.916349031,0.024632506,88.63679268,0.164604604,124.5018957,55.5876294,107.7533337
57,0.4,3,4,3,60,8,2.5,27.85262193,4.012472137,90.32352147,72.14737807,5.860858506,0.025326187,136.7114798,0.182469174,192.7631443,80.94545368,155.3396203
61,0.2,3,3,4,60,8,2.5,13.67023464,3.728640251,176.7271485,86.32976536,2.188701879,0.025055638,50.46191773,0.136673689,67.90255999,29.72377592,60.18950053
65,0.3,4,3,4,60,8,2.5,18.77999739,3.662231323,120.4759939,81.22000261,3.006450455,0.023417336,64.39015903,0.127564698,87.9489891,40.9365925,82.45095441
69,0.4,3,4,4,60,8,2.5,25.58264339,3.705511915,90.65686573,74.41735661,5.011932662,0.02462526,113.3962799,0.158307731,160.3126347,66.28081632,125.5693762
73,0.2,3,3,3,0,10,2.5,15.39105542,5.236318313,171.4603318,84.60894458,3.187484614,0.022731966,66.08282349,0.166391301,93.68091761,40.57987152,80.37810417
77,0.3,4,3,3,0,10,2.5,21.05983133,4.981331047,119.1697904,78.94016867,3.037615013,0.026564304,74.6168995,0.189847684,110.4734777,48.68628764,95.85994727
81,0.4,3,4,3,0,10,2.5,28.0791284,5.033126079,90.20340711,71.9208716,4.264702632,0.026062734,102.6204071,0.18986907,156.7857733,68.76959843,145.463813
85,0.2,3,3,4,0,10,2.5,13.83922386,4.779445011,173.6720156,86.16077614,3.50201347,0.022792981,72.81729964,0.09618572,98.1216623,40.53873788,80.03311067
89,0.3,4,3,4,0,10,2.5,18.9736204,4.487495631,119.6965183,81.0263796,4.197941953,0.022899891,87.73652738,0.129898334,117.783694,47.77144251,97.37262368
93,0.4,3,4,4,0,10,2.5,25.30903713,4.572116338,90.69487877,74.69096287,5.834855869,0.022704953,120.8104178,0.166467381,163.4819771,72.27269761,140.9413853
97,0.2,3,3,3,30,10,2.5,15.37171488,5.265793271,172.1966421,84.62828512,2.89794533,0.02344102,62.13490401,0.143854403,86.88396222,38.19373739,77.69215377
101,0.3,4,3,3,30,10,2.5,20.97717718,4.866989287,118.8032123,79.02282282,4.305642912,0.023043852,90.60731114,0.147546494,119.4663457,52.11825055,99.31142063
105,0.4,3,4,3,30,10,2.5,27.72357892,4.903437837,89.50138169,72.27642108,4.782311918,0.026246018,115.9520198,0.165845418,168.0296609,73.82134695,146.97569
109,0.2,3,3,4,30,10,2.5,13.96809498,4.799083597,175.7801036,86.03190502,2.76295861,0.023746806,60.08552368,0.118732214,79.37624217,34.45753813,68.13967601
113,0.3,4,3,4,30,10,2.5,18.92675264,4.449974275,119.5299211,81.07324736,4.317827888,0.022514063,88.57619227,0.083175397,113.1951564,47.13249447,91.96695982
117,0.4,3,4,4,30,10,2.5,25.30190806,4.540250517,90.90480394,74.69809194,5.024502452,0.024880674,114.9640029,0.137754488,155.6905862,66.21521281,127.0920981
121,0.2,3,3,3,60,10,2.5,15.33928035,5.222465588,172.6055907,84.66071965,2.871534125,0.023658429,62.19291864,0.135053897,87.50762313,37.95730469,77.02672705
125,0.3,4,3,3,60,10,2.5,20.97882453,4.906377736,118.2753543,79.02117547,4.309347811,0.022678285,89.10992199,0.139960146,119.5347012,52.68148191,103.1224378
129,0.4,3,4,3,60,10,2.5,27.98186914,4.895835726,89.60464715,72.01813086,6.348527515,0.023620499,137.2583331,0.140191293,190.568206,78.60156688,148.3535624
133,0.2,3,3,4,60,10,2.5,13.82493029,4.744060942,175.5972646,86.17506971,2.010540472,0.026206419,48.6679856,0.145550156,69.99918956,31.00525616,63.74115739
137,0.3,4,3,4,60,10,2.5,18.83496004,4.445489566,119.8916557,81.16503996,2.657088512,0.026411334,64.86307579,0.107594895,86.7831275,39.4937946,79.06142549
141,0.4,3,4,4,60,10,2.5,25.26087287,4.570963902,90.89173355,74.73912713,5.107943071,0.024780863,116.3633504,0.137747598,156.8598065,66.01065786,124.7088999
289,0.2,3,3,3,0,8,5,15.37289168,16.58438719,170.634074,84.62710832,3.351871785,0.023164346,70.94017396,0.182958841,98.74026153,44.32999652,90.58394235
293,0.3,4,3,3,0,8,5,20.96042403,15.23487075,114.2564749,79.03957597,3.965015424,0.02397659,87.13751697,0.153002247,122.0607238,57.74113608,116.9753543
297,0.4,3,4,3,0,8,5,27.99346323,15.43756104,86.53020684,72.00653677,5.543090472,0.023752018,120.5734014,0.174462646,172.5849358,80.86403234,164.0317363
301,0.2,3,3,4,0,8,5,14.09381562,15.2345425,171.2156025,85.90618438,2.751271967,0.032829021,84.8190215,0.103022531,103.6647735,47.60671007,99.96759429
305,0.3,4,3,4,0,8,5,19.21419029,13.83279943,115.4776136,80.78580971,4.40080647,0.025216938,102.1732505,0.136782676,136.30259,61.9837584,122.1777241
309,0.4,3,4,4,0,8,5,25.65784324,14.17117989,86.92682336,74.34215676,6.117134019,0.025180104,141.7958025,0.14565888,189.6661137,83.26457478,172.437557
313,0.2,3,3,3,30,8,5,15.49829473,16.63610506,169.5045685,84.50170527,2.84336201,0.025935248,68.05657576,0.190207064,98.47538724,43.77975304,85.53579616
317,0.3,4,3,3,30,8,5,21.12193353,15.19399266,115.6613888,78.87806647,4.054664932,0.024788055,92.39792749,0.198877037,136.9262506,58.30035795,113.5879414
321,0.4,3,4,3,30,8,5,28.00662885,15.38409714,86.83143492,71.99337115,5.350433008,0.025798982,127.3348598,0.198992312,188.6979706,80.5644073,156.8767424
325,0.2,3,3,4,30,8,5,14.06159514,15.39287368,172.8242114,85.93840486,2.865165624,0.025213509,66.51054814,0.164681867,88.98567998,37.93255554,69.58635626
329,0.3,4,3,4,30,8,5,19.13547166,14.06261569,115.80011,80.86452834,3.890055942,0.025251418,90.44931613,0.191350833,127.2850833,53.15072691,99.17676635
333,0.4,3,4,4,30,8,5,25.43543989,14.02741314,87.50729142,74.56456011,5.298302366,0.026365314,129.0948012,0.184025064,179.9932328,76.62600605,151.5531302
337,0.2,3,3,3,60,8,5,15.45034239,16.46652601,168.9166694,84.54965761,2.848666702,0.025887056,68.04626155,0.19149226,98.46127314,43.67638686,84.91506912
341,0.3,4,3,3,60,8,5,21.11681314,15.35215966,115.1882797,78.88318686,4.006508778,0.024941601,91.9157271,0.198898196,136.1499859,58.06277334,113.5370553
345,0.4,3,4,3,60,8,5,28.15757484,15.4439721,87.03279601,71.84242516,6.633369693,0.024968962,152.3616194,0.188802421,218.5155256,87.09469244,159.1330348
349,0.2,3,3,4,60,8,5,13.99092488,15.16078735,172.9926635,86.00907512,2.266347547,0.026058727,54.52543641,0.195161045,79.10456714,34.64933278,67.51073506
353,0.3,4,3,4,60,8,5,19.08536196,13.89985078,115.8309709,80.91463804,3.099961141,0.025864183,73.97803987,0.16352132,104.626069,47.49117751,94.48272477
357,0.4,3,4,4,60,8,5,25.43789708,14.25622475,87.52070595,74.56210292,5.281075684,0.026454642,129.1468147,0.178937063,178.9843627,76.72859831,151.8670038
361,0.2,3,3,3,0,10,5,15.59157426,21.01342329,168.7766007,84.40842574,3.137173839,0.025641949,74.16890291,0.199840856,101.5241215,44.43505723,88.61233371
365,0.3,4,3,3,0,10,5,21.29584774,19.19343754,114.7635954,78.70415226,3.639019877,0.02659068,89.48597158,0.198830652,129.4889859,56.56883239,113.3114089
369,0.4,3,4,3,0,10,5,28.44318552,19.27049056,85.72931279,71.55681448,5.05328404,0.02634569,123.0256884,0.198834682,179.7808559,79.41346418,162.7751723
373,0.2,3,3,4,0,10,5,14.09217749,19.0918849,172.8332741,85.90782251,3.625168844,0.024054442,79.95107738,0.169582629,107.3691199,42.41650966,95.06473746
377,0.3,4,3,4,0,10,5,19.25667436,17.64726294,114.5464,80.74332564,4.419480514,0.025200958,102.5361796,0.131611228,136.0637404,60.47039592,124.438532
381,0.4,3,4,4,0,10,5,25.65320132,17.5968039,86.1634989,74.34679868,6.10969886,0.025209466,141.8028485,0.154402542,188.5497908,84.45249163,173.281083
385,0.2,3,3,3,30,10,5,15.50242378,20.61520029,169.1255395,84.49757622,2.377937379,0.033126318,74.01643577,0.192963707,99.82204688,43.54297895,85.85346539
389,0.3,4,3,3,30,10,5,21.15062674,18.9428891,114.4099939,78.84937326,4.18247354,0.024376943,93.5909715,0.188294625,136.7427245,58.73617182,114.473823
393,0.4,3,4,3,30,10,5,28.11386792,19.04680981,86.16426613,71.88613208,5.261825202,0.026306674,127.8974711,0.192380583,186.4877876,80.15319327,155.6828099
397,0.2,3,3,4,30,10,5,14.04244617,18.70091571,172.5645828,85.95755383,3.029438967,0.024059916,66.82916901,0.143983531,88.02002989,37.7360227,71.62633559
401,0.3,4,3,4,30,10,5,19.14288447,17.40423189,115.148701,80.85711553,4.130312148,0.024193994,91.66812171,0.197169292,127.2685749,52.73679771,100.457615
405,0.4,3,4,4,30,10,5,25.56168657,17.47576351,86.92407557,74.43831343,5.53891761,0.025352686,129.348604,0.159425354,178.8404517,76.21817822,145.0292301
409,0.2,3,3,3,60,10,5,15.47226615,20.7605015,169.0023288,84.52773385,2.383765858,0.03311892,74.1802198,0.182797694,99.6587608,43.73302421,85.88363722
413,0.3,4,3,3,60,10,5,21.11024766,19.25368262,115.200486,78.88975234,4.177332889,0.024346653,93.34940913,0.194640911,136.5315111,58.58128454,113.0627946
417,0.4,3,4,3,60,10,5,28.13277702,19.01353896,86.25395091,71.86722298,7.067806066,0.023736288,153.6278682,0.197018909,217.1176452,86.42999005,158.0360948
421,0.2,3,3,4,60,10,5,14.05360286,19.17796615,172.2629605,85.94639714,2.253831198,0.026917982,56.16092518,0.178472948,78.66554044,34.40193625,66.67969279
425,0.3,4,3,4,60,10,5,19.12512976,17.28503447,115.5613977,80.87487024,3.02669872,0.026089341,72.91117732,0.164538455,102.6253429,47.38770149,95.11125381
429,0.4,3,4,4,60,10,5,25.56965087,17.5977436,87.10292424,74.43034913,5.532939205,0.025425547,129.6121288,0.161955297,178.7570502,76.05938583,141.9001879
433,0.2,3,3,3,0,15,5,15.4488187,31.13577236,169.0529416,84.5511813,3.417992718,0.023760646,74.37772816,0.183855438,101.4336857,45.17233902,91.58342073
437,0.3,4,3,3,0,15,5,21.15271528,28.48526563,113.5282286,78.84728472,4.053155283,0.02411769,89.64643053,0.199025377,128.2759734,57.11968108,114.4728684
441,0.4,3,4,3,0,15,5,28.20520826,28.30102248,85.24472859,71.79479174,5.591603954,0.023992333,122.9724146,0.199009005,178.5336889,79.67532089,166.8445069
445,0.2,3,3,4,0,15,5,14.10629996,28.51570351,172.3530437,85.89370004,4.321535809,0.022450345,88.37689611,0.10957942,110.3646091,45.68592144,83.88912773
449,0.3,4,3,4,0,15,5,19.19818044,26.32130166,114.9354746,80.80181956,5.00821781,0.023409755,107.2247183,0.132555358,139.1652991,58.76697696,109.1854631
453,0.4,3,4,4,0,15,5,25.59918229,26.25236761,86.56099835,74.40081771,6.878625602,0.023343386,146.8131633,0.181797473,192.8249557,80.42576916,152.0231316
457,0.2,3,3,3,30,15,5,15.45505572,30.7503818,169.0009117,84.54494428,3.027603903,0.025171886,70.15529196,0.170258935,97.73958059,43.36828438,85.94171263
461,0.3,4,3,3,30,15,5,21.12959507,28.64128486,114.4474759,78.87040493,4.406051507,0.023508249,94.76645462,0.182560412,134.478768,58.29045272,115.6715554
465,0.4,3,4,3,30,15,5,28.09490627,28.74519367,85.8278119,71.90509373,6.149080782,0.023209668,130.4199622,0.181211837,186.1488336,81.735381,163.2581365
469,0.2,3,3,4,30,15,5,14.01069705,28.54035677,172.2294818,85.98930295,3.047170052,0.023767637,66.32969232,0.117211159,86.82555714,38.12667445,73.85284855
473,0.3,4,3,4,30,15,5,19.20138558,26.30592705,114.091645,80.79861442,4.318625333,0.023374474,92.30834416,0.159961255,125.4739955,53.67782329,102.0338518
477,0.4,3,4,4,30,15,5,25.58831328,26.23133922,86.7122769,74.41168672,6.060801033,0.023737163,131.7446169,0.120926197,175.1953139,74.66820976,141.9039469
481,0.2,3,3,3,60,15,5,15.49935478,30.78377434,168.4781718,84.50064522,3.029911648,0.025091752,69.96596848,0.186713568,98.72569872,43.62566206,86.89550492
485,0.3,4,3,3,60,15,5,21.13804369,28.27270685,113.8515404,78.86195631,4.396789287,0.023564845,94.81607901,0.181302436,134.8456647,58.4513661,115.9309808
489,0.4,3,4,3,60,15,5,28.10022127,28.21714005,85.81594613,71.89977873,7.097507062,0.023672705,153.8221748,0.151224407,212.3381469,85.94093765,156.6949616
493,0.2,3,3,4,60,15,5,14.04102845,28.41582375,171.8685929,85.95897155,2.642681991,0.023578551,57.02524754,0.137185176,77.47073521,35.22283881,71.11139283
497,0.3,4,3,4,60,15,5,19.13243276,26.05097603,114.716266,80.86756724,3.244384964,0.024620379,73.38921869,0.133620453,101.817983,45.43719243,91.15352212
501,0.4,3,4,4,60,15,5,25.60536818,26.01288206,86.44349141,74.39463182,6.050301536,0.023758818,131.6474118,0.136083253,175.0006924,74.23839098,141.6461261
505,0.2,3,3,3,0,20,5,15.44099112,40.85512196,168.0481547,84.55900888,3.657914144,0.022475201,74.89652749,0.097926867,96.6194733,43.67987227,88.2397056
509,0.3,4,3,3,0,20,5,21.05917174,37.86511335,114.7224177,78.94082826,4.175344591,0.023463445,89.61727874,0.116960382,120.5834337,54.69490052,109.3666888
513,0.4,3,4,3,0,20,5,28.13318255,37.75076357,85.5664025,71.86681745,5.756613892,0.023357216,122.9452456,0.157201982,171.6000222,77.59268471,159.41821
517,0.2,3,3,4,0,20,5,14.06792393,38.01951631,171.5424736,85.93207607,3.987473837,0.02315542,84.35668445,0.138371968,106.1974972,43.09879878,87.61244338
521,0.3,4,3,4,0,20,5,19.26374281,34.5623249,114.0662324,80.73625719,4.90568515,0.023516461,105.5529828,0.103150082,136.2313006,58.56012447,120.343064
525,0.4,3,4,4,0,20,5,25.65628895,34.9241425,85.64126845,74.34371105,6.703852876,0.023546685,144.4458082,0.115737069,188.3972783,75.36975353,151.1047926
529,0.2,3,3,3,30,20,5,15.31178166,40.41753121,168.9462539,84.68821834,3.181122558,0.023496779,68.38388986,0.144612312,95.1314736,42.88810958,85.6330732
533,0.3,4,3,3,30,20,5,20.89296951,37.46397771,114.1734192,79.10703049,4.428613072,0.02297367,92.88426974,0.15445528,128.1903354,55.47460543,110.1611455
537,0.4,3,4,3,30,20,5,27.78659213,37.52834032,86.09961528,72.21340787,6.128670228,0.022929678,128.2710932,0.160915399,178.3117856,76.87806192,153.807375
541,0.2,3,3,4,30,20,5,13.91355443,37.38501687,172.038578,86.08644557,2.975929506,0.023470231,63.89389439,0.100594318,83.78894681,37.21760702,75.7161324
545,0.3,4,3,4,30,20,5,18.99081389,34.3580548,114.8372888,81.00918611,3.985625495,0.023718341,86.56117383,0.13341167,121.5638397,50.08351986,94.00339822
549,0.4,3,4,4,30,20,5,25.29191143,34.3358639,86.04593838,74.70808857,6.352508664,0.022605751,130.8982088,0.12192055,171.3829355,70.90866138,136.7352359
553,0.2,3,3,3,60,20,5,15.37213572,40.19237378,167.9516812,84.62786428,3.192712752,0.023469852,68.54706887,0.134545946,94.8295144,41.46721244,82.79875397
557,0.3,4,3,3,60,20,5,20.92493333,37.42005938,113.640664,79.07506667,4.418214133,0.022999809,92.78165164,0.163257086,127.9269995,55.41223742,108.2865451
561,0.4,3,4,3,60,20,5,27.8729105,37.57155609,85.38276655,72.1270895,6.992517698,0.0228541,145.8226626,0.118196404,201.8380813,80.65567458,157.2979406
565,0.2,3,3,4,60,20,5,13.8596486,37.51451406,173.1457583,86.1403514,2.609714574,0.023299577,55.58581591,0.123173904,75.86800956,33.18248492,69.36149395
569,0.3,4,3,4,60,20,5,18.9181537,33.90628409,114.7155096,81.0818463,3.364103934,0.02365121,72.83692063,0.121999478,97.81368182,41.71544832,85.43986799
573,0.4,3,4,4,60,20,5,25.28668584,34.64249445,85.81258616,74.71331416,6.336019046,0.022589261,130.4539479,0.119417048,171.8225283,71.91879518,139.3056923
577,0.2,3,3,3,0,8,7.5,15.30335023,36.69632014,169.2043776,84.69664977,3.158080718,0.024837167,72.12161677,0.120233439,99.87911463,47.16424901,97.76238363
581,0.3,4,3,3,0,8,7.5,20.8847543,33.76667568,114.3620636,79.1152457,3.861445735,0.02456407,87.12993128,0.142993093,123.7795467,58.04902004,115.6167949
585,0.4,3,4,3,0,8,7.5,27.88937976,33.80274895,85.44946596,72.11062024,5.411972903,0.024450814,121.5031985,0.170856297,174.1754242,80.95444382,160.0154872
589,0.2,3,3,4,0,8,7.5,14.0697441,34.1470008,169.3336959,85.9302559,2.753177386,0.034482436,89.42990724,0.101749979,107.9117714,48.73193365,101.4639262
593,0.3,4,3,4,0,8,7.5,19.1030288,31.14790233,114.7030098,80.8969712,3.428350111,0.034170062,110.2902346,0.120827988,136.8028521,61.71091192,124.701336
597,0.4,3,4,4,0,8,7.5,25.53868352,30.91673331,85.16361431,74.46131648,4.814976734,0.033527996,151.8065652,0.153886467,190.5837815,85.42294383,171.074403
601,0.2,3,3,3,30,8,7.5,15.42916477,36.91909808,168.2656334,84.57083523,2.847845466,0.026166278,68.82182424,0.199124336,100.5280898,44.11352243,86.57538421
605,0.3,4,3,3,30,8,7.5,21.04237799,33.94665194,113.6022801,78.95762201,4.053013095,0.025020273,93.30146801,0.190014184,135.8675807,59.1038863,117.5832084
609,0.4,3,4,3,30,8,7.5,28.20705591,34.14234021,85.11005435,71.79294409,5.070825254,0.028280746,133.2650692,0.191659302,193.2137929,83.38117005,165.4944334
613,0.2,3,3,4,30,8,7.5,14.02249992,33.62431386,171.9121544,85.97750008,2.425801808,0.030488773,69.10811651,0.123275205,88.46387107,37.93786657,70.03084726
617,0.3,4,3,4,30,8,7.5,19.13205745,31.26308269,115.0743593,80.86794255,3.859926269,0.025247261,89.73271483,0.164738148,124.8029541,52.82248152,95.64765375
621,0.4,3,4,4,30,8,7.5,25.59086999,31.22337057,86.04157723,74.40913001,5.305108903,0.027576032,135.6836362,0.124371424,182.0637856,74.4254779,133.7099306
625,0.2,3,3,3,60,8,7.5,15.45725154,36.67546318,168.7332483,84.54274846,2.844542692,0.026116682,68.6009303,0.191502288,100.1992882,44.17097892,86.77457047
629,0.3,4,3,3,60,8,7.5,21.04046531,34.14607887,114.4389046,78.95953469,4.040593035,0.024985618,92.8755284,0.193829715,135.9450489,58.94066369,118.5446907
633,0.4,3,4,3,60,8,7.5,28.11766296,33.95559208,85.318352,71.88233704,5.652014585,0.029941269,157.924461,0.162712425,215.7257063,86.06077796,156.4070754
637,0.2,3,3,4,60,8,7.5,14.08983969,34.1901607,172.4533031,85.91016031,2.164442484,0.028387506,57.11423869,0.15992558,80.97069548,36.21487198,70.88346486
641,0.3,4,3,4,60,8,7.5,19.15465543,31.06593987,114.8199904,80.84534457,2.543032855,0.032255768,76.94141282,0.183074564,106.7330069,48.14003961,96.28766454
645,0.4,3,4,4,60,8,7.5,25.5896219,31.67875794,86.05240817,74.4103781,5.2879632,0.027710072,135.9539151,0.124368459,182.4437853,74.37321682,134.5197949
649,0.2,3,3,3,0,10,7.5,15.57095749,46.46335639,167.4383615,84.42904251,3.566565035,0.02365157,77.22173159,0.196747637,105.0391683,46.10350852,92.20818955
653,0.3,4,3,3,0,10,7.5,21.17038137,42.56090778,113.5729226,78.82961863,3.63998896,0.026658397,89.75629266,0.198795903,128.6020289,56.83099154,116.5650353
657,0.4,3,4,3,0,10,7.5,28.31040212,42.83556765,85.09650351,71.68959788,5.038741409,0.026470334,123.299684,0.198789799,179.2062985,79.75581449,165.8031815
661,0.2,3,3,4,0,10,7.5,14.05223815,41.95166555,170.4117368,85.94776185,3.66515243,0.024518364,82.533236,0.105046034,108.810696,49.13610839,101.7311189
665,0.3,4,3,4,0,10,7.5,19.09812678,38.9060305,113.7976056,80.90187322,4.478775532,0.025118695,103.5434454,0.107572532,134.7034226,60.00094249,122.1608182
669,0.4,3,4,4,0,10,7.5,25.52411961,38.65893989,85.20039221,74.47588039,6.20152739,0.025023483,142.7807584,0.11770159,187.2393031,81.61871028,164.0868183
673,0.2,3,3,3,30,10,7.5,15.48611463,45.96690963,168.6649005,84.51388537,2.408060245,0.032673655,73.86400927,0.199286962,100.1828931,43.78521031,86.35378398
677,0.3,4,3,3,30,10,7.5,21.00773816,42.36153619,113.3666374,78.99226184,4.0813334,0.024882714,93.39198486,0.161874413,133.1108725,58.31728496,114.6024623
681,0.4,3,4,3,30,10,7.5,28.18447917,42.61932723,84.99165678,71.81552083,5.339633847,0.026763578,132.2284379,0.188592541,190.0525487,82.75741637,162.4583223
685,0.2,3,3,4,30,10,7.5,14.05107151,42.39247856,171.3416609,85.94892849,2.367492085,0.031951225,70.90928864,0.153609061,88.89711274,37.89932518,71.8564682
689,0.3,4,3,4,30,10,7.5,19.11481389,38.79503215,114.5387986,80.88518611,3.905279291,0.025324258,91.08774093,0.175804281,125.5029457,52.2328018,96.49601108
693,0.4,3,4,4,30,10,7.5,25.51738547,38.72388653,86.29125169,74.48261453,5.799215212,0.025151353,134.2596794,0.15816623,182.5366004,73.20392281,135.6535147
697,0.2,3,3,3,60,10,7.5,15.41545346,46.13384999,167.9990319,84.58454654,2.396664353,0.032875894,73.99915387,0.18915354,99.82838487,43.78278771,86.31171486
701,0.3,4,3,3,60,10,7.5,20.99837265,42.44785537,113.6573399,79.00162735,4.063324627,0.024975963,93.35879674,0.173192263,132.8073767,58.58812789,115.3271837
705,0.4,3,4,3,60,10,7.5,28.1793588,42.16451099,84.93681303,71.8206412,5.51257463,0.031389591,162.0123163,0.173859763,217.1989687,86.42127608,158.5990261
709,0.2,3,3,4,60,10,7.5,14.06142514,42.71016992,172.0263578,85.93857486,2.283434213,0.027187806,57.51469767,0.164560652,80.26474169,35.90171478,70.38853554
713,0.3,4,3,4,60,10,7.5,19.14127321,38.79202739,114.1535279,80.85872679,3.069482038,0.026181744,74.22542767,0.156947827,106.3883997,48.1037684,97.44556584
717,0.4,3,4,4,60,10,7.5,25.54160836,38.96939051,86.04520574,74.45839164,5.787071386,0.025179492,134.1413725,0.154374981,181.9383792,74.32852347,135.8714318
721,0.2,3,3,3,0,15,7.5,15.46090188,68.38999614,166.5693518,84.53909812,3.346842492,0.024026768,73.72012458,0.177842156,102.845717,45.86927993,92.26148692
725,0.3,4,3,3,0,15,7.5,21.09172161,62.84318364,113.2871962,78.90827839,4.198573521,0.022942213,87.92742083,0.152599684,127.4399123,55.21758958,109.5128955
729,0.4,3,4,3,0,15,7.5,28.12419509,62.6459916,84.17121351,71.87580491,5.813085249,0.023376413,124.2629129,0.195363871,176.1144921,77.59283281,157.4157133
733,0.2,3,3,4,0,15,7.5,14.04121336,63.90782912,170.3260214,85.95878664,4.486264351,0.022111476,90.22539725,0.138757356,123.9560431,44.21517025,80.50774109
737,0.3,4,3,4,0,15,7.5,19.11941356,57.97604228,114.8248143,80.88058644,4.2051658,0.027784581,108.4284367,0.120224524,137.6396579,57.89129844,107.2264383
741,0.4,3,4,4,0,15,7.5,25.53788042,58.04818139,85.56782357,74.46211958,5.796526804,0.027520706,147.9314584,0.129080725,188.7413019,80.02496024,152.6494105
745,0.2,3,3,3,30,15,7.5,15.47066306,68.92868183,167.3211136,84.52933694,2.995336962,0.025223291,69.56158238,0.192054701,100.9596951,44.10186038,87.6258322
749,0.3,4,3,3,30,15,7.5,21.03488041,63.25179323,113.3741705,78.96511959,4.138594631,0.024523224,93.21449354,0.199558306,136.9733918,59.01207351,116.7368886
753,0.4,3,4,3,30,15,7.5,28.18785716,63.21171684,83.9235753,71.81214284,5.798953022,0.02440245,129.9107528,0.194502068,193.9637078,80.91394331,159.7911683
757,0.2,3,3,4,30,15,7.5,14.08762777,62.81239535,171.0287312,85.91237223,2.642711289,0.029895811,73.72057399,0.159041214,95.79011551,33.22870135,60.59405599
761,0.3,4,3,4,30,15,7.5,19.108487,57.82525287,113.5788128,80.891513,3.524482788,0.02802654,91.73009088,0.179912281,124.8059916,52.30909536,97.28713421
765,0.4,3,4,4,30,15,7.5,25.52947415,58.27951092,84.96507608,74.47052585,5.419702177,0.026944631,135.1924718,0.151912038,181.6496922,74.51518424,137.874802
769,0.2,3,3,3,60,15,7.5,15.42050541,68.34495666,168.6421528,84.57949459,2.999989306,0.02522846,69.68513182,0.197045549,100.8136676,44.19779726,87.80327706
773,0.3,4,3,3,60,15,7.5,21.03295469,63.22089003,113.51059,78.96704531,4.142888809,0.024520317,93.29917072,0.199551694,137.3439323,59.25026079,117.5239079
777,0.4,3,4,3,60,15,7.5,28.14909507,62.87018441,84.49325324,71.85090493,6.576709128,0.025557782,154.9326787,0.174557114,216.4249494,53.53866319,158.8873831
781,0.2,3,3,4,60,15,7.5,14.09671578,63.46394752,170.1574344,85.90328422,2.405171524,0.023896401,52.6645991,0.138951731,82.72395445,35.93852441,70.66843261
785,0.3,4,3,4,60,15,7.5,19.14636555,57.82424181,114.1319366,80.85363445,3.126250069,0.025125139,72.2949663,0.167833742,108.0578725,47.76568466,95.38007818
789,0.4,3,4,4,60,15,7.5,25.55036081,57.80598362,85.0124442,74.44963919,5.435094918,0.02698288,135.7843267,0.126529551,181.520951,70.39508724,128.4797585
793,0.2,3,3,3,0,20,7.5,15.42981122,91.03333143,168.1481059,84.57018878,3.617499999,0.022028324,72.45246222,0.173397493,105.3870977,45.96780598,97.82746583
797,0.3,4,3,3,0,20,7.5,20.97993266,84.44262766,113.4941727,79.02006734,4.631983743,0.022080223,93.01126749,0.104396021,132.0824146,54.88801112,115.1857033
801,0.4,3,4,3,0,20,7.5,28.01627569,82.92154074,84.41699893,71.98372431,6.030452839,0.02262137,124.3561985,0.168567586,173.9400826,78.9097664,166.8936683
805,0.2,3,3,4,0,20,7.5,14.02804205,84.74176841,169.9393446,85.97195795,4.230285803,0.021585419,82.85192083,0.086632186,118.4975376,42.93559345,72.0232156
809,0.3,4,3,4,0,20,7.5,19.13887676,77.1715223,113.5971956,80.86112324,5.208238442,0.02277731,108.2131858,0.109430528,137.7122088,62.00621834,123.9820462
813,0.4,3,4,4,0,20,7.5,25.52131596,75.78227215,84.78935613,74.47868404,7.199304144,0.022387065,146.7726796,0.127012968,189.8296576,83.34281001,162.5572453
817,0.2,3,3,3,30,20,7.5,15.48683837,91.97342949,166.3756749,84.51316163,3.001043366,0.025605357,70.84070031,0.182832432,102.8556641,43.93520581,87.70757328
821,0.3,4,3,3,30,20,7.5,21.05452659,84.61453688,112.9361598,78.94547341,4.140699676,0.02418101,91.84490115,0.187912989,136.8595547,60.08177115,119.1376866
825,0.4,3,4,3,30,20,7.5,28.14371741,83.25526578,83.75278892,71.85628259,5.899636696,0.024313793,131.6432733,0.15372436,196.7458445,82.25485816,164.1591068
829,0.2,3,3,4,30,20,7.5,14.04320563,84.44325392,171.6931895,85.95679437,2.900740497,0.029045646,78.45239964,0.118572354,97.3202285,32.41543066,62.21145697
833,0.3,4,3,4,30,20,7.5,19.14315698,76.97762751,114.0729247,80.85684302,4.205886758,0.023351763,89.80309857,0.166724885,133.8697445,50.92276395,95.17288797
837,0.4,3,4,4,30,20,7.5,25.56375123,76.74112161,84.79139968,74.43624877,6.166813475,0.02348891,132.5181,0.142405939,183.5776436,74.13751543,138.7912433
841,0.2,3,3,3,60,20,7.5,15.45650767,91.11317417,167.1177135,84.54349233,2.868085437,0.022470474,58.71106715,0.182846951,114.2743699,43.58184943,87.20543484
845,0.3,4,3,3,60,20,7.5,21.04535349,84.63824101,113.4122383,78.95464651,4.129928337,0.024181099,91.60635097,0.187918389,135.4856075,60.1466117,119.9914759
849,0.4,3,4,3,60,20,7.5,28.11166912,84.17410444,84.23844386,71.88833088,6.875866785,0.023940203,150.8579105,0.153937805,212.8230784,76.68995544,146.6717081
853,0.2,3,3,4,60,20,7.5,14.07878688,83.80462052,170.423361,85.92121312,2.553758631,0.023861042,55.82782513,0.099538493,85.96809159,36.18899438,72.15746164
857,0.3,4,3,4,60,20,7.5,19.12867489,77.11981531,113.9032195,80.87132511,3.397053159,0.023775632,73.9729779,0.127269435,105.2075002,47.07962074,95.09064531
861,0.4,3,4,4,60,20,7.5,25.58530947,76.06725934,84.55135175,74.41469053,6.160479446,0.024587219,139.148098,0.14991951,190.9295407,71.2102242,137.2176733
865,0.2,3,3,3,0,8,10,15.264578,64.8874639,168.7938649,84.735422,2.491929245,0.033845467,79.35665052,0.108372971,99.70945734,48.21578588,102.2236238
869,0.3,4,3,3,0,8,10,20.86726325,59.92371195,113.4731481,79.13273675,3.266440395,0.030098201,91.78109923,0.143810153,127.6735407,59.91610347,120.3095362
873,0.4,3,4,3,0,8,10,27.8677035,60.1587343,85.17781301,72.1322965,4.662271578,0.029277774,127.1763887,0.145097017,180.2891027,80.55171226,159.9554882
877,0.2,3,3,4,0,8,10,14.02161403,60.91670797,170.5831175,85.97838597,2.791923755,0.035209806,92.71924657,0.121163048,110.0742009,48.95022245,99.57164028
881,0.3,4,3,4,0,8,10,19.12824815,54.95194248,113.2835093,80.87175185,3.105968166,0.038709685,114.0191139,0.117437795,139.089197,63.44682201,128.996533
885,0.4,3,4,4,0,8,10,25.55261628,54.78115643,85.16661822,74.44738372,4.40264968,0.037703991,157.1921636,0.135310382,195.7307058,86.78077769,172.0174148
889,0.2,3,3,3,30,8,10,15.48006911,65.24913201,168.1699897,84.51993089,2.198236187,0.036962108,76.85497201,0.177465469,102.5541245,45.27320187,90.09823084
893,0.3,4,3,3,30,8,10,21.10596735,60.17226489,112.7625832,78.89403265,2.945816051,0.036616414,101.9735883,0.198012173,141.1269478,60.74323766,122.6482257
897,0.4,3,4,3,30,8,10,28.12994039,60.71839511,84.73808909,71.87005961,4.719852927,0.031197269,137.8068154,0.158169463,197.8520874,86.61291098,174.3314446
901,0.2,3,3,4,30,8,10,14.0730636,60.20232112,170.8271883,85.9269364,1.806205447,0.045872151,79.24211886,0.120382696,91.42485276,39.52846303,75.70113098
905,0.3,4,3,4,30,8,10,19.14202374,54.82077395,113.6182985,80.85797626,3.12113972,0.031473477,91.99083895,0.168646961,128.5556006,52.5577553,99.79394218
909,0.4,3,4,4,30,8,10,25.4996366,54.66299703,85.28640059,74.5003634,4.32804601,0.036026395,147.2678046,0.149535477,189.809186,77.80662408,143.9940894
913,0.2,3,3,3,60,8,10,15.46378668,65.06591805,168.1765856,84.53621332,2.180345059,0.037655096,77.74041152,0.180057973,102.701468,45.35599011,90.69638368
917,0.3,4,3,3,60,8,10,21.08059453,60.52918641,113.7434142,78.91940547,2.90741551,0.037779788,104.0267116,0.199253827,141.4691534,60.91721545,123.7888814
921,0.4,3,4,3,60,8,10,28.11273072,60.07557169,85.22559129,71.88726928,4.206894407,0.045733973,183.9842071,0.187063456,224.8770208,88.98370061,165.8936605
925,0.2,3,3,4,60,8,10,14.091377,60.75840132,171.0981024,85.908623,1.991284312,0.031717302,59.17559689,0.155625746,83.56869699,37.5379935,76.23693585
929,0.3,4,3,4,60,8,10,19.20673441,55.38229872,114.559861,80.79326559,2.514876593,0.033374591,78.90322362,0.155626506,109.1377054,49.622706,99.45497912
933,0.4,3,4,4,60,8,10,25.50708413,55.05246443,85.70919474,74.49291587,4.279450853,0.037416077,151.5613609,0.157040715,190.1100106,77.41540847,143.5401371
937,0.2,3,3,3,0,10,10,15.51710181,81.68912421,167.3034927,84.48289819,3.226571388,0.025392335,75.4770379,0.197919869,107.4036347,44.20578489,89.13828978
941,0.3,4,3,3,0,10,10,21.20579375,76.40077787,113.0921698,78.79420625,4.059053123,0.027141409,102.0503164,0.194587278,149.3762981,59.46106004,122.8179061
945,0.4,3,4,3,0,10,10,28.35148606,74.72857308,83.96106458,71.64851394,5.699748889,0.023849631,124.5374078,0.188277102,187.8244934,83.44709195,176.234161
949,0.2,3,3,4,0,10,10,14.03301022,75.16024655,170.1366374,85.96698978,4.294489253,0.027722271,110.4640156,0.194044089,120.8463998,41.57128287,83.89639274
953,0.3,4,3,4,0,10,10,19.16819435,67.7573962,113.1222428,80.83180565,4.823859141,0.024174275,106.9655802,0.106157541,138.777676,63.49563068,128.4249534
957,0.4,3,4,4,0,10,10,25.54505236,68.15607195,84.88846483,74.45494764,6.704806752,0.024075091,148.0092196,0.131425643,194.7991047,87.60712654,174.3896086
961,0.2,3,3,3,30,10,10,15.43388736,80.89209851,167.6254711,84.56611264,2.650248609,0.029694266,73.39669107,0.180422878,101.4827213,44.86900373,88.53642193
965,0.3,4,3,3,30,10,10,21.0985274,74.57598986,112.9829456,78.9014726,3.618372115,0.029304177,98.79667373,0.199482155,138.1769609,60.07530982,119.663349
969,0.4,3,4,3,30,10,10,28.12418139,74.8518042,84.51129222,71.87581861,4.967658443,0.0301622,139.9001881,0.12199235,216.8348467,84.78071657,172.1118275
973,0.2,3,3,4,30,10,10,14.04100627,74.71315715,171.3915944,85.95899373,2.072588077,0.038338743,75.31524476,0.14279747,90.88099336,39.33373832,75.75177403
977,0.3,4,3,4,30,10,10,19.21261003,68.63190613,112.4896085,80.78738997,3.112982994,0.032784932,95.83297008,0.154047513,126.9543522,54.22019126,104.8918631
981,0.4,3,4,4,30,10,10,25.53260882,68.68580802,85.07216968,74.46739118,4.773690013,0.031863748,142.5602772,0.15152173,186.2585119,75.94288076,137.7744863
985,0.2,3,3,3,60,10,10,15.45455214,80.2996049,167.9698539,84.54544786,2.644182339,0.029800541,73.50969908,0.162640262,101.8832124,44.73947867,88.53384351
989,0.3,4,3,3,60,10,10,21.05751195,75.45026257,113.2745185,78.94248805,3.613899576,0.029421474,99.09845219,0.190578616,138.3156656,60.33221436,120.3416629
993,0.4,3,4,3,60,10,10,28.1237039,75.28593743,84.35057306,71.8762961,4.807502478,0.037692136,171.5900309,0.163194489,218.623686,88.28385429,162.4746717
997,0.2,3,3,4,60,10,10,14.04498649,74.72953078,170.9998831,85.95501351,2.190566344,0.029657612,60.58583503,0.129601431,82.34504257,36.94197566,73.60220062
1001,0.3,4,3,4,60,10,10,19.21173385,68.35071644,113.1546479,80.78826615,2.314210939,0.038478365,84.4186306,0.152914143,109.2731463,49.49319593,100.9422294
1005,0.4,3,4,4,60,10,10,25.56504574,68.07018592,85.43190074,74.43495426,4.797733237,0.03172242,142.6002431,0.133698118,186.5284801,76.3441573,140.3336661
1009,0.2,3,3,3,0,15,10,15.4096945,122.3641127,166.8595248,84.5903055,3.292828947,0.024202774,73.1099364,0.122179421,104.994878,43.97193147,89.45440179
1013,0.3,4,3,3,0,15,10,21.08244951,111.2508184,111.9721613,78.91755049,4.143261319,0.020909661,78.34766603,0.12255098,136.1572092,55.17231368,109.9476175
1017,0.4,3,4,3,0,15,10,28.12983713,110.5408667,83.71816418,71.87016287,5.841664151,0.023607345,126.2228552,0.181616116,177.9759654,80.14204485,163.0471975
1021,0.2,3,3,4,0,15,10,13.96485496,112.9073896,171.1117087,86.03514504,4.087871618,0.023785045,89.05446808,0.090843868,111.5183965,45.86841905,85.87200531
1025,0.3,4,3,4,0,15,10,19.14024979,102.1974525,113.3597016,80.85975021,4.293759948,0.027969162,111.5053475,0.111372709,139.2399457,59.32459566,110.8604865
1029,0.4,3,4,4,0,15,10,25.54049834,102.970724,85.40901346,74.45950166,5.959531488,0.027519621,152.0849838,0.101253804,193.3700734,80.96177841,154.1673751
1033,0.2,3,3,3,30,15,10,15.4301378,121.4503662,167.5065675,84.5698622,3.057660325,0.025207925,70.96195006,0.170570978,100.7794833,44.37766029,88.13153417
1037,0.3,4,3,3,30,15,10,21.05627313,111.899387,112.3778823,78.94372687,3.895130827,0.026776088,96.50610448,0.178401597,137.6348658,59.59369432,117.5104784
1041,0.4,3,4,3,30,15,10,28.10045606,111.8832965,83.94081921,71.89954394,5.752782817,0.024010037,126.6189607,0.132649716,189.2943624,81.67512855,162.1093469
1045,0.2,3,3,4,30,15,10,14.0044327,112.6016938,169.9981967,85.9955673,2.951015335,0.023607491,63.76403753,0.11147155,106.2038896,34.90541559,63.5598031
1049,0.3,4,3,4,30,15,10,19.13978821,101.7144934,113.5007565,80.86021179,3.392779015,0.029992003,94.97068019,0.086292807,127.7648376,50.15119545,96.5801806
1053,0.4,3,4,4,30,15,10,25.53092049,103.0312364,85.0088698,74.46907951,5.493544479,0.027149716,138.1610837,0.139237706,183.3154236,74.86153108,138.8415489
1057,0.2,3,3,3,60,15,10,15.42573599,121.6427965,166.1794225,84.57426401,3.053796226,0.024866158,69.82858753,0.168053611,103.4692756,34.73299748,85.58855353
1061,0.3,4,3,3,60,15,10,21.06075226,111.9219971,112.5720012,78.93924774,4.287909998,0.025385325,100.2741706,0.124063857,150.5212709,57.47375571,109.8360057
1065,0.4,3,4,3,60,15,10,28.10382738,110.8364868,83.66831211,71.89617262,6.406458328,0.026585602,157.5066367,0.16460859,215.5512339,65.66861599,162.4046473
1069,0.2,3,3,4,60,15,10,14.04032954,112.9733526,170.6303941,85.95967046,2.438675863,0.02330367,51.95274511,0.175571442,82.25491621,35.97992743,71.47745109
1073,0.3,4,3,4,60,15,10,19.16043359,102.5697696,113.2841381,80.83956641,3.173585651,0.026530817,77.85064751,0.155514828,108.8200932,49.82439475,101.2681183
1077,0.4,3,4,4,60,15,10,25.50287329,102.8851864,83.876493,74.49712671,5.489688778,0.027164561,138.1456088,0.117737103,185.0202606,73.39563329,135.7611513
1081,0.2,3,3,3,0,20,10,15.35865687,160.9555967,166.4844282,84.64134313,4.095149705,0.021910555,81.53670208,0.160736251,117.4772773,42.53837342,89.23699524
1085,0.3,4,3,3,0,20,10,20.9587547,148.4171033,112.7825233,79.0412453,4.875452339,0.022096347,97.97878117,0.172403264,140.2416096,56.38917454,116.8931291
1089,0.4,3,4,3,0,20,10,28.03160714,147.2417698,83.42184419,71.96839286,6.153824984,0.022764544,127.7813722,0.127056265,172.9675798,79.37870597,167.0454163
1093,0.2,3,3,4,0,20,10,13.95398589,149.0874932,170.3635331,86.04601411,4.736385923,0.022745638,98.25934939,0.143938875,116.691894,39.28977254,67.76997399
1097,0.3,4,3,4,0,20,10,19.11129599,135.6026506,112.5647039,80.88870401,5.378338583,0.022690639,111.2812629,0.154699707,139.1126655,62.97057005,132.6709448
1101,0.4,3,4,4,0,20,10,25.51224333,134.8936982,84.08389657,74.48775667,7.399386309,0.022392445,150.8915749,0.125763178,190.8005113,81.8573609,159.6244468
1105,0.2,3,3,3,30,20,10,15.4381538,159.6783865,166.9173841,84.5618462,2.686265883,0.033662833,85.05478851,0.185528839,118.1986111,44.08138018,86.67639644
1109,0.3,4,3,3,30,20,10,21.11172141,149.6893419,111.793603,78.88827859,4.074358288,0.026004212,97.80176021,0.123647928,146.2722013,59.02467357,118.263483
1113,0.4,3,4,3,30,20,10,28.09317975,149.7102802,83.76177613,71.90682025,6.197956572,0.023496398,133.2337443,0.152490973,228.5160255,80.40704194,155.5787368
1117,0.2,3,3,4,30,20,10,14.021037,149.4119796,170.5871354,85.978963,2.998811683,0.026786315,74.3294918,0.12995944,106.0573457,36.5937596,68.58669929
1121,0.3,4,3,4,30,20,10,19.1325157,137.2634352,113.3326151,80.8674843,3.611317209,0.033054453,112.1474808,0.116092658,142.125069,52.77858398,101.3515224
1125,0.4,3,4,4,30,20,10,25.46806715,134.334676,84.60317617,74.53193285,6.416997266,0.023876939,140.3842562,0.15374763,186.1128715,69.43884054,124.6449136
1129,0.2,3,3,3,60,20,10,15.43207222,160.8973356,167.031344,84.56792778,3.11488154,0.02483128,71.11673108,0.141341114,120.8103192,42.59746222,82.98797195
1133,0.3,4,3,3,60,20,10,21.07657814,149.5199624,112.1090783,78.92342186,4.057851892,0.026829655,100.7550616,0.198100209,137.9967162,60.57621004,123.3557137
1137,0.4,3,4,3,60,20,10,28.1022865,147.4150227,83.94112979,71.8977135,6.935087939,0.024771526,157.9225365,0.16526897,222.4243342,87.90871518,163.7613543
1141,0.2,3,3,4,60,20,10,14.00231864,149.1596184,169.8864453,85.99768136,2.597894438,0.028067031,67.7193945,0.181495667,84.77832616,36.25077119,70.94979167
1145,0.3,4,3,4,60,20,10,19.17070331,136.9025757,112.479935,80.82929669,3.267794073,0.027461398,83.20260461,0.148768663,108.3433293,49.42862454,100.7654219
1149,0.4,3,4,4,60,20,10,25.47081896,136.2848285,84.52474724,74.52918104,6.469472059,0.023685785,140.2955785,0.134860897,190.0704884,68.57976532,122.3153885
1152,0.4,4,4,4,60,20,10,23.19493378,122.3970331,83.51632556,76.80506622,4.71935862,0.025955859,113.0562915,0.194330812,152.3021263,62.95634763,119.8926854